Workbook

Sheet 2026-1
B2: ='Monthly Report 2026 €'!D107 -> 46053
B4: CCY | C4: Rate | D4: Ester/SOFR | E4: BCE/Fed | F4: Amont EoM | G4: Interest Due | H4: Interest Paid | I4: Profit/NCA
F5: in Thousand | G5: in Thousand | H5: in Thousand | I5: in Thousand
B7: K€ | C7: =INDEX('Monthly Report 2026 €'!$I$107:$I$118,MATCH('2026-1'!$B$2,'Monthly Report 2026 €'!$D$107:$D$118,0)) -> 0.022007028 | D7: 0.0193 | E7: 0.02 | F7: =INDEX('Monthly Report 2026 €'!J$107:J$118,MATCH('2026-1'!$B$2,'Monthly Report 2026 €'!$D$107:$D$118,0)) -> 1.8793802e+08 | G7: =INDEX('Monthly Report 2026 €'!K$107:K$118,MATCH('2026-1'!$B$2,'Monthly Report 2026 €'!$D$107:$D$118,0)) -> 383920.66 | H7: =INDEX('Monthly Report 2026 €'!L$107:L$118,MATCH('2026-1'!$B$2,'Monthly Report 2026 €'!$D$107:$D$118,0)) -> 150003.47 | I7: =INDEX('Monthly Report 2026 €'!M$107:M$118,MATCH('2026-1'!$B$2,'Monthly Report 2026 €'!$D$107:$D$118,0)) -> 93246.038
B8: K$ | C8: =INDEX('Monthly Report 2026 $'!I$93:I$104,MATCH($B$2,'Monthly Report 2026 $'!$D$93:$D$104,0)) -> 0.036755514 | D8: 0.0367 | E8: 0.035 | F8: =INDEX('Monthly Report 2026 $'!J$93:J$104,MATCH($B$2,'Monthly Report 2026 $'!$D$93:$D$104,0)) -> 3.694326e+08 | G8: =INDEX('Monthly Report 2026 $'!K$93:K$104,MATCH($B$2,'Monthly Report 2026 $'!$D$93:$D$104,0)) -> 1183348.9 | H8: =INDEX('Monthly Report 2026 $'!L$93:L$104,MATCH($B$2,'Monthly Report 2026 $'!$D$93:$D$104,0)) -> 1095294.4 | I8: =INDEX('Monthly Report 2026 $'!M$93:M$104,MATCH($B$2,'Monthly Report 2026 $'!$D$93:$D$104,0)) -> 185126.47
B10: ="Total in K€eq at FX "&M10 -> Total in K€eq at FX 1,1919 | G10: =(G7+G8/$M$10)*10^-3 -> 1376.7463 | H10: =(H7+H8/$M$10)*10^-3 -> 1068.9517 | I10: =(I7+I8/$M$10)*10^-3 -> 248.56651 | M10: 1.1919
B12: ="Total in K€eq at FX "&M12 -> Total in K€eq at FX 1,1886 | G12: =(G7+G8/$M$12)*10^-3 -> 1379.5027 | H12: =(H7+H8/$M$12)*10^-3 -> 1071.5031 | I12: =(I7+I8/$M$12)*10^-3 -> 248.99774 | M12: 1.1886
B13: FX Gain/Loss- in thousand | G13: =G12-G10 -> 2.7564568 | H13: =H12-H10 -> 2.5513454 | I13: =I12-I10 -> 0.43122796
B15: YTD 2026
B17: CCY | C17: Rate | D17: Ester/SOFR | E17: BCE/Fed | F17: Amont EoM | G17: Interest Due | H17: Interest Paid | I17: Profit/NCA
F18: in Thousand | G18: in Thousand | H18: in Thousand | I18: in Thousand
B20: EUR | C20: ='Monthly Report 2026 €'!I119 -> 0.022007028 | D20: 0.0193 | E20: 0.02 | F20: ='Monthly Report 2026 €'!J119 -> 1.8793802e+08 | G20: ='Monthly Report 2026 €'!K119 -> 383920.66 | H20: ='Monthly Report 2026 €'!L119 -> 150003.47 | I20: ='Monthly Report 2026 €'!M119 -> 93246.038
B21: USD | C21: ='Monthly Report 2026 $'!I105 -> 0.036755514 | D21: 0.0367 | E21: 0.035 | F21: ='Monthly Report 2026 $'!J105 -> 3.694326e+08 | G21: ='Monthly Report 2026 $'!K105 -> 1183348.9 | H21: ='Monthly Report 2026 $'!L105 -> 1095294.4 | I21: ='Monthly Report 2026 $'!M105 -> 185126.47
B23: ="Total in K€eq at FX "&M23 -> Total in K€eq at FX 1,1919 | G23: =(G20+G21/M23)*10^-3 -> 1376.7463 | H23: =(H20+H21/$M$23)*10^-3 -> 1068.9517 | I23: =(I20+I21/$M$23)*10^-3 -> 248.56651 | M23: 1.1919
B25: ="Total in K€eq at FX "&M25 -> Total in K€eq at FX 1,1886 | G25: =(G20+G21/$M$25)*10^-3 -> 1379.5027 | H25: =(H20+H21/$M$25)*10^-3 -> 1071.5031 | I25: =(I20+I21/$M$25)*10^-3 -> 248.99774 | M25: =M12 -> 1.1886
B26: FX Gain/Loss- in thousand | G26: =G25-G23 -> 2.7564568 | H26: =H25-H23 -> 2.5513454 | I26: =I25-I23 -> 0.43122796

Sheet 2026-2
D3: Month | E3: Rate * | F3: Amount EoM | G3: Interest due | H3: Interest paid | I3: Profit/NCA
F4: in k€ | G4: in k€ | H4: in k€ | I4: in k€
D5: ='Monthly Report 2026 €'!D107 -> 46053 | E5: ='Monthly Report 2026 €'!I107 -> 0.022007028 | F5: ='Monthly Report 2026 €'!J107 -> 1.8793802e+08 | G5: ='Monthly Report 2026 €'!K107 -> 383920.66 | H5: ='Monthly Report 2026 €'!L107 -> 150003.47 | I5: ='Monthly Report 2026 €'!M107 -> 93246.038
A6: =CONCATENATE(MONTH(D6)," ",YEAR(D6)) -> 2 2026 | B6: =EOMONTH(D6,0) -> 46081 | D6: ='Monthly Report 2026 €'!D108 -> 46081 | E6: ='Monthly Report 2026 €'!I108 -> 0.022605121 | F6: ='Monthly Report 2026 €'!J108 -> 37210956 | G6: ='Monthly Report 2026 €'!K108 -> 67926.154 | H6: ='Monthly Report 2026 €'!L108 -> 0 | I6: ='Monthly Report 2026 €'!M108 -> 15322.769
A7: =CONCATENATE(MONTH(D7)," ",YEAR(D7)) -> 3 2026 | B7: =EOMONTH(D7,0) -> 46112 | D7: ='Monthly Report 2026 €'!D109 -> 46112 | E7: ='Monthly Report 2026 €'!I109 -> 0.02073427 | F7: ='Monthly Report 2026 €'!J109 -> 67260956 | G7: ='Monthly Report 2026 €'!K109 -> 112477.53 | H7: ='Monthly Report 2026 €'!L109 -> 0 | I7: ='Monthly Report 2026 €'!M109 -> 16964.495
A8: =CONCATENATE(MONTH(D8)," ",YEAR(D8)) -> 4 2026 | B8: =EOMONTH(D8,0) -> 46142 | D8: ='Monthly Report 2026 €'!D110 -> 46142 | E8: ='Monthly Report 2026 €'!I110 -> 0.020428995 | F8: ='Monthly Report 2026 €'!J110 -> 67260956 | G8: ='Monthly Report 2026 €'!K110 -> 114506.15 | H8: ='Monthly Report 2026 €'!L110 -> 0 | I8: ='Monthly Report 2026 €'!M110 -> 16417.253
A9: =CONCATENATE(MONTH(D9)," ",YEAR(D9)) -> 5 2026 | B9: =EOMONTH(D9,0) -> 46173 | D9: ='Monthly Report 2026 €'!D111 -> 46173 | E9: ='Monthly Report 2026 €'!I111 -> 0.020428995 | F9: ='Monthly Report 2026 €'!J111 -> 67260956 | G9: ='Monthly Report 2026 €'!K111 -> 118323.02 | H9: ='Monthly Report 2026 €'!L111 -> 0 | I9: ='Monthly Report 2026 €'!M111 -> 16964.495
A10: =CONCATENATE(MONTH(D10)," ",YEAR(D10)) -> 6 2026 | B10: =EOMONTH(D10,0) -> 46203 | D10: ='Monthly Report 2026 €'!D112 -> 46203 | E10: ='Monthly Report 2026 €'!I112 -> 0.020428995 | F10: ='Monthly Report 2026 €'!J112 -> 67260956 | G10: ='Monthly Report 2026 €'!K112 -> 114506.15 | H10: ='Monthly Report 2026 €'!L112 -> 0 | I10: ='Monthly Report 2026 €'!M112 -> 16417.253
A11: =CONCATENATE(MONTH(D11)," ",YEAR(D11)) -> 7 2026 | B11: =EOMONTH(D11,0) -> 46234 | D11: ='Monthly Report 2026 €'!D113 -> 46234 | E11: ='Monthly Report 2026 €'!I113 -> 0.020428995 | F11: ='Monthly Report 2026 €'!J113 -> 67260956 | G11: ='Monthly Report 2026 €'!K113 -> 118323.02 | H11: ='Monthly Report 2026 €'!L113 -> 0 | I11: ='Monthly Report 2026 €'!M113 -> 16964.495
A12: =CONCATENATE(MONTH(D12)," ",YEAR(D12)) -> 8 2026 | B12: =EOMONTH(D12,0) -> 46265 | D12: ='Monthly Report 2026 €'!D114 -> 46265 | E12: ='Monthly Report 2026 €'!I114 -> 0.020428995 | F12: ='Monthly Report 2026 €'!J114 -> 67260956 | G12: ='Monthly Report 2026 €'!K114 -> 118323.02 | H12: ='Monthly Report 2026 €'!L114 -> 0 | I12: ='Monthly Report 2026 €'!M114 -> 16964.495
A13: =CONCATENATE(MONTH(D13)," ",YEAR(D13)) -> 9 2026 | B13: =EOMONTH(D13,0) -> 46295 | D13: ='Monthly Report 2026 €'!D115 -> 46295 | E13: ='Monthly Report 2026 €'!I115 -> 0.020428995 | F13: ='Monthly Report 2026 €'!J115 -> 67260956 | G13: ='Monthly Report 2026 €'!K115 -> 114506.15 | H13: ='Monthly Report 2026 €'!L115 -> 0 | I13: ='Monthly Report 2026 €'!M115 -> 16417.253
A14: =CONCATENATE(MONTH(D14)," ",YEAR(D14)) -> 10 2026 | B14: =EOMONTH(D14,0) -> 46326 | D14: ='Monthly Report 2026 €'!D116 -> 46326 | E14: ='Monthly Report 2026 €'!I116 -> 0.020428995 | F14: ='Monthly Report 2026 €'!J116 -> 67260956 | G14: ='Monthly Report 2026 €'!K116 -> 118323.02 | H14: ='Monthly Report 2026 €'!L116 -> 0 | I14: ='Monthly Report 2026 €'!M116 -> 16964.495
A15: =CONCATENATE(MONTH(D15)," ",YEAR(D15)) -> 11 2026 | B15: =EOMONTH(D15,0) -> 46356 | D15: ='Monthly Report 2026 €'!D117 -> 46356 | E15: ='Monthly Report 2026 €'!I117 -> 0.019198018 | F15: ='Monthly Report 2026 €'!J117 -> 52260956 | G15: ='Monthly Report 2026 €'!K117 -> 88716.147 | H15: ='Monthly Report 2026 €'!L117 -> 0 | I15: ='Monthly Report 2026 €'!M117 -> 8127.253
A16: =CONCATENATE(MONTH(D16)," ",YEAR(D16)) -> 12 2026 | B16: =EOMONTH(D16,0) -> 46387 | D16: ='Monthly Report 2026 €'!D118 -> 46387 | E16: ='Monthly Report 2026 €'!I118 -> 0.018890274 | F16: ='Monthly Report 2026 €'!J118 -> 52260956 | G16: ='Monthly Report 2026 €'!K118 -> 85010.936 | H16: ='Monthly Report 2026 €'!L118 -> 0 | I16: ='Monthly Report 2026 €'!M118 -> 6256.5781
D17: ='Monthly Report 2026 €'!D119 -> Total 2026 | E17: ='Monthly Report 2026 €'!I119 -> 0.022007028 | F17: ='Monthly Report 2026 €'!J119 -> 1.8793802e+08 | G17: ='Monthly Report 2026 €'!K119 -> 383920.66 | H17: ='Monthly Report 2026 €'!L119 -> 150003.47 | I17: ='Monthly Report 2026 €'!M119 -> 93246.038
D20: Month | E20: Rate * | F20: Amount EoM | G20: Interest due | H20: Interest paid | I20: Profit/NCA
F21: in k$ | G21: in k$ | H21: in k$ | I21: in k$
D22: ='Monthly Report 2026 $'!D93 -> 46053 | E22: ='Monthly Report 2026 $'!I93 -> 0.036755514 | F22: ='Monthly Report 2026 $'!J93 -> 3.694326e+08 | G22: ='Monthly Report 2026 $'!K93 -> 1183348.9 | H22: ='Monthly Report 2026 $'!L93 -> 1095294.4 | I22: ='Monthly Report 2026 $'!M93 -> 185126.47
D23: ='Monthly Report 2026 $'!D94 -> 46081 | E23: ='Monthly Report 2026 $'!I94 -> 0.033400702 | F23: ='Monthly Report 2026 $'!J94 -> 22280000 | G23: ='Monthly Report 2026 $'!K94 -> 65861.444 | H23: ='Monthly Report 2026 $'!L94 -> 50983.33 | I23: ='Monthly Report 2026 $'!M94 -> 10834.444
D24: ='Monthly Report 2026 $'!D95 -> 46112 | E24: ='Monthly Report 2026 $'!I95 -> 0.037444946 | F24: ='Monthly Report 2026 $'!J95 -> 1450000 | G24: ='Monthly Report 2026 $'!K95 -> 3858.75 | H24: ='Monthly Report 2026 $'!L95 -> 0 | I24: ='Monthly Report 2026 $'!M95 -> 0
D25: ='Monthly Report 2026 $'!D96 -> 46142 | E25: ='Monthly Report 2026 $'!I96 -> 0.037437639 | F25: ='Monthly Report 2026 $'!J96 -> 1450000 | G25: ='Monthly Report 2026 $'!K96 -> 3806.25 | H25: ='Monthly Report 2026 $'!L96 -> 0 | I25: ='Monthly Report 2026 $'!M96 -> 0
D26: ='Monthly Report 2026 $'!D97 -> 46173 | E26: ='Monthly Report 2026 $'!I97 -> 0.036732483 | F26: ='Monthly Report 2026 $'!J97 -> 1450000 | G26: ='Monthly Report 2026 $'!K97 -> 3933.125 | H26: ='Monthly Report 2026 $'!L97 -> 0 | I26: ='Monthly Report 2026 $'!M97 -> 0
D27: ='Monthly Report 2026 $'!D98 -> 46203 | E27: ='Monthly Report 2026 $'!I98 -> 0.036932665 | F27: ='Monthly Report 2026 $'!J98 -> 1450000 | G27: ='Monthly Report 2026 $'!K98 -> 3806.25 | H27: ='Monthly Report 2026 $'!L98 -> 0 | I27: ='Monthly Report 2026 $'!M98 -> 0
D28: ='Monthly Report 2026 $'!D99 -> 46234 | E28: ='Monthly Report 2026 $'!I99 -> 0.036932665 | F28: ='Monthly Report 2026 $'!J99 -> 1450000 | G28: ='Monthly Report 2026 $'!K99 -> 3933.125 | H28: ='Monthly Report 2026 $'!L99 -> 0 | I28: ='Monthly Report 2026 $'!M99 -> 0
D29: ='Monthly Report 2026 $'!D100 -> 46265 | E29: ='Monthly Report 2026 $'!I100 -> 0.035600742 | F29: ='Monthly Report 2026 $'!J100 -> 1450000 | G29: ='Monthly Report 2026 $'!K100 -> 3933.125 | H29: ='Monthly Report 2026 $'!L100 -> 0 | I29: ='Monthly Report 2026 $'!M100 -> 0
D30: ='Monthly Report 2026 $'!D101 -> 46295 | E30: ='Monthly Report 2026 $'!I101 -> 0.036171141 | F30: ='Monthly Report 2026 $'!J101 -> 1450000 | G30: ='Monthly Report 2026 $'!K101 -> 3806.25 | H30: ='Monthly Report 2026 $'!L101 -> 0 | I30: ='Monthly Report 2026 $'!M101 -> 0
D31: ='Monthly Report 2026 $'!D102 -> 46326 | E31: ='Monthly Report 2026 $'!I102 -> 0.036171141 | F31: ='Monthly Report 2026 $'!J102 -> 1450000 | G31: ='Monthly Report 2026 $'!K102 -> 3933.125 | H31: ='Monthly Report 2026 $'!L102 -> 0 | I31: ='Monthly Report 2026 $'!M102 -> 0
D32: ='Monthly Report 2026 $'!D103 -> 46356 | E32: ='Monthly Report 2026 $'!I103 -> 0.031277181 | F32: ='Monthly Report 2026 $'!J103 -> 1450000 | G32: ='Monthly Report 2026 $'!K103 -> 3806.25 | H32: ='Monthly Report 2026 $'!L103 -> 0 | I32: ='Monthly Report 2026 $'!M103 -> 0
D33: ='Monthly Report 2026 $'!D104 -> 46387 | E33: ='Monthly Report 2026 $'!I104 -> 0.0315 | F33: ='Monthly Report 2026 $'!J104 -> 1450000 | G33: ='Monthly Report 2026 $'!K104 -> 3933.125 | H33: ='Monthly Report 2026 $'!L104 -> 0 | I33: ='Monthly Report 2026 $'!M104 -> 0
D34: Total 2026 | E34: ='Monthly Report 2026 $'!F105 -> 0 | F34: ='Monthly Report 2026 $'!J105 -> 3.694326e+08 | G34: ='Monthly Report 2026 $'!K105 -> 1183348.9 | H34: ='Monthly Report 2026 $'!L105 -> 1095294.4 | I34: ='Monthly Report 2026 $'!M105 -> 185126.47

Sheet Monthly Report 2026 €
L1: 46053
D6: ="€ Cash investments report as of "&TEXT(L1,"jj mm aaaa") -> € Cash investments report as of 31 01 2026
B7: Formule | D7: Month | E7: Bank | F7: Investment | G7: Opening Date | H7: Closing Date | I7: Rate * | J7: Amount EoM | K7: Interest due | L7: Interest paid | M7: Profit/NCA
D9: Deposit
A11: =CONCATENATE(MONTH(D11)," ",YEAR(D11)) -> 1 2026 | B11: 46053 | D11: 46053 | E11: SG | F11: NCA | G11: 45205 | I11: =INDEX('OverNight €'!$I$376:$I$737,MATCH(B11,'OverNight €'!$D$376:$D$737,0)) -> 0.0175 | J11: =INDEX('OverNight €'!$H$376:$H$737,MATCH(B11,'OverNight €'!$C$376:$C$737,0)) -> 7130000 | K11: =SUMIFS('OverNight €'!$J$373:$J$750,'OverNight €'!$B$373:$B$750,A11) -> 5285.9722 | L11: 4939.39 | M11: 0 | O11: OK
A12: =CONCATENATE(MONTH(D12)," ",YEAR(D12)) -> 2 2026 | B12: =EOMONTH(B11,1) -> 46081 | D12: =EOMONTH(D11,1) -> 46081 | E12: SG | F12: NCA | I12: =INDEX('OverNight €'!$I$376:$I$737,MATCH(B12,'OverNight €'!$D$376:$D$737,0)) -> 0.0175 | J12: =INDEX('OverNight €'!$H$376:$H$737,MATCH(B12,'OverNight €'!$C$376:$C$737,0)) -> 4200000 | K12: =SUMIFS('OverNight €'!$J$373:$J$750,'OverNight €'!$B$373:$B$750,A12) -> 7671.8056 | M12: 0
A13: =CONCATENATE(MONTH(D13)," ",YEAR(D13)) -> 3 2026 | B13: =EOMONTH(B12,1) -> 46112 | D13: =EOMONTH(D12,1) -> 46112 | E13: SG | F13: NCA | I13: =INDEX('OverNight €'!$I$376:$I$737,MATCH(B13,'OverNight €'!$D$376:$D$737,0)) -> 0.0175 | J13: =INDEX('OverNight €'!$H$376:$H$737,MATCH(B13,'OverNight €'!$C$376:$C$737,0)) -> 34250000 | K13: =SUMIFS('OverNight €'!$J$373:$J$750,'OverNight €'!$B$373:$B$750,A13) -> 45767.361 | M13: 0
A14: =CONCATENATE(MONTH(D14)," ",YEAR(D14)) -> 4 2026 | B14: =EOMONTH(B13,1) -> 46142 | D14: =EOMONTH(D13,1) -> 46142 | E14: SG | F14: NCA | I14: =INDEX('OverNight €'!$I$376:$I$737,MATCH(B14,'OverNight €'!$D$376:$D$737,0)) -> 0.0175 | J14: =INDEX('OverNight €'!$H$376:$H$737,MATCH(B14,'OverNight €'!$C$376:$C$737,0)) -> 34250000 | K14: =SUMIFS('OverNight €'!$J$373:$J$750,'OverNight €'!$B$373:$B$750,A14) -> 49947.917 | M14: 0
A15: =CONCATENATE(MONTH(D15)," ",YEAR(D15)) -> 5 2026 | B15: =EOMONTH(B14,1) -> 46173 | D15: =EOMONTH(D14,1) -> 46173 | E15: SG | F15: NCA | I15: =INDEX('OverNight €'!$I$376:$I$737,MATCH(B15,'OverNight €'!$D$376:$D$737,0)) -> 0.0175 | J15: =INDEX('OverNight €'!$H$376:$H$737,MATCH(B15,'OverNight €'!$C$376:$C$737,0)) -> 34250000 | K15: =SUMIFS('OverNight €'!$J$373:$J$750,'OverNight €'!$B$373:$B$750,A15) -> 51612.847 | M15: 0
A16: =CONCATENATE(MONTH(D16)," ",YEAR(D16)) -> 6 2026 | B16: =EOMONTH(B15,1) -> 46203 | D16: =EOMONTH(D15,1) -> 46203 | E16: SG | F16: NCA | I16: =INDEX('OverNight €'!$I$376:$I$737,MATCH(B16,'OverNight €'!$D$376:$D$737,0)) -> 0.0175 | J16: =INDEX('OverNight €'!$H$376:$H$737,MATCH(B16,'OverNight €'!$C$376:$C$737,0)) -> 34250000 | K16: =SUMIFS('OverNight €'!$J$373:$J$750,'OverNight €'!$B$373:$B$750,A16) -> 49947.917 | M16: 0
A17: =CONCATENATE(MONTH(D17)," ",YEAR(D17)) -> 7 2026 | B17: =EOMONTH(B16,1) -> 46234 | D17: =EOMONTH(D16,1) -> 46234 | E17: SG | F17: NCA | I17: =INDEX('OverNight €'!$I$376:$I$737,MATCH(B17,'OverNight €'!$D$376:$D$737,0)) -> 0.0175 | J17: =INDEX('OverNight €'!$H$376:$H$737,MATCH(B17,'OverNight €'!$C$376:$C$737,0)) -> 34250000 | K17: =SUMIFS('OverNight €'!$J$373:$J$750,'OverNight €'!$B$373:$B$750,A17) -> 51612.847 | M17: 0
A18: =CONCATENATE(MONTH(D18)," ",YEAR(D18)) -> 8 2026 | B18: =EOMONTH(B17,1) -> 46265 | D18: =EOMONTH(D17,1) -> 46265 | E18: SG | F18: NCA | I18: =INDEX('OverNight €'!$I$376:$I$737,MATCH(B18,'OverNight €'!$D$376:$D$737,0)) -> 0.0175 | J18: =INDEX('OverNight €'!$H$376:$H$737,MATCH(B18,'OverNight €'!$C$376:$C$737,0)) -> 34250000 | K18: =SUMIFS('OverNight €'!$J$373:$J$750,'OverNight €'!$B$373:$B$750,A18) -> 51612.847 | M18: 0
A19: =CONCATENATE(MONTH(D19)," ",YEAR(D19)) -> 9 2026 | B19: =EOMONTH(B18,1) -> 46295 | D19: =EOMONTH(D18,1) -> 46295 | E19: SG | F19: NCA | I19: =INDEX('OverNight €'!$I$376:$I$737,MATCH(B19,'OverNight €'!$D$376:$D$737,0)) -> 0.0175 | J19: =INDEX('OverNight €'!$H$376:$H$737,MATCH(B19,'OverNight €'!$C$376:$C$737,0)) -> 34250000 | K19: =SUMIFS('OverNight €'!$J$373:$J$750,'OverNight €'!$B$373:$B$750,A19) -> 49947.917 | M19: 0
A20: =CONCATENATE(MONTH(D20)," ",YEAR(D20)) -> 10 2026 | B20: =EOMONTH(B19,1) -> 46326 | D20: =EOMONTH(D19,1) -> 46326 | E20: SG | F20: NCA | I20: =INDEX('OverNight €'!$I$376:$I$737,MATCH(B20,'OverNight €'!$D$376:$D$737,0)) -> 0.0175 | J20: =INDEX('OverNight €'!$H$376:$H$737,MATCH(B20,'OverNight €'!$C$376:$C$737,0)) -> 34250000 | K20: =SUMIFS('OverNight €'!$J$373:$J$750,'OverNight €'!$B$373:$B$750,A20) -> 51612.847 | M20: 0
A21: =CONCATENATE(MONTH(D21)," ",YEAR(D21)) -> 11 2026 | B21: =EOMONTH(B20,1) -> 46356 | D21: =EOMONTH(D20,1) -> 46356 | E21: SG | F21: NCA | I21: =INDEX('OverNight €'!$I$376:$I$737,MATCH(B21,'OverNight €'!$D$376:$D$737,0)) -> 0.0175 | J21: =INDEX('OverNight €'!$H$376:$H$737,MATCH(B21,'OverNight €'!$C$376:$C$737,0)) -> 34250000 | K21: =SUMIFS('OverNight €'!$J$373:$J$750,'OverNight €'!$B$373:$B$750,A21) -> 49947.917 | M21: 0
A22: =CONCATENATE(MONTH(D22)," ",YEAR(D22)) -> 12 2026 | B22: =EOMONTH(B21,1) -> 46387 | D22: =EOMONTH(D21,1) -> 46387 | E22: SG | F22: NCA | I22: =INDEX('OverNight €'!$I$376:$I$737,MATCH(B22,'OverNight €'!$D$376:$D$737,0)) -> 0.0175 | J22: =INDEX('OverNight €'!$H$376:$H$750,MATCH(B22,'OverNight €'!$C$376:$C$750,0)) -> 34250000 | K22: =SUMIFS('OverNight €'!$J$373:$J$750,'OverNight €'!$B$373:$B$750,A22) -> 51612.847 | M22: 0
D23: Total 2026 NCA | I23: =AVERAGE(I11) -> 0.0175 | K23: =SUM(K11:K11) -> 5285.9722 | L23: =SUM(L11:L11) -> 4939.39 | M23: =SUM(M11:M11) -> 0 | O23: change all sums manually each month
A25: =CONCATENATE(MONTH(D25)," ",YEAR(D25)) -> 1 2026 | B25: 46053 | D25: 46053 | E25: SG | F25: CAT Tréso Plus | G25: 46027 | H25: =EDATE(G25,1) -> 46058 | I25: =INDEX('OverNight €'!$O$376:$O$750,MATCH($B25,'OverNight €'!$D$376:$D$750,0)) -> 0.02169863 | J25: =INDEX('OverNight €'!$N$376:$N$750,MATCH(B25,'OverNight €'!$C$376:$C$750,0)) -> 12000000 | K25: =SUMIFS('OverNight €'!$P$373:$P$750,'OverNight €'!$B$373:$B$750,A25) -> 22421.918 | L25: 22421.92 | M25: =SUMIFS('OverNight €'!$R$373:$R$750,'OverNight €'!$B$373:$B$750,A25) -> 4338.5845 | O25: OK
A26: =CONCATENATE(MONTH(D26)," ",YEAR(D26)) -> 2 2026 | B26: =EOMONTH(B25,1) -> 46081 | D26: =EOMONTH(D25,1) -> 46081 | E26: SG | F26: CAT Tréso Plus | G26: =H25 -> 46058 | H26: =EDATE(G26,1) -> 46086 | I26: =INDEX('OverNight €'!$O$376:$O$750,MATCH($B26,'OverNight €'!$D$376:$D$750,0)) -> 0.02169863 | J26: =INDEX('OverNight €'!$N$376:$N$750,MATCH(B26,'OverNight €'!$C$376:$C$750,0)) -> 12000000 | K26: =SUMIFS('OverNight €'!$P$373:$P$750,'OverNight €'!$B$373:$B$750,A26) -> 20252.055 | M26: =SUMIFS('OverNight €'!$R$373:$R$750,'OverNight €'!$B$373:$B$750,A26) -> 3918.7215
A27: =CONCATENATE(MONTH(D27)," ",YEAR(D27)) -> 3 2026 | B27: =EOMONTH(B26,1) -> 46112 | D27: =EOMONTH(D26,1) -> 46112 | E27: SG | F27: CAT Tréso Plus | G27: =H26 -> 46086 | H27: =EDATE(G27,1) -> 46117 | I27: =INDEX('OverNight €'!$O$376:$O$750,MATCH($B27,'OverNight €'!$D$376:$D$750,0)) -> 0.02169863 | J27: =INDEX('OverNight €'!$N$376:$N$750,MATCH(B27,'OverNight €'!$C$376:$C$750,0)) -> 12000000 | K27: =SUMIFS('OverNight €'!$P$373:$P$750,'OverNight €'!$B$373:$B$750,A27) -> 22421.918 | M27: =SUMIFS('OverNight €'!$R$373:$R$750,'OverNight €'!$B$373:$B$750,A27) -> 4338.5845
A28: =CONCATENATE(MONTH(D28)," ",YEAR(D28)) -> 4 2026 | B28: =EOMONTH(B27,1) -> 46142 | D28: =EOMONTH(D27,1) -> 46142 | E28: SG | F28: CAT Tréso Plus | G28: =H27 -> 46117 | H28: =EDATE(G28,1) -> 46147 | I28: =INDEX('OverNight €'!$O$376:$O$750,MATCH($B28,'OverNight €'!$D$376:$D$750,0)) -> 0.02169863 | J28: =INDEX('OverNight €'!$N$376:$N$750,MATCH(B28,'OverNight €'!$C$376:$C$750,0)) -> 12000000 | K28: =SUMIFS('OverNight €'!$P$373:$P$750,'OverNight €'!$B$373:$B$750,A28) -> 21698.63 | M28: =SUMIFS('OverNight €'!$R$373:$R$750,'OverNight €'!$B$373:$B$750,A28) -> 4198.6301
A29: =CONCATENATE(MONTH(D29)," ",YEAR(D29)) -> 5 2026 | B29: =EOMONTH(B28,1) -> 46173 | D29: =EOMONTH(D28,1) -> 46173 | E29: SG | F29: CAT Tréso Plus | G29: =H28 -> 46147 | H29: =EDATE(G29,1) -> 46178 | I29: =INDEX('OverNight €'!$O$376:$O$750,MATCH($B29,'OverNight €'!$D$376:$D$750,0)) -> 0.02169863 | J29: =INDEX('OverNight €'!$N$376:$N$750,MATCH(B29,'OverNight €'!$C$376:$C$750,0)) -> 12000000 | K29: =SUMIFS('OverNight €'!$P$373:$P$750,'OverNight €'!$B$373:$B$750,A29) -> 22421.918 | M29: =SUMIFS('OverNight €'!$R$373:$R$750,'OverNight €'!$B$373:$B$750,A29) -> 4338.5845
A30: =CONCATENATE(MONTH(D30)," ",YEAR(D30)) -> 6 2026 | B30: =EOMONTH(B29,1) -> 46203 | D30: =EOMONTH(D29,1) -> 46203 | E30: SG | F30: CAT Tréso Plus | G30: =H29 -> 46178 | H30: =EDATE(G30,1) -> 46208 | I30: =INDEX('OverNight €'!$O$376:$O$750,MATCH($B30,'OverNight €'!$D$376:$D$750,0)) -> 0.02169863 | J30: =INDEX('OverNight €'!$N$376:$N$750,MATCH(B30,'OverNight €'!$C$376:$C$750,0)) -> 12000000 | K30: =SUMIFS('OverNight €'!$P$373:$P$750,'OverNight €'!$B$373:$B$750,A30) -> 21698.63 | M30: =SUMIFS('OverNight €'!$R$373:$R$750,'OverNight €'!$B$373:$B$750,A30) -> 4198.6301
A31: =CONCATENATE(MONTH(D31)," ",YEAR(D31)) -> 7 2026 | B31: =EOMONTH(B30,1) -> 46234 | D31: =EOMONTH(D30,1) -> 46234 | E31: SG | F31: CAT Tréso Plus | G31: =H30 -> 46208 | H31: =EDATE(G31,1) -> 46239 | I31: =INDEX('OverNight €'!$O$376:$O$750,MATCH($B31,'OverNight €'!$D$376:$D$750,0)) -> 0.02169863 | J31: =INDEX('OverNight €'!$N$376:$N$750,MATCH(B31,'OverNight €'!$C$376:$C$750,0)) -> 12000000 | K31: =SUMIFS('OverNight €'!$P$373:$P$750,'OverNight €'!$B$373:$B$750,A31) -> 22421.918 | M31: =SUMIFS('OverNight €'!$R$373:$R$750,'OverNight €'!$B$373:$B$750,A31) -> 4338.5845
A32: =CONCATENATE(MONTH(D32)," ",YEAR(D32)) -> 8 2026 | B32: =EOMONTH(B31,1) -> 46265 | D32: =EOMONTH(D31,1) -> 46265 | E32: SG | F32: CAT Tréso Plus | G32: =H31 -> 46239 | H32: =EDATE(G32,1) -> 46270 | I32: =INDEX('OverNight €'!$O$376:$O$750,MATCH($B32,'OverNight €'!$D$376:$D$750,0)) -> 0.02169863 | J32: =INDEX('OverNight €'!$N$376:$N$750,MATCH(B32,'OverNight €'!$C$376:$C$750,0)) -> 12000000 | K32: =SUMIFS('OverNight €'!$P$373:$P$750,'OverNight €'!$B$373:$B$750,A32) -> 22421.918 | M32: =SUMIFS('OverNight €'!$R$373:$R$750,'OverNight €'!$B$373:$B$750,A32) -> 4338.5845
A33: =CONCATENATE(MONTH(D33)," ",YEAR(D33)) -> 9 2026 | B33: =EOMONTH(B32,1) -> 46295 | D33: =EOMONTH(D32,1) -> 46295 | E33: SG | F33: CAT Tréso Plus | G33: =H32 -> 46270 | H33: =EDATE(G33,1) -> 46300 | I33: =INDEX('OverNight €'!$O$376:$O$750,MATCH($B33,'OverNight €'!$D$376:$D$750,0)) -> 0.02169863 | J33: =INDEX('OverNight €'!$N$376:$N$750,MATCH(B33,'OverNight €'!$C$376:$C$750,0)) -> 12000000 | K33: =SUMIFS('OverNight €'!$P$373:$P$750,'OverNight €'!$B$373:$B$750,A33) -> 21698.63 | M33: =SUMIFS('OverNight €'!$R$373:$R$750,'OverNight €'!$B$373:$B$750,A33) -> 4198.6301
A34: =CONCATENATE(MONTH(D34)," ",YEAR(D34)) -> 10 2026 | B34: =EOMONTH(B33,1) -> 46326 | D34: =EOMONTH(D33,1) -> 46326 | E34: SG | F34: CAT Tréso Plus | G34: =H33 -> 46300 | H34: =EDATE(G34,1) -> 46331 | I34: =INDEX('OverNight €'!$O$376:$O$750,MATCH($B34,'OverNight €'!$D$376:$D$750,0)) -> 0.02169863 | J34: =INDEX('OverNight €'!$N$376:$N$750,MATCH(B34,'OverNight €'!$C$376:$C$750,0)) -> 12000000 | K34: =SUMIFS('OverNight €'!$P$373:$P$750,'OverNight €'!$B$373:$B$750,A34) -> 22421.918 | M34: =SUMIFS('OverNight €'!$R$373:$R$750,'OverNight €'!$B$373:$B$750,A34) -> 4338.5845
A35: =CONCATENATE(MONTH(D35)," ",YEAR(D35)) -> 11 2026 | B35: =EOMONTH(B34,1) -> 46356 | D35: =EOMONTH(D34,1) -> 46356 | E35: SG | F35: CAT Tréso Plus | G35: =H34 -> 46331 | H35: =EDATE(G35,1) -> 46361 | I35: =INDEX('OverNight €'!$O$376:$O$750,MATCH($B35,'OverNight €'!$D$376:$D$750,0)) -> 0.02169863 | J35: =INDEX('OverNight €'!$N$376:$N$750,MATCH(B35,'OverNight €'!$C$376:$C$750,0)) -> 12000000 | K35: =SUMIFS('OverNight €'!$P$373:$P$750,'OverNight €'!$B$373:$B$750,A35) -> 21698.63 | M35: =SUMIFS('OverNight €'!$R$373:$R$750,'OverNight €'!$B$373:$B$750,A35) -> 4198.6301
A36: =CONCATENATE(MONTH(D36)," ",YEAR(D36)) -> 12 2026 | B36: =EOMONTH(B35,1) -> 46387 | D36: =EOMONTH(D35,1) -> 46387 | E36: SG | F36: CAT Tréso Plus | G36: =H35 -> 46361 | H36: =EDATE(G36,1) -> 46392 | I36: =INDEX('OverNight €'!$O$376:$O$750,MATCH($B36,'OverNight €'!$D$376:$D$750,0)) -> 0.02169863 | J36: =INDEX('OverNight €'!$N$376:$N$750,MATCH(B36,'OverNight €'!$C$376:$C$750,0)) -> 12000000 | K36: =SUMIFS('OverNight €'!$P$373:$P$750,'OverNight €'!$B$373:$B$750,A36) -> 22421.918 | M36: =SUMIFS('OverNight €'!$R$373:$R$750,'OverNight €'!$B$373:$B$750,A36) -> 4338.5845
D37: Total 2026 CAT Tréso Plus | I37: =AVERAGE(I25) -> 0.02169863 | K37: =SUM(K25:K25) -> 22421.918 | L37: =SUM(L25:L25) -> 22421.92 | M37: =SUM(M25:M25) -> 4338.5845
A39: =CONCATENATE(MONTH(D39)," ",YEAR(D39)) -> 1 2026 | B39: 46053 | D39: 46053 | E39: SG | F39: CAT Tréso Plus n°2 | G39: 45668 | H39: =EDATE(G39,1) -> 45699 | I39: =INDEX('OverNight €'!$V$376:$V$750,MATCH($B39,'OverNight €'!$D$376:$D$750,0)) -> 0.021205479 | J39: =INDEX('OverNight €'!$U$376:$U$750,MATCH($B39,'OverNight €'!$D$376:$D$750,0)) -> 6010956.2 | K39: =SUMIFS('OverNight €'!$W$373:$W$750,'OverNight €'!$B$373:$B$750,$A39) -> 10969.072 | L39: 10956.16 | M39: =SUMIFS('OverNight €'!$Y$373:$Y$750,'OverNight €'!$B$373:$B$750,$A39) -> 1916.7532 | O39: OK
A40: =CONCATENATE(MONTH(D40)," ",YEAR(D40)) -> 2 2026 | B40: =EOMONTH(B39,1) -> 46081 | D40: =EOMONTH(D39,1) -> 46081 | E40: SG | F40: CAT Tréso Plus n°2 | G40: =H39 -> 45699 | H40: =EDATE(G40,1) -> 45727 | I40: =INDEX('OverNight €'!$V$376:$V$750,MATCH($B40,'OverNight €'!$D$376:$D$750,0)) -> 0.021205479 | J40: =INDEX('OverNight €'!$U$376:$U$750,MATCH($B40,'OverNight €'!$D$376:$D$750,0)) -> 6010956.2 | K40: =SUMIFS('OverNight €'!$W$373:$W$750,'OverNight €'!$B$373:$B$750,$A40) -> 9913.9606 | M40: =SUMIFS('OverNight €'!$Y$373:$Y$750,'OverNight €'!$B$373:$B$750,$A40) -> 1732.3814
A41: =CONCATENATE(MONTH(D41)," ",YEAR(D41)) -> 3 2026 | B41: =EOMONTH(B40,1) -> 46112 | D41: =EOMONTH(D40,1) -> 46112 | E41: SG | F41: CAT Tréso Plus n°2 | G41: =H40 -> 45727 | H41: =EDATE(G41,1) -> 45758 | I41: =INDEX('OverNight €'!$V$376:$V$750,MATCH($B41,'OverNight €'!$D$376:$D$750,0)) -> 0.021205479 | J41: =INDEX('OverNight €'!$U$376:$U$750,MATCH($B41,'OverNight €'!$D$376:$D$750,0)) -> 6010956.2 | K41: =SUMIFS('OverNight €'!$W$373:$W$750,'OverNight €'!$B$373:$B$750,$A41) -> 10976.171 | M41: =SUMIFS('OverNight €'!$Y$373:$Y$750,'OverNight €'!$B$373:$B$750,$A41) -> 1917.9936
A42: =CONCATENATE(MONTH(D42)," ",YEAR(D42)) -> 4 2026 | B42: =EOMONTH(B41,1) -> 46142 | D42: =EOMONTH(D41,1) -> 46142 | E42: SG | F42: CAT Tréso Plus n°2 | G42: =H41 -> 45758 | H42: =EDATE(G42,1) -> 45788 | I42: =INDEX('OverNight €'!$V$376:$V$750,MATCH($B42,'OverNight €'!$D$376:$D$750,0)) -> 0.021205479 | J42: =INDEX('OverNight €'!$U$376:$U$750,MATCH($B42,'OverNight €'!$D$376:$D$750,0)) -> 6010956.2 | K42: =SUMIFS('OverNight €'!$W$373:$W$750,'OverNight €'!$B$373:$B$750,$A42) -> 10622.101 | M42: =SUMIFS('OverNight €'!$Y$373:$Y$750,'OverNight €'!$B$373:$B$750,$A42) -> 1856.1229
A43: =CONCATENATE(MONTH(D43)," ",YEAR(D43)) -> 5 2026 | B43: =EOMONTH(B42,1) -> 46173 | D43: =EOMONTH(D42,1) -> 46173 | E43: SG | F43: CAT Tréso Plus n°2 | G43: =H42 -> 45788 | H43: =EDATE(G43,1) -> 45819 | I43: =INDEX('OverNight €'!$V$376:$V$750,MATCH($B43,'OverNight €'!$D$376:$D$750,0)) -> 0.021205479 | J43: =INDEX('OverNight €'!$U$376:$U$750,MATCH($B43,'OverNight €'!$D$376:$D$750,0)) -> 6010956.2 | K43: =SUMIFS('OverNight €'!$W$373:$W$750,'OverNight €'!$B$373:$B$750,$A43) -> 10976.171 | M43: =SUMIFS('OverNight €'!$Y$373:$Y$750,'OverNight €'!$B$373:$B$750,$A43) -> 1917.9936
A44: =CONCATENATE(MONTH(D44)," ",YEAR(D44)) -> 6 2026 | B44: =EOMONTH(B43,1) -> 46203 | D44: =EOMONTH(D43,1) -> 46203 | E44: SG | F44: CAT Tréso Plus n°2 | G44: =H43 -> 45819 | H44: =EDATE(G44,1) -> 45849 | I44: =INDEX('OverNight €'!$V$376:$V$750,MATCH($B44,'OverNight €'!$D$376:$D$750,0)) -> 0.021205479 | J44: =INDEX('OverNight €'!$U$376:$U$750,MATCH($B44,'OverNight €'!$D$376:$D$750,0)) -> 6010956.2 | K44: =SUMIFS('OverNight €'!$W$373:$W$750,'OverNight €'!$B$373:$B$750,$A44) -> 10622.101 | M44: =SUMIFS('OverNight €'!$Y$373:$Y$750,'OverNight €'!$B$373:$B$750,$A44) -> 1856.1229
A45: =CONCATENATE(MONTH(D45)," ",YEAR(D45)) -> 7 2026 | B45: =EOMONTH(B44,1) -> 46234 | D45: =EOMONTH(D44,1) -> 46234 | E45: SG | F45: CAT Tréso Plus n°2 | G45: =H44 -> 45849 | H45: =EDATE(G45,1) -> 45880 | I45: =INDEX('OverNight €'!$V$376:$V$750,MATCH($B45,'OverNight €'!$D$376:$D$750,0)) -> 0.021205479 | J45: =INDEX('OverNight €'!$U$376:$U$750,MATCH($B45,'OverNight €'!$D$376:$D$750,0)) -> 6010956.2 | K45: =SUMIFS('OverNight €'!$W$373:$W$750,'OverNight €'!$B$373:$B$750,$A45) -> 10976.171 | M45: =SUMIFS('OverNight €'!$Y$373:$Y$750,'OverNight €'!$B$373:$B$750,$A45) -> 1917.9936
A46: =CONCATENATE(MONTH(D46)," ",YEAR(D46)) -> 8 2026 | B46: =EOMONTH(B45,1) -> 46265 | D46: =EOMONTH(D45,1) -> 46265 | E46: SG | F46: CAT Tréso Plus n°2 | G46: =H45 -> 45880 | H46: =EDATE(G46,1) -> 45911 | I46: =INDEX('OverNight €'!$V$376:$V$750,MATCH($B46,'OverNight €'!$D$376:$D$750,0)) -> 0.021205479 | J46: =INDEX('OverNight €'!$U$376:$U$750,MATCH($B46,'OverNight €'!$D$376:$D$750,0)) -> 6010956.2 | K46: =SUMIFS('OverNight €'!$W$373:$W$750,'OverNight €'!$B$373:$B$750,$A46) -> 10976.171 | M46: =SUMIFS('OverNight €'!$Y$373:$Y$750,'OverNight €'!$B$373:$B$750,$A46) -> 1917.9936
A47: =CONCATENATE(MONTH(D47)," ",YEAR(D47)) -> 9 2026 | B47: =EOMONTH(B46,1) -> 46295 | D47: =EOMONTH(D46,1) -> 46295 | E47: SG | F47: CAT Tréso Plus n°2 | G47: =H46 -> 45911 | H47: =EDATE(G47,1) -> 45941 | I47: =INDEX('OverNight €'!$V$376:$V$750,MATCH($B47,'OverNight €'!$D$376:$D$750,0)) -> 0.021205479 | J47: =INDEX('OverNight €'!$U$376:$U$750,MATCH($B47,'OverNight €'!$D$376:$D$750,0)) -> 6010956.2 | K47: =SUMIFS('OverNight €'!$W$373:$W$750,'OverNight €'!$B$373:$B$750,$A47) -> 10622.101 | M47: =SUMIFS('OverNight €'!$Y$373:$Y$750,'OverNight €'!$B$373:$B$750,$A47) -> 1856.1229
A48: =CONCATENATE(MONTH(D48)," ",YEAR(D48)) -> 10 2026 | B48: =EOMONTH(B47,1) -> 46326 | D48: =EOMONTH(D47,1) -> 46326 | E48: SG | F48: CAT Tréso Plus n°2 | G48: =H47 -> 45941 | H48: =EDATE(G48,1) -> 45972 | I48: =INDEX('OverNight €'!$V$376:$V$750,MATCH($B48,'OverNight €'!$D$376:$D$750,0)) -> 0.021205479 | J48: =INDEX('OverNight €'!$U$376:$U$750,MATCH($B48,'OverNight €'!$D$376:$D$750,0)) -> 6010956.2 | K48: =SUMIFS('OverNight €'!$W$373:$W$750,'OverNight €'!$B$373:$B$750,$A48) -> 10976.171 | M48: =SUMIFS('OverNight €'!$Y$373:$Y$750,'OverNight €'!$B$373:$B$750,$A48) -> 1917.9936
...

Sheet Monthly Report 2025 €
L1: 46022
D8: € Cash investments report as of 31 12 2025
B9: Formule | D9: Month | E9: Bank | F9: Investment | G9: Opening Date | H9: Closing Date | I9: Rate * | J9: Amount end of month | K9: Interest due | L9: Interest paid | M9: Profit/NCA
D11: Deposit
A13: 10 2023
A14: 11 2023 | B14: 45230 | D14: 45200 | E14: SG | F14: NCA | G14: 45205 | I14: 0.038 | J14: 150000000 | K14: 278983.33 | L14: 278983.33
A15: 12 2023 | B15: 45260 | D15: 45231 | E15: SG | F15: NCA | G15: 45205 | I15: 0.038 | J15: 191300000 | K15: 559423.33 | L15: 559423.35
B16: 45291 | D16: 45261 | E16: SG | F16: NCA | G16: 45205 | I16: 0.038 | J16: 191200000 | K16: 663965.56 | L16: 623601.11
D17: Total 2023 | K17: 1502372.2 | L17: 1462007.8
A19: 1 2024 | B19: 45322 | D19: 45292 | E19: SG | F19: NCA | G19: 45205 | I19: 0.038 | J19: 184300000 | K19: 614829.44 | L19: 655193.9
A20: 2 2024 | B20: 45351 | D20: 45323 | E20: SG | F20: NCA | I20: 0.038 | J20: 179700000 | K20: 561355 | L20: 561355
A21: 3 2024 | B21: 45382 | D21: 45352 | E21: SG | F21: NCA | I21: 0.038 | J21: 168900000 | K21: 575024.44 | L21: 521528.88
A22: 4 2024 | B22: 45412 | D22: 45383 | E22: SG | F22: NCA | I22: 0.038 | J22: 175300000 | K22: 557987.78 | L22: 611472.77
A23: 5 2024 | B23: 45443 | D23: 45413 | E23: SG | F23: NCA | I23: 0.038 | J23: 153100000 | K23: 536845 | L23: 539061.67
A24: 6 2024 | B24: 45473 | D24: 45444 | E24: SG | F24: NCA | I24: 0.0355 | J24: 169500000 | K24: 471724.44 | L24: 438295.27
A25: 7 2024 | B25: 45504 | D25: 45474 | E25: SG | F25: NCA | I25: 0.0355 | J25: 159950000 | K25: 509306.67 | L25: 542735.84
A26: 8 2024 | B26: 45535 | D26: 45505 | E26: SG | F26: NCA | I26: 0.0355 | J26: 142700000 | K26: 462777.01 | L26: 448705.21
A27: 9 2024 | B27: 45565 | D27: 45536 | E27: SG | F27: NCA | I27: 0.033 | J27: 134800000 | K27: 405311.39 | L27: 419383.19
A28: 10 2024 | B28: 45596 | D28: 45566 | E28: SG | F28: NCA | I28: 0.0305 | J28: 61250000 | K28: 234960.33 | L28: 234960.33
A29: 11 2024 | B29: 45626 | D29: 45597 | E29: SG | F29: NCA | I29: 0.0305 | J29: 61800000 | K29: 181072.57 | L29: 175836.75
A30: 12 2024 | B30: 45657 | D30: 45627 | E30: SG | F30: NCA | I30: 0.0275 | J30: 31100000 | K30: 120010 | L30: 125245.84
D31: Total 2024 NCA | K31: 5231204.1 | L31: 5273774.7
A35: 1 2025 | B35: 45688 | D35: 45688 | E35: SG | F35: NCA | G35: 45205 | I35: 0.0275 | J35: 12000000 | K35: 54071.875 | L35: 54071.89 | M35: 0
A36: 2 2025 | B36: 45716 | D36: 45716 | E36: SG | F36: NCA | I36: 0.025 | J36: 24350000 | K36: 49647.639 | L36: 49647.63 | M36: 0
A37: 3 2025 | B37: 45747 | D37: 45747 | E37: SG | F37: NCA | I37: 0.0225 | J37: 21820000 | K37: 56474.861 | L37: 56474.87 | M37: 0
A38: 4 2025 | B38: 45777 | D38: 45777 | E38: SG | F38: NCA | I38: 0.02 | J38: 11690000 | K38: 29334.236 | L38: 29334.24 | M38: 0
A39: 5 2025 | B39: 45808 | D39: 45808 | E39: SG | F39: NCA | I39: 0.02 | J39: 6430000 | K39: 15132.778 | L39: 14775.55 | M39: 0
A40: 6 2025 | B40: 45838 | D40: 45838 | E40: SG | F40: NCA | I40: 0.0175 | J40: 11530000 | K40: 14464.444 | L40: 14821.66 | M40: 0
A41: 7 2025 | B41: 45869 | D41: 45869 | E41: SG | F41: NCA | I41: 0.0175 | J41: 6120000 | K41: 14420.486 | L41: 14420.49 | M41: 0
A42: 8 2025 | B42: 45900 | D42: 45900 | E42: SG | F42: NCA | I42: 0.0175 | J42: 15800000 | K42: 88886.875 | L42: 87350.77 | M42: 0
A43: 9 2025 | B43: 45930 | D43: 45930 | E43: SG | F43: NCA | I43: 0.0175 | J43: 9445000 | K43: 28973.194 | L43: 30509.31 | M43: 0 | O43: OK fin septembre
A44: 10 2025 | B44: 45961 | D44: 45961 | E44: SG | F44: NCA | I44: 0.0175 | J44: 11244000 | K44: 33940.181 | L44: 33940.17 | M44: 0 | O44: OK fin octobre
A45: 11 2025 | B45: 45991 | D45: 45991 | E45: SG | F45: NCA | I45: 0.0175 | J45: 9710000 | K45: 18029.861 | L45: 17085.84 | M45: 0 | O45: OK au vendredi 26/11
A46: 12 2025 | B46: 46022 | D46: 46022 | E46: SG | F46: NCA | I46: 0.0175 | J46: 3940000 | K46: 14341.736 | L46: 15285.77 | M46: 0 | O46: OK au 31/12
D47: Total 2025 NCA | I47: 0.019791667 | K47: 417718.17 | L47: 417718.19 | M47: 0
A49: 1 2024 | B49: 45565 | D49: 45292 | E49: SG | F49: Dual deposit $ -> € | G49: 45288 | H49: 45320 | I49: 0.08 | J49: 9160025.6 | K49: 65137.962 | L49: 65137.962
A50: 10 2024 | B50: 45596 | D50: 45566 | E50: SG | F50: CAT Tréso Plus | G50: 45567 | H50: 45598 | I50: 0.033534247 | J50: 12000000 | K50: 32416.438 | L50: 0
A51: 10 2024 | B51: 45596 | D51: 45566 | E51: SG | F51: CAT €ster +0,25% n°1,2,3 | G51: 45575 | H51: 45606 | I51: 0.035268164 | J51: 45000000 | K51: 92578.932 | L51: 0 | P51: moyenne arithématique ester entre date blocage et veille de l'échéance de clôture
A52: 11 2024 | B52: 45626 | D52: 45597 | E52: SG | F52: CAT Tréso Plus | G52: 45598 | H52: 45628 | I52: 0.033534247 | J52: 12000000 | K52: 33534.247 | L52: 34652.05
A53: 11 2024 | B53: 45626 | D53: 45597 | E53: SG | F53: CAT €ster +0,25% | G53: 45606 | H53: 45636 | I53: 0.034148712 | J53: 45136664 | K53: 129716.26 | L53: 136664.13
...

Sheet OverNight €
C1: PLACEMENTS DE TRESORERIE AU JOUR LE JOUR | M1: € | T1: €
C2: Date de valeur pr mvt argent Date comptable pour solde | D2: Intérêts dû in fine ( à date d'échéance) | G2: Notice-Call Account Daily | M2: CAT Tréso plus (du 5 au 5) | T2: CAT Tréso plus n°2 (du 11 au 11) | AA2: CAT ARKEA 12m (du 05/11/25 au 05/11/26) | AH2: Ellipsis BNP | AM2: Codéis EUR
B3: mois | C3: Date départ | D3: Date échéance | E3: Nbj | G3: Emetteur | H3: Montant | I3: Taux | J3: Intérêts | K3: Cumul intérêts | M3: Emetteur | N3: Montant | O3: Taux | P3: Intérêts | Q3: Cumul intérêts | R3: Gain/NCA | T3: Emetteur | U3: Montant | V3: Taux | W3: Intérêts | X3: Cumul intérêts | Y3: Gain/NCA | AA3: Emetteur | AB3: Montant | AC3: Taux | AD3: Intérêts | AE3: Cumul intérêts | AF3: Gain/NCA | AH3: Valorisation | AI3: perf annuelle mensuelle annualisée | AJ3: +/- values quotidiennes | AK3: gain/NCA | AM3: Valorisation | AN3: Performance mensuelle annualisée | AO3: +/- values quotidiennes | AP3: gain/NCA | AR3: Total Montant | AS3: Taux BCE | AT3: Taux moyen | AU3: Total Interêts | AV3: Gain Placement/NCA
B5: 1 2025 | C5: 45657 | D5: 45658 | E5: 1 | G5: SG | H5: 31100000 | I5: 0.0275 | J5: =+H5*I5*E5/360 -> 2375.6944 | K5: =J5 -> 2375.6944 | M5: SG | N5: 12000000 | O5: =2.9%*360/365 -> 0.02860274 | P5: =+N5*O5*$E5/360 -> 953.42466 | Q5: =P5 -> 953.42466 | R5: =P5-(+N5*I5*$E5/360) -> 36.757991 | AR5: 1.1836511e+08 | AS5: 0.03 | AT5: 0.0307 | AU5: 10096.42 | AV5: 1054.64
B6: =CONCATENATE(MONTH(D6)," ",YEAR(D6)) -> 1 2025 | C6: =D5 -> 45658 | D6: =C6+1 -> 45659 | E6: =D6-C6 -> 1 | G6: SG | H6: =H5 -> 31100000 | I6: =I5 -> 0.0275 | J6: =+H6*I6*E6/360 -> 2375.6944 | K6: =J6+K5 -> 4751.3889 | M6: SG | N6: =N5 -> 12000000 | O6: =2.9%*360/365 -> 0.02860274 | P6: =+N6*O6*$E6/360 -> 953.42466 | Q6: =Q5+P6 -> 1906.8493 | R6: =P6-(+N6*I6*$E6/360) -> 36.757991 | AR6: 1.1836511e+08 | AS6: 0.03 | AT6: 0.0307 | AU6: 10096.42 | AV6: 1054.64
B7: =CONCATENATE(MONTH(D7)," ",YEAR(D7)) -> 1 2025 | C7: =D6 -> 45659 | D7: =D6+1 -> 45660 | E7: =D7-C7 -> 1 | G7: SG | H7: =H6-4900000 -> 26200000 | I7: =I6 -> 0.0275 | J7: =+H7*I7*E7/360 -> 2001.3889 | K7: =K6+J7 -> 6752.7778 | M7: SG | N7: =N6 -> 12000000 | O7: =2.9%*360/365 -> 0.02860274 | P7: =+N7*O7*$E7/360 -> 953.42466 | Q7: =Q6+P7 -> 2860.274 | R7: =P7-(+N7*I7*$E7/360) -> 36.757991 | AR7: 1.1346511e+08 | AS7: 0.03 | AT7: 0.0308 | AU7: 9722.12 | AV7: 1054.64
B8: =CONCATENATE(MONTH(D8)," ",YEAR(D8)) -> 1 2025 | C8: =D7 -> 45660 | D8: =D7+1 -> 45661 | E8: =D8-C8 -> 1 | G8: SG | H8: =H7-100000 -> 26100000 | I8: =I7 -> 0.0275 | J8: =+H8*I8*E8/360 -> 1993.75 | K8: =K7+J8 -> 8746.5278 | M8: SG | N8: =N7 -> 12000000 | O8: =2.9%*360/365 -> 0.02860274 | P8: =+N8*O8*$E8/360 -> 953.42466 | Q8: =Q7+P8 -> 3813.6986 | R8: =P8-(+N8*I8*$E8/360) -> 36.757991 | AR8: 1.1336511e+08 | AS8: 0.03 | AT8: 0.0308 | AU8: 9714.48 | AV8: 1054.64
B9: =CONCATENATE(MONTH(D9)," ",YEAR(D9)) -> 1 2025 | C9: =D8 -> 45661 | D9: =D8+1 -> 45662 | E9: =D9-C9 -> 1 | G9: SG | H9: =H8 -> 26100000 | I9: =I8 -> 0.0275 | J9: =+H9*I9*E9/360 -> 1993.75 | K9: =K8+J9 -> 10740.278 | M9: SG | N9: =N8 -> 12000000 | O9: =2.9%*360/365 -> 0.02860274 | P9: =+N9*O9*$E9/360 -> 953.42466 | Q9: =Q8+P9 -> 4767.1233 | R9: =P9-(+N9*I9*$E9/360) -> 36.757991 | AR9: 1.1336511e+08 | AS9: 0.03 | AT9: 0.0308 | AU9: 9714.48 | AV9: 1054.64
B10: =CONCATENATE(MONTH(D10)," ",YEAR(D10)) -> 1 2025 | C10: =D9 -> 45662 | D10: =D9+1 -> 45663 | E10: =D10-C10 -> 1 | G10: SG | H10: =H9 -> 26100000 | I10: =I9 -> 0.0275 | J10: =+H10*I10*E10/360 -> 1993.75 | K10: =K9+J10 -> 12734.028 | M10: SG | N10: =N9 -> 12000000 | O10: =2.9%*360/365 -> 0.02860274 | P10: =+N10*O10*$E10/360 -> 953.42466 | Q10: =Q9+P10 -> 5720.5479 | R10: =P10-(+N10*I10*$E10/360) -> 36.757991 | AR10: 1.1336511e+08 | AS10: 0.03 | AT10: 0.0308 | AU10: 9714.48 | AV10: 1054.64
B11: =CONCATENATE(MONTH(D11)," ",YEAR(D11)) -> 1 2025 | C11: =D10 -> 45663 | D11: =D10+1 -> 45664 | E11: =D11-C11 -> 1 | G11: SG | H11: =H10 -> 26100000 | I11: =I10 -> 0.0275 | J11: =+H11*I11*E11/360 -> 1993.75 | K11: =K10+J11 -> 14727.778 | M11: SG | N11: =N10 -> 12000000 | O11: =O10 -> 0.02860274 | P11: =+N11*O11*$E11/360 -> 953.42466 | Q11: =Q10+P11 -> 6673.9726 | R11: =P11-(+N11*I11*$E11/360) -> 36.757991 | AR11: 1.1336511e+08 | AS11: 0.03 | AT11: 0.0308 | AU11: 9714.48 | AV11: 1054.64
B12: =CONCATENATE(MONTH(D12)," ",YEAR(D12)) -> 1 2025 | C12: =D11 -> 45664 | D12: =D11+1 -> 45665 | E12: =D12-C12 -> 1 | G12: SG | H12: =H11 -> 26100000 | I12: =I11 -> 0.0275 | J12: =+H12*I12*E12/360 -> 1993.75 | K12: =K11+J12 -> 16721.528 | M12: SG | N12: =N11 -> 12000000 | O12: =O11 -> 0.02860274 | P12: =+N12*O12*$E12/360 -> 953.42466 | Q12: =Q11+P12 -> 7627.3973 | R12: =P12-(+N12*I12*$E12/360) -> 36.757991 | AR12: 1.1336511e+08 | AS12: 0.03 | AT12: 0.0308 | AU12: 9714.48 | AV12: 1054.64
B13: =CONCATENATE(MONTH(D13)," ",YEAR(D13)) -> 1 2025 | C13: =D12 -> 45665 | D13: =D12+1 -> 45666 | E13: =D13-C13 -> 1 | G13: SG | H13: =H12 -> 26100000 | I13: =I12 -> 0.0275 | J13: =+H13*I13*E13/360 -> 1993.75 | K13: =K12+J13 -> 18715.278 | M13: SG | N13: =N12 -> 12000000 | O13: =O12 -> 0.02860274 | P13: =+N13*O13*$E13/360 -> 953.42466 | Q13: =Q12+P13 -> 8580.8219 | R13: =P13-(+N13*I13*$E13/360) -> 36.757991 | AR13: 1.1336511e+08 | AS13: 0.03 | AT13: 0.0308 | AU13: 9714.48 | AV13: 1054.64
B14: =CONCATENATE(MONTH(D14)," ",YEAR(D14)) -> 1 2025 | C14: =D13 -> 45666 | D14: =D13+1 -> 45667 | E14: =D14-C14 -> 1 | G14: SG | H14: =H13+300000 -> 26400000 | I14: =I13 -> 0.0275 | J14: =+H14*I14*E14/360 -> 2016.6667 | K14: =K13+J14 -> 20731.944 | M14: SG | N14: =N13 -> 12000000 | O14: =O13 -> 0.02860274 | P14: =+N14*O14*$E14/360 -> 953.42466 | Q14: =Q13+P14 -> 9534.2466 | R14: =P14-(+N14*I14*$E14/360) -> 36.757991 | AR14: 1.1366511e+08 | AS14: 0.03 | AT14: 0.0308 | AU14: 9737.39 | AV14: 1054.64
B15: =CONCATENATE(MONTH(D15)," ",YEAR(D15)) -> 1 2025 | C15: =D14 -> 45667 | D15: =D14+1 -> 45668 | E15: =D15-C15 -> 1 | G15: SG | H15: =H14 -> 26400000 | I15: =I14 -> 0.0275 | J15: =+H15*I15*E15/360 -> 2016.6667 | K15: =K14+J15 -> 22748.611 | M15: SG | N15: =N14 -> 12000000 | O15: =O14 -> 0.02860274 | P15: =+N15*O15*$E15/360 -> 953.42466 | Q15: =Q14+P15 -> 10487.671 | R15: =P15-(+N15*I15*$E15/360) -> 36.757991 | AR15: 1.137913e+08 | AS15: 0.03 | AT15: 0.0304 | AU15: 9621.65 | AV15: 929.26
B16: =CONCATENATE(MONTH(D16)," ",YEAR(D16)) -> 1 2025 | C16: =D15 -> 45668 | D16: =D15+1 -> 45669 | E16: =D16-C16 -> 1 | G16: SG | H16: =H15 -> 26400000 | I16: =I15 -> 0.0275 | J16: =+H16*I16*E16/360 -> 2016.6667 | K16: =K15+J16 -> 24765.278 | M16: SG | N16: =N15 -> 12000000 | O16: =O15 -> 0.02860274 | P16: =+N16*O16*$E16/360 -> 953.42466 | Q16: =Q15+P16 -> 11441.096 | R16: =P16-(+N16*I16*$E16/360) -> 36.757991 | AR16: 1.137913e+08 | AS16: 0.03 | AT16: 0.0304 | AU16: 9621.65 | AV16: 929.26
B17: =CONCATENATE(MONTH(D17)," ",YEAR(D17)) -> 1 2025 | C17: =D16 -> 45669 | D17: =D16+1 -> 45670 | E17: =D17-C17 -> 1 | G17: SG | H17: =H16 -> 26400000 | I17: =I16 -> 0.0275 | J17: =+H17*I17*E17/360 -> 2016.6667 | K17: =K16+J17 -> 26781.944 | M17: SG | N17: =N16 -> 12000000 | O17: =O16 -> 0.02860274 | P17: =+N17*O17*$E17/360 -> 953.42466 | Q17: =Q16+P17 -> 12394.521 | R17: =P17-(+N17*I17*$E17/360) -> 36.757991 | AR17: 1.137913e+08 | AS17: 0.03 | AT17: 0.0304 | AU17: 9621.65 | AV17: 929.26
B18: =CONCATENATE(MONTH(D18)," ",YEAR(D18)) -> 1 2025 | C18: =D17 -> 45670 | D18: =D17+1 -> 45671 | E18: =D18-C18 -> 1 | G18: SG | H18: =H17-1700000 -> 24700000 | I18: =I17 -> 0.0275 | J18: =+H18*I18*E18/360 -> 1886.8056 | K18: =K17+J18 -> 28668.75 | M18: SG | N18: =N17 -> 12000000 | O18: =O17 -> 0.02860274 | P18: =+N18*O18*$E18/360 -> 953.42466 | Q18: =Q17+P18 -> 13347.945 | R18: =P18-(+N18*I18*$E18/360) -> 36.757991 | AR18: 1.120913e+08 | AS18: 0.03 | AT18: 0.0305 | AU18: 9491.78 | AV18: 929.26
B19: =CONCATENATE(MONTH(D19)," ",YEAR(D19)) -> 1 2025 | C19: =D18 -> 45671 | D19: =D18+1 -> 45672 | E19: =D19-C19 -> 1 | G19: SG | H19: =H18 -> 24700000 | I19: =I18 -> 0.0275 | J19: =+H19*I19*E19/360 -> 1886.8056 | K19: =K18+J19 -> 30555.556 | M19: SG | N19: =N18 -> 12000000 | O19: =O18 -> 0.02860274 | P19: =+N19*O19*$E19/360 -> 953.42466 | Q19: =Q18+P19 -> 14301.37 | R19: =P19-(+N19*I19*$E19/360) -> 36.757991 | AR19: 1.120913e+08 | AS19: 0.03 | AT19: 0.0305 | AU19: 9491.78 | AV19: 929.26
B20: =CONCATENATE(MONTH(D20)," ",YEAR(D20)) -> 1 2025 | C20: =D19 -> 45672 | D20: =D19+1 -> 45673 | E20: =D20-C20 -> 1 | G20: SG | H20: =H19 -> 24700000 | I20: =I19 -> 0.0275 | J20: =+H20*I20*E20/360 -> 1886.8056 | K20: =K19+J20 -> 32442.361 | M20: SG | N20: =N19 -> 12000000 | O20: =O19 -> 0.02860274 | P20: =+N20*O20*$E20/360 -> 953.42466 | Q20: =Q19+P20 -> 15254.795 | R20: =P20-(+N20*I20*$E20/360) -> 36.757991 | AR20: 1.120913e+08 | AS20: 0.03 | AT20: 0.0305 | AU20: 9491.78 | AV20: 929.26
B21: =CONCATENATE(MONTH(D21)," ",YEAR(D21)) -> 1 2025 | C21: =D20 -> 45673 | D21: =D20+1 -> 45674 | E21: =D21-C21 -> 1 | G21: SG | H21: =H20-450000 -> 24250000 | I21: =I20 -> 0.0275 | J21: =+H21*I21*E21/360 -> 1852.4306 | K21: =K20+J21 -> 34294.792 | M21: SG | N21: =N20 -> 12000000 | O21: =O20 -> 0.02860274 | P21: =+N21*O21*$E21/360 -> 953.42466 | Q21: =Q20+P21 -> 16208.219 | R21: =P21-(+N21*I21*$E21/360) -> 36.757991 | AR21: 1.116413e+08 | AS21: 0.03 | AT21: 0.0305 | AU21: 9457.41 | AV21: 929.26
B22: =CONCATENATE(MONTH(D22)," ",YEAR(D22)) -> 1 2025 | C22: =D21 -> 45674 | D22: =D21+1 -> 45675 | E22: =D22-C22 -> 1 | G22: SG | H22: =H21+50000 -> 24300000 | I22: =I21 -> 0.0275 | J22: =+H22*I22*E22/360 -> 1856.25 | K22: =K21+J22 -> 36151.042 | M22: SG | N22: =N21 -> 12000000 | O22: =O21 -> 0.02860274 | P22: =+N22*O22*$E22/360 -> 953.42466 | Q22: =Q21+P22 -> 17161.644 | R22: =P22-(+N22*I22*$E22/360) -> 36.757991 | AR22: 1.116913e+08 | AS22: 0.03 | AT22: 0.0305 | AU22: 9461.23 | AV22: 929.26
B23: =CONCATENATE(MONTH(D23)," ",YEAR(D23)) -> 1 2025 | C23: =D22 -> 45675 | D23: =D22+1 -> 45676 | E23: =D23-C23 -> 1 | G23: SG | H23: =H22 -> 24300000 | I23: =I22 -> 0.0275 | J23: =+H23*I23*E23/360 -> 1856.25 | K23: =K22+J23 -> 38007.292 | M23: SG | N23: =N22 -> 12000000 | O23: =O22 -> 0.02860274 | P23: =+N23*O23*$E23/360 -> 953.42466 | Q23: =Q22+P23 -> 18115.068 | R23: =P23-(+N23*I23*$E23/360) -> 36.757991 | AR23: 1.116913e+08 | AS23: 0.03 | AT23: 0.0305 | AU23: 9461.23 | AV23: 929.26
B24: =CONCATENATE(MONTH(D24)," ",YEAR(D24)) -> 1 2025 | C24: =D23 -> 45676 | D24: =D23+1 -> 45677 | E24: =D24-C24 -> 1 | G24: SG | H24: =H23 -> 24300000 | I24: =I23 -> 0.0275 | J24: =+H24*I24*E24/360 -> 1856.25 | K24: =K23+J24 -> 39863.542 | M24: SG | N24: =N23 -> 12000000 | O24: =O23 -> 0.02860274 | P24: =+N24*O24*$E24/360 -> 953.42466 | Q24: =Q23+P24 -> 19068.493 | R24: =P24-(+N24*I24*$E24/360) -> 36.757991 | AR24: 1.116913e+08 | AS24: 0.03 | AT24: 0.0305 | AU24: 9461.23 | AV24: 929.26
B25: =CONCATENATE(MONTH(D25)," ",YEAR(D25)) -> 1 2025 | C25: =D24 -> 45677 | D25: =D24+1 -> 45678 | E25: =D25-C25 -> 1 | G25: SG | H25: =H24 -> 24300000 | I25: =I24 -> 0.0275 | J25: =+H25*I25*E25/360 -> 1856.25 | K25: =K24+J25 -> 41719.792 | M25: SG | N25: =N24 -> 12000000 | O25: =O24 -> 0.02860274 | P25: =+N25*O25*$E25/360 -> 953.42466 | Q25: =Q24+P25 -> 20021.918 | R25: =P25-(+N25*I25*$E25/360) -> 36.757991 | AR25: 1.116913e+08 | AS25: 0.03 | AT25: 0.0305 | AU25: 9461.23 | AV25: 929.26
B26: =CONCATENATE(MONTH(D26)," ",YEAR(D26)) -> 1 2025 | C26: =D25 -> 45678 | D26: =D25+1 -> 45679 | E26: =D26-C26 -> 1 | G26: SG | H26: =H25-5350000 -> 18950000 | I26: =I25 -> 0.0275 | J26: =+H26*I26*E26/360 -> 1447.5694 | K26: =K25+J26 -> 43167.361 | M26: SG | N26: =N25 -> 12000000 | O26: =O25 -> 0.02860274 | P26: =+N26*O26*$E26/360 -> 953.42466 | Q26: =Q25+P26 -> 20975.342 | R26: =P26-(+N26*I26*$E26/360) -> 36.757991 | AR26: 1.063413e+08 | AS26: 0.03 | AT26: 0.0306 | AU26: 9052.55 | AV26: 929.26
B27: =CONCATENATE(MONTH(D27)," ",YEAR(D27)) -> 1 2025 | C27: =D26 -> 45679 | D27: =D26+1 -> 45680 | E27: =D27-C27 -> 1 | G27: SG | H27: =H26 -> 18950000 | I27: =I26 -> 0.0275 | J27: =+H27*I27*E27/360 -> 1447.5694 | K27: =K26+J27 -> 44614.931 | M27: SG | N27: =N26 -> 12000000 | O27: =O26 -> 0.02860274 | P27: =+N27*O27*$E27/360 -> 953.42466 | Q27: =Q26+P27 -> 21928.767 | R27: =P27-(+N27*I27*$E27/360) -> 36.757991 | AR27: 1.063413e+08 | AS27: 0.03 | AT27: 0.0306 | AU27: 9052.55 | AV27: 929.26
B28: =CONCATENATE(MONTH(D28)," ",YEAR(D28)) -> 1 2025 | C28: =D27 -> 45680 | D28: =D27+1 -> 45681 | E28: =D28-C28 -> 1 | G28: SG | H28: =H27 -> 18950000 | I28: =I27 -> 0.0275 | J28: =+H28*I28*E28/360 -> 1447.5694 | K28: =K27+J28 -> 46062.5 | M28: SG | N28: =N27 -> 12000000 | O28: =O27 -> 0.02860274 | P28: =+N28*O28*$E28/360 -> 953.42466 | Q28: =Q27+P28 -> 22882.192 | R28: =P28-(+N28*I28*$E28/360) -> 36.757991 | AR28: 1.063413e+08 | AS28: 0.03 | AT28: 0.0306 | AU28: 9052.55 | AV28: 929.26
B29: =CONCATENATE(MONTH(D29)," ",YEAR(D29)) -> 1 2025 | C29: =D28 -> 45681 | D29: =D28+1 -> 45682 | E29: =D29-C29 -> 1 | G29: SG | H29: =H28 -> 18950000 | I29: =I28 -> 0.0275 | J29: =+H29*I29*E29/360 -> 1447.5694 | K29: =K28+J29 -> 47510.069 | M29: SG | N29: =N28 -> 12000000 | O29: =O28 -> 0.02860274 | P29: =+N29*O29*$E29/360 -> 953.42466 | Q29: =Q28+P29 -> 23835.616 | R29: =P29-(+N29*I29*$E29/360) -> 36.757991 | AR29: 1.063413e+08 | AS29: 0.03 | AT29: 0.0306 | AU29: 9052.55 | AV29: 929.26
B30: =CONCATENATE(MONTH(D30)," ",YEAR(D30)) -> 1 2025 | C30: =D29 -> 45682 | D30: =D29+1 -> 45683 | E30: =D30-C30 -> 1 | G30: SG | H30: =H29 -> 18950000 | I30: =I29 -> 0.0275 | J30: =+H30*I30*E30/360 -> 1447.5694 | K30: =K29+J30 -> 48957.639 | M30: SG | N30: =N29 -> 12000000 | O30: =O29 -> 0.02860274 | P30: =+N30*O30*$E30/360 -> 953.42466 | Q30: =Q29+P30 -> 24789.041 | R30: =P30-(+N30*I30*$E30/360) -> 36.757991 | AR30: 1.063413e+08 | AS30: 0.03 | AT30: 0.0306 | AU30: 9052.55 | AV30: 929.26
B31: =CONCATENATE(MONTH(D31)," ",YEAR(D31)) -> 1 2025 | C31: =D30 -> 45683 | D31: =D30+1 -> 45684 | E31: =D31-C31 -> 1 | G31: SG | H31: =H30 -> 18950000 | I31: =I30 -> 0.0275 | J31: =+H31*I31*E31/360 -> 1447.5694 | K31: =K30+J31 -> 50405.208 | M31: SG | N31: =N30 -> 12000000 | O31: =O30 -> 0.02860274 | P31: =+N31*O31*$E31/360 -> 953.42466 | Q31: =Q30+P31 -> 25742.466 | R31: =P31-(+N31*I31*$E31/360) -> 36.757991 | AR31: 1.063413e+08 | AS31: 0.03 | AT31: 0.0306 | AU31: 9052.55 | AV31: 929.26
B32: =CONCATENATE(MONTH(D32)," ",YEAR(D32)) -> 1 2025 | C32: =D31 -> 45684 | D32: =D31+1 -> 45685 | E32: =D32-C32 -> 1 | G32: SG | H32: =H31-6700000 -> 12250000 | I32: =I31 -> 0.0275 | J32: =+H32*I32*E32/360 -> 935.76389 | K32: =K31+J32 -> 51340.972 | M32: SG | N32: =N31 -> 12000000 | O32: =O31 -> 0.02860274 | P32: =+N32*O32*$E32/360 -> 953.42466 | Q32: =Q31+P32 -> 26695.89 | R32: =P32-(+N32*I32*$E32/360) -> 36.757991 | AR32: 99641300 | AS32: 0.03 | AT32: 0.0309 | AU32: 8540.74 | AV32: 929.26
B33: =CONCATENATE(MONTH(D33)," ",YEAR(D33)) -> 1 2025 | C33: =D32 -> 45685 | D33: =D32+1 -> 45686 | E33: =D33-C33 -> 1 | G33: SG | H33: =H32-400000+50000 -> 11900000 | I33: =I32 -> 0.0275 | J33: =+H33*I33*E33/360 -> 909.02778 | K33: =K32+J33 -> 52250 | M33: SG | N33: =N32 -> 12000000 | O33: =O32 -> 0.02860274 | P33: =+N33*O33*$E33/360 -> 953.42466 | Q33: =Q32+P33 -> 27649.315 | R33: =P33-(+N33*I33*$E33/360) -> 36.757991 | AR33: 99291300 | AS33: 0.03 | AT33: 0.0309 | AU33: 8514.01 | AV33: 929.26
B34: =CONCATENATE(MONTH(D34)," ",YEAR(D34)) -> 1 2025 | C34: =D33 -> 45686 | D34: =D33+1 -> 45687 | E34: =D34-C34 -> 1 | G34: SG | H34: =H33 -> 11900000 | I34: =I33 -> 0.0275 | J34: =+H34*I34*E34/360 -> 909.02778 | K34: =K33+J34 -> 53159.028 | M34: SG | N34: =N33 -> 12000000 | O34: =O33 -> 0.02860274 | P34: =+N34*O34*$E34/360 -> 953.42466 | Q34: =Q33+P34 -> 28602.74 | R34: =P34-(+N34*I34*$E34/360) -> 36.757991 | AR34: 99291300 | AS34: 0.03 | AT34: 0.0309 | AU34: 8514.01 | AV34: 929.26
B35: =CONCATENATE(MONTH(D35)," ",YEAR(D35)) -> 1 2025 | C35: =D34 -> 45687 | D35: =D34+1 -> 45688 | E35: =D35-C35 -> 1 | G35: SG | H35: =H34+50000 -> 11950000 | I35: =I34 -> 0.0275 | J35: =+H35*I35*E35/360 -> 912.84722 | K35: =K34+J35 -> 54071.875 | M35: SG | N35: =N34 -> 12000000 | O35: =O34 -> 0.02860274 | P35: =+N35*O35*$E35/360 -> 953.42466 | Q35: =Q34+P35 -> 29556.164 | R35: =P35-(+N35*I35*$E35/360) -> 36.757991 | AR35: 99341300 | AS35: 0.03 | AT35: 0.0309 | AU35: 8517.83 | AV35: 929.26
B36: =CONCATENATE(MONTH(D36)," ",YEAR(D36)) -> 2 2025 | C36: =D35 -> 45688 | D36: =D35+1 -> 45689 | E36: =D36-C36 -> 1 | G36: SG | H36: =H35+50000 -> 12000000 | I36: =I35 -> 0.0275 | J36: =+H36*I36*E36/360 -> 916.66667 | K36: =K35+J36 -> 54988.542 | M36: SG | N36: =N35 -> 12000000 | O36: =O35 -> 0.02860274 | P36: =+N36*O36*$E36/360 -> 953.42466 | Q36: =Q35+P36 -> 30509.589 | R36: =P36-(+N36*I36*$E36/360) -> 36.757991 | AR36: 99391300 | AS36: 0.03 | AT36: 0.0309 | AU36: 8521.65 | AV36: 929.26
B37: =CONCATENATE(MONTH(D37)," ",YEAR(D37)) -> 2 2025 | C37: =D36 -> 45689 | D37: =D36+1 -> 45690 | E37: =D37-C37 -> 1 | G37: SG | H37: =H36 -> 12000000 | I37: =I36 -> 0.0275 | J37: =+H37*I37*E37/360 -> 916.66667 | K37: =K36+J37 -> 55905.208 | M37: SG | N37: =N36 -> 12000000 | O37: =O36 -> 0.02860274 | P37: =+N37*O37*$E37/360 -> 953.42466 | Q37: =Q36+P37 -> 31463.014 | R37: =P37-(+N37*I37*$E37/360) -> 36.757991 | AR37: 99391300 | AS37: 0.03 | AT37: 0.0309 | AU37: 8521.65 | AV37: 929.26
B38: =CONCATENATE(MONTH(D38)," ",YEAR(D38)) -> 2 2025 | C38: =D37 -> 45690 | D38: =D37+1 -> 45691 | E38: =D38-C38 -> 1 | G38: SG | H38: =H37 -> 12000000 | I38: =I37 -> 0.0275 | J38: =+H38*I38*E38/360 -> 916.66667 | K38: =K37+J38 -> 56821.875 | M38: SG | N38: =N37 -> 12000000 | O38: =O37 -> 0.02860274 | P38: =+N38*O38*$E38/360 -> 953.42466 | Q38: =Q37+P38 -> 32416.438 | R38: =P38-(+N38*I38*$E38/360) -> 36.757991 | AR38: 99391300 | AS38: 0.03 | AT38: 0.0309 | AU38: 8521.65 | AV38: 929.26
B39: =CONCATENATE(MONTH(D39)," ",YEAR(D39)) -> 2 2025 | C39: =D38 -> 45691 | D39: =D38+1 -> 45692 | E39: =D39-C39 -> 1 | G39: SG | H39: =H38+9820000 -> 21820000 | I39: =I38 -> 0.0275 | J39: =+H39*I39*E39/360 -> 1666.8056 | K39: =K38+J39 -> 58488.681 | M39: SG | AR39: 97211300 | AS39: 0.03 | AT39: 0.0308 | AU39: 8318.36 | AV39: 892.5
B40: =CONCATENATE(MONTH(D40)," ",YEAR(D40)) -> 2 2025 | C40: =D39 -> 45692 | D40: =D39+1 -> 45693 | E40: =D40-C40 -> 1 | G40: SG | H40: =H39+3120000 -> 24940000 | I40: =I39 -> 0.0275 | J40: =+H40*I40*E40/360 -> 1905.1389 | K40: =K39+J40 -> 60393.819 | M40: SG | AR40: 1.003313e+08 | AS40: 0.03 | AT40: 0.0307 | AU40: 8556.69 | AV40: 892.5
B41: =CONCATENATE(MONTH(D41)," ",YEAR(D41)) -> 2 2025 | C41: =D40 -> 45693 | D41: =D40+1 -> 45694 | E41: =D41-C41 -> 1 | G41: SG | H41: =H40 -> 24940000 | I41: 0.025 | J41: =+H41*I41*E41/360 -> 1731.9444 | K41: =K40+J41 -> 62125.764 | M41: SG | AR41: 1.003313e+08 | AS41: 0.0275 | AT41: 0.0301 | AU41: 8383.5 | AV41: 1416.05
...

Sheet codeis €
C2: Date de valeur pr mvt argent Date comptable pour solde | D2: Intérêts dû in fine ( à date d'échéance)
B3: Fin de mois | C3: Date départ | D3: Date échéance | E3: Nbj | F3: Emetteur | H3: Date de Valorisation Codéis | I3: VL (Date départ) | K3: Prix initial- 1 Part (EUR) | L3: Achat (Part) | M3: Valos achat | N3: Vente (Part) (31/10/2025) | O3: Part Restttes 31/10/2025 | P3: Vente 05/11/2025 | Q3: Parts Resttes 05/11/2025 | R3: Vente 26/01/2026 | S3: Part resttes 26/01/2026 | T3: Valos de la vente | U3: PV Vente | V3: Prinicpal ventes | X3: Part | Y3: Principal (EUR) | Z3: Valos (Date départ) | AB3: PV/MV depuis origine | AC3: PV quotidienne | AD3: PV mensuel | AF3: Performance mensuelle annualisée | AG3: Performance cumulée et annualisée | AI3: gain/NCA
B5: =CONCATENATE(MONTH(D5)," ",YEAR(D5)) -> 1 2025 | C5: ='OverNight €'!C5 -> 45657 | D5: ='OverNight €'!D5 -> 45658 | E5: =D5-C5 -> 1 | F5: SG | H5: =C5 -> 45657
B6: =CONCATENATE(MONTH(D6)," ",YEAR(D6)) -> 1 2025 | C6: =D5 -> 45658 | D6: =D5+1 -> 45659 | E6: =D6-C6 -> 1 | F6: SG | H6: =C6 -> 45658
B7: =CONCATENATE(MONTH(D7)," ",YEAR(D7)) -> 1 2025 | C7: =D6 -> 45659 | D7: =D6+1 -> 45660 | E7: =D7-C7 -> 1 | F7: SG | H7: =C7 -> 45659
B8: =CONCATENATE(MONTH(D8)," ",YEAR(D8)) -> 1 2025 | C8: =D7 -> 45660 | D8: =D7+1 -> 45661 | E8: =D8-C8 -> 1 | F8: SG | H8: =C8 -> 45660
B9: =CONCATENATE(MONTH(D9)," ",YEAR(D9)) -> 1 2025 | C9: =D8 -> 45661 | D9: =D8+1 -> 45662 | E9: =D9-C9 -> 1 | F9: SG | H9: =C9 -> 45661
B10: =CONCATENATE(MONTH(D10)," ",YEAR(D10)) -> 1 2025 | C10: =D9 -> 45662 | D10: =D9+1 -> 45663 | E10: =D10-C10 -> 1 | F10: SG | H10: =C10 -> 45662
B11: =CONCATENATE(MONTH(D11)," ",YEAR(D11)) -> 1 2025 | C11: =D10 -> 45663 | D11: =D10+1 -> 45664 | E11: =D11-C11 -> 1 | F11: SG | H11: =C11 -> 45663
B12: =CONCATENATE(MONTH(D12)," ",YEAR(D12)) -> 1 2025 | C12: =D11 -> 45664 | D12: =D11+1 -> 45665 | E12: =D12-C12 -> 1 | F12: SG | H12: =C12 -> 45664
B13: =CONCATENATE(MONTH(D13)," ",YEAR(D13)) -> 1 2025 | C13: =D12 -> 45665 | D13: =D12+1 -> 45666 | E13: =D13-C13 -> 1 | F13: SG | H13: =C13 -> 45665
B14: =CONCATENATE(MONTH(D14)," ",YEAR(D14)) -> 1 2025 | C14: =D13 -> 45666 | D14: =D13+1 -> 45667 | E14: =D14-C14 -> 1 | F14: SG | H14: =C14 -> 45666
B15: =CONCATENATE(MONTH(D15)," ",YEAR(D15)) -> 1 2025 | C15: =D14 -> 45667 | D15: =D14+1 -> 45668 | E15: =D15-C15 -> 1 | F15: SG | H15: =C15 -> 45667
B16: =CONCATENATE(MONTH(D16)," ",YEAR(D16)) -> 1 2025 | C16: =D15 -> 45668 | D16: =D15+1 -> 45669 | E16: =D16-C16 -> 1 | F16: SG | H16: =C16 -> 45668
B17: =CONCATENATE(MONTH(D17)," ",YEAR(D17)) -> 1 2025 | C17: =D16 -> 45669 | D17: =D16+1 -> 45670 | E17: =D17-C17 -> 1 | F17: SG | H17: =C17 -> 45669
... B192: =CONCATENATE(MONTH(D192)," ",YEAR(D192)) -> 7 2025 | C192: =D191 -> 45844 | D192: =D191+1 -> 45845 | E192: =D192-C192 -> 1 | F192: SG | H192: =C192 -> 45844
A193: recupérer argent CAT | B193: =CONCATENATE(MONTH(D193)," ",YEAR(D193)) -> 7 2025 | C193: =D192 -> 45845 | D193: =D192+1 -> 45846 | E193: =D193-C193 -> 1 | F193: SG | H193: =C193 -> 45845
B194: =CONCATENATE(MONTH(D194)," ",YEAR(D194)) -> 7 2025 | C194: =D193 -> 45846 | D194: =D193+1 -> 45847 | E194: =D194-C194 -> 1 | F194: SG | H194: =C194 -> 45846
B195: =CONCATENATE(MONTH(D195)," ",YEAR(D195)) -> 7 2025 | C195: =D194 -> 45847 | D195: =D194+1 -> 45848 | E195: =D195-C195 -> 1 | F195: SG | H195: =C195 -> 45847
B196: =CONCATENATE(MONTH(D196)," ",YEAR(D196)) -> 7 2025 | C196: =D195 -> 45848 | D196: =D195+1 -> 45849 | E196: =D196-C196 -> 1 | F196: SG | H196: =C196 -> 45848
B197: =CONCATENATE(MONTH(D197)," ",YEAR(D197)) -> 7 2025 | C197: =D196 -> 45849 | D197: =D196+1 -> 45850 | E197: =D197-C197 -> 1 | F197: SG | H197: =C197 -> 45849
B198: =CONCATENATE(MONTH(D198)," ",YEAR(D198)) -> 7 2025 | C198: =D197 -> 45850 | D198: =D197+1 -> 45851 | E198: =D198-C198 -> 1 | F198: SG | H198: =C198 -> 45850
B199: =CONCATENATE(MONTH(D199)," ",YEAR(D199)) -> 7 2025 | C199: =D198 -> 45851 | D199: =D198+1 -> 45852 | E199: =D199-C199 -> 1 | F199: SG | H199: =C199 -> 45851
B200: =CONCATENATE(MONTH(D200)," ",YEAR(D200)) -> 7 2025 | C200: =D199 -> 45852 | D200: =D199+1 -> 45853 | E200: =D200-C200 -> 1 | F200: SG | H200: =C200 -> 45852
B201: =CONCATENATE(MONTH(D201)," ",YEAR(D201)) -> 7 2025 | C201: =D200 -> 45853 | D201: =D200+1 -> 45854 | E201: =D201-C201 -> 1 | F201: SG | H201: =C201 -> 45853
B202: =CONCATENATE(MONTH(D202)," ",YEAR(D202)) -> 7 2025 | C202: =D201 -> 45854 | D202: =D201+1 -> 45855 | E202: =D202-C202 -> 1 | F202: SG | H202: =C202 -> 45854
B203: =CONCATENATE(MONTH(D203)," ",YEAR(D203)) -> 7 2025 | C203: =D202 -> 45855 | D203: =D202+1 -> 45856 | E203: =D203-C203 -> 1 | F203: SG | H203: =C203 -> 45855
B204: =CONCATENATE(MONTH(D204)," ",YEAR(D204)) -> 7 2025 | C204: =D203 -> 45856 | D204: =D203+1 -> 45857 | E204: =D204-C204 -> 1 | F204: SG | H204: =C204 -> 45856
B205: =CONCATENATE(MONTH(D205)," ",YEAR(D205)) -> 7 2025 | C205: =D204 -> 45857 | D205: =D204+1 -> 45858 | E205: =D205-C205 -> 1 | F205: SG | H205: =C205 -> 45857
... B277: =CONCATENATE(MONTH(D277)," ",YEAR(D277)) -> 9 2025 | C277: =D276 -> 45929 | D277: =D276+1 -> 45930 | E277: =D277-C277 -> 1 | F277: SG | H277: =C277 -> 45929
A278: Date VL | B278: =CONCATENATE(MONTH(D278)," ",YEAR(D278)) -> 10 2025 | C278: =D277 -> 45930 | D278: =D277+1 -> 45931 | E278: =D278-C278 -> 1 | F278: SG | H278: =C278 -> 45930
B279: =CONCATENATE(MONTH(D279)," ",YEAR(D279)) -> 10 2025 | C279: =D278 -> 45931 | D279: =D278+1 -> 45932 | E279: =D279-C279 -> 1 | F279: SG | H279: =C279 -> 45931
B280: =CONCATENATE(MONTH(D280)," ",YEAR(D280)) -> 10 2025 | C280: =D279 -> 45932 | D280: =D279+1 -> 45933 | E280: =D280-C280 -> 1 | F280: SG | H280: =C280 -> 45932
B281: =CONCATENATE(MONTH(D281)," ",YEAR(D281)) -> 10 2025 | C281: =D280 -> 45933 | D281: =D280+1 -> 45934 | E281: =D281-C281 -> 1 | F281: SG | H281: =C281 -> 45933
