Workbook

Sheet To do
C3: AGA US | G3: AGA Fr
C4: update % avec taux Matt | G4: DS et MM | H4: retirer des AGA et remplacer par le virement prévu
H5: retirer Saafa
C11: Verif
C13: 2027
C14: par quarter ???

Sheet Forecast    ->

Sheet Consolidated Forecast in €
B3: Abivax SA & LLC | E3: 2026 Cash Forecast
R5: if USDEUR 1,16 at 31/12/2026
R6: 3.0911801e+08 | S6: €
B7: Abivax SA + LLC | E7: 46023 | F7: =EDATE(E7,1) -> 46054 | G7: =EDATE(F7,1) -> 46082 | H7: =EDATE(G7,1) -> 46113 | I7: =EDATE(H7,1) -> 46143 | J7: =EDATE(I7,1) -> 46174 | K7: =EDATE(J7,1) -> 46204 | L7: =EDATE(K7,1) -> 46235 | M7: =EDATE(L7,1) -> 46266 | ... P7: =EDATE(O7,1) -> 46357 | R7: =R6-P10 -> 12621891 | S7: de plus si EURUSD a 1,16 car on rmaène tout en eur
A9: Forecast | B9: Balance SA + LLC -EUR+USD- begining of month | C9: k€ | E9: =E15+E19 -> 5.3015759e+08 | F9: =F15+F19 -> 5.0619075e+08 | G9: =G15+G19 -> 4.8497668e+08 | H9: =H15+H19 -> 4.7210148e+08 | I9: =I15+I19 -> 4.3911238e+08 | J9: =J15+J19 -> 4.147261e+08 | K9: =K15+K19 -> 4.0240552e+08 | L9: =L15+L19 -> 3.8323451e+08 | ... P9: =P15+P19 -> 3.0122866e+08 | R9: en USD
A10: Forecast | B10: Balance SA +LLC -EUR+USD- end of month | C10: k€ | E10: =E16+E20 -> 4.9767694e+08 | F10: =F16+F20 -> 4.8497668e+08 | G10: =G16+G20 -> 4.7210148e+08 | H10: =H16+H20 -> 4.3911238e+08 | I10: =I16+I20 -> 4.147261e+08 | J10: =J16+J20 -> 4.0240552e+08 | K10: =K16+K20 -> 3.8323451e+08 | L10: =L16+L20 -> 3.5508067e+08 | ... P10: =P16+P20 -> 2.9649612e+08 | R10: =P10*1.18 -> 3.4986542e+08
A12: Forecast | B12: Montly variance | C12: k€ | E12: =E10-E9 -> -32480653 | F12: =F10-F9 -> -21214077 | G12: =G10-G9 -> -12875195 | H12: =H10-H9 -> -32989102 | I12: =I10-I9 -> -24386281 | J12: =J10-J9 -> -12320576 | K12: =K10-K9 -> -19171010 | L12: =L10-L9 -> -28153839 | ... P12: =P10-P9 -> -4732544.2
B14: Abivax SA, EUR + USD | E14: 45658 | F14: =EDATE(E14,1) -> 45689 | G14: =EDATE(F14,1) -> 45717 | H14: =EDATE(G14,1) -> 45748 | I14: =EDATE(H14,1) -> 45778 | J14: =EDATE(I14,1) -> 45809 | K14: =EDATE(J14,1) -> 45839 | L14: =EDATE(K14,1) -> 45870 | M14: =EDATE(L14,1) -> 45901 | ... P14: =EDATE(O14,1) -> 45992
A15: Forecast | B15: Balance SA-EUR - begining of month | C15: k€ | E15: ='SA Reforecast'!E101 -> 3.6169533e+08 | F15: ='SA Reforecast'!F101 -> 3.4508643e+08 | G15: ='SA Reforecast'!G101 -> 3.3090059e+08 | H15: ='SA Reforecast'!H101 -> 3.1947064e+08 | I15: ='SA Reforecast'!I101 -> 2.8809606e+08 | J15: ='SA Reforecast'!J101 -> 2.6526307e+08 | K15: ='SA Reforecast'!K101 -> 2.5449966e+08 | L15: ='SA Reforecast'!L101 -> 2.3748713e+08 | ... P15: ='SA Reforecast'!P101 -> 1.7051297e+08
A16: Forecast | B16: Balance SA-EUR - end of month | C16: k€ | E16: ='SA Reforecast'!E102 -> 3.4088442e+08 | F16: ='SA Reforecast'!F102 -> 3.3090059e+08 | G16: ='SA Reforecast'!G102 -> 3.1947064e+08 | H16: ='SA Reforecast'!H102 -> 2.8809606e+08 | I16: ='SA Reforecast'!I102 -> 2.6526307e+08 | J16: ='SA Reforecast'!J102 -> 2.5449966e+08 | K16: ='SA Reforecast'!K102 -> 2.3748713e+08 | L16: ='SA Reforecast'!L102 -> 2.1242931e+08 | ... P16: ='SA Reforecast'!P102 -> 1.6944222e+08
B18: Abivax LLC, USD expressed in EUR
A19: Forecast | B19: Balance SA-USD - begining of month | C19: k€ | E19: ='LLC Reforecast'!E45 -> 1.6846226e+08 | F19: ='LLC Reforecast'!F45 -> 1.6110432e+08 | G19: ='LLC Reforecast'!G45 -> 1.5407609e+08 | H19: ='LLC Reforecast'!H45 -> 1.5263084e+08 | I19: ='LLC Reforecast'!I45 -> 1.5101632e+08 | J19: ='LLC Reforecast'!J45 -> 1.4946303e+08 | K19: ='LLC Reforecast'!K45 -> 1.4790586e+08 | L19: ='LLC Reforecast'!L45 -> 1.4574739e+08 | ... P19: ='LLC Reforecast'!P45 -> 1.3071569e+08
A20: Forecast | B20: Balance SA-USD - end of month | C20: k€ | E20: ='LLC Reforecast'!E46 -> 1.5679253e+08 | F20: ='LLC Reforecast'!F46 -> 1.5407609e+08 | G20: ='LLC Reforecast'!G46 -> 1.5263084e+08 | H20: ='LLC Reforecast'!H46 -> 1.5101632e+08 | I20: ='LLC Reforecast'!I46 -> 1.4946303e+08 | J20: ='LLC Reforecast'!J46 -> 1.4790586e+08 | K20: ='LLC Reforecast'!K46 -> 1.4574739e+08 | L20: ='LLC Reforecast'!L46 -> 1.4265136e+08 | ... P20: ='LLC Reforecast'!P46 -> 1.2705389e+08
E23: Budget
B26: Abivax SA + LLC | E26: 45658 | F26: =EDATE(E26,1) -> 45689 | G26: =EDATE(F26,1) -> 45717 | H26: =EDATE(G26,1) -> 45748 | I26: =EDATE(H26,1) -> 45778 | J26: =EDATE(I26,1) -> 45809 | K26: =EDATE(J26,1) -> 45839 | L26: =EDATE(K26,1) -> 45870 | M26: =EDATE(L26,1) -> 45901 | ... P26: =EDATE(O26,1) -> 45992
A27: Budget | B27: Balance SA -EUR+USD- begining of month | C27: k€ | E27: ='Consolidated Budget'!E8 -> 5.3015759e+08 | F27: ='Consolidated Budget'!F8 -> 5.1424281e+08 | G27: ='Consolidated Budget'!G8 -> 4.9302873e+08 | H27: ='Consolidated Budget'!H8 -> 4.8015354e+08 | I27: ='Consolidated Budget'!I8 -> 4.4716444e+08 | J27: ='Consolidated Budget'!J8 -> 4.2277816e+08 | K27: ='Consolidated Budget'!K8 -> 4.1045758e+08 | L27: ='Consolidated Budget'!L8 -> 3.9128657e+08 | ... P27: ='Consolidated Budget'!P8 -> 3.0928072e+08
A28: Budget | B28: Balance SA -EUR+USD- end of month | C28: k€ | E28: ='Consolidated Budget'!E9 -> 5.1424281e+08 | F28: ='Consolidated Budget'!F9 -> 4.9302873e+08 | G28: ='Consolidated Budget'!G9 -> 4.8015354e+08 | H28: ='Consolidated Budget'!H9 -> 4.4716444e+08 | I28: ='Consolidated Budget'!I9 -> 4.2277816e+08 | J28: ='Consolidated Budget'!J9 -> 4.1045758e+08 | K28: ='Consolidated Budget'!K9 -> 3.9128657e+08 | L28: ='Consolidated Budget'!L9 -> 3.6313273e+08 | ... P28: ='Consolidated Budget'!P9 -> 3.0454818e+08
A30: Budget | B30: Montly variance | E30: ='Consolidated Budget'!E11 -> -15914782 | F30: ='Consolidated Budget'!F11 -> -21214077 | G30: ='Consolidated Budget'!G11 -> -12875195 | H30: ='Consolidated Budget'!H11 -> -32989102 | I30: ='Consolidated Budget'!I11 -> -24386281 | J30: ='Consolidated Budget'!J11 -> -12320576 | K30: ='Consolidated Budget'!K11 -> -19171010 | L30: ='Consolidated Budget'!L11 -> -28153839 | ... P30: ='Consolidated Budget'!P11 -> -4732544.2
B33: Abivax SA, EUR + USD | E33: 45658 | F33: =EDATE(E33,1) -> 45689 | G33: =EDATE(F33,1) -> 45717 | H33: =EDATE(G33,1) -> 45748 | I33: =EDATE(H33,1) -> 45778 | J33: =EDATE(I33,1) -> 45809 | K33: =EDATE(J33,1) -> 45839 | L33: =EDATE(K33,1) -> 45870 | M33: =EDATE(L33,1) -> 45901 | ... P33: =EDATE(O33,1) -> 45992
A34: Budget | B34: Balance SA-EUR - begining of month | C34: k€ | E34: ='Consolidated Budget'!E15 -> 3.6169533e+08 | F34: ='Consolidated Budget'!F15 -> 3.4497937e+08 | G34: ='Consolidated Budget'!G15 -> 3.3079352e+08 | H34: ='Consolidated Budget'!H15 -> 3.1936358e+08 | I34: ='Consolidated Budget'!I15 -> 2.87989e+08 | J34: ='Consolidated Budget'!J15 -> 2.65156e+08 | K34: ='Consolidated Budget'!K15 -> 2.543926e+08 | L34: ='Consolidated Budget'!L15 -> 2.3738007e+08 | ... P34: ='Consolidated Budget'!P15 -> 1.7040591e+08
A35: Budget | B35: Balance SA-EUR - end of month | C35: k€ | E35: ='Consolidated Budget'!E16 -> 3.4497937e+08 | F35: ='Consolidated Budget'!F16 -> 3.3079352e+08 | G35: ='Consolidated Budget'!G16 -> 3.1936358e+08 | H35: ='Consolidated Budget'!H16 -> 2.87989e+08 | I35: ='Consolidated Budget'!I16 -> 2.65156e+08 | J35: ='Consolidated Budget'!J16 -> 2.543926e+08 | K35: ='Consolidated Budget'!K16 -> 2.3738007e+08 | L35: ='Consolidated Budget'!L16 -> 2.1232225e+08 | ... P35: ='Consolidated Budget'!P16 -> 1.6933516e+08
B37: Abivax LLC, USD expressed in EUR
A38: Budget | B38: Balance SA-USD - begining of month | C38: k€ | E38: ='Consolidated Budget'!E19 -> 1.6846226e+08 | F38: ='Consolidated Budget'!F19 -> 1.6926344e+08 | G38: ='Consolidated Budget'!G19 -> 1.6223521e+08 | H38: ='Consolidated Budget'!H19 -> 1.6078996e+08 | I38: ='Consolidated Budget'!I19 -> 1.5917544e+08 | J38: ='Consolidated Budget'!J19 -> 1.5762215e+08 | K38: ='Consolidated Budget'!K19 -> 1.5606498e+08 | L38: ='Consolidated Budget'!L19 -> 1.539065e+08 | ... P38: ='Consolidated Budget'!P19 -> 1.3887481e+08
A39: Budget | B39: Balance SA-USD - end of month | C39: k€ | E39: ='Consolidated Budget'!E20 -> 1.6926344e+08 | F39: ='Consolidated Budget'!F20 -> 1.6223521e+08 | G39: ='Consolidated Budget'!G20 -> 1.6078996e+08 | H39: ='Consolidated Budget'!H20 -> 1.5917544e+08 | I39: ='Consolidated Budget'!I20 -> 1.5762215e+08 | J39: ='Consolidated Budget'!J20 -> 1.5606498e+08 | K39: ='Consolidated Budget'!K20 -> 1.539065e+08 | L39: ='Consolidated Budget'!L20 -> 1.5081048e+08 | ... P39: ='Consolidated Budget'!P20 -> 1.3521301e+08
E43: Comparison with Budget (12 month, same methodology so diferent than Board)
B46: Abivax SA + LLC | E46: 45658 | F46: =EDATE(E46,1) -> 45689 | G46: =EDATE(F46,1) -> 45717 | H46: =EDATE(G46,1) -> 45748 | I46: =EDATE(H46,1) -> 45778 | J46: =EDATE(I46,1) -> 45809 | K46: =EDATE(J46,1) -> 45839 | L46: =EDATE(K46,1) -> 45870 | M46: =EDATE(L46,1) -> 45901 | ... P46: =EDATE(O46,1) -> 45992
A47: Comparison | B47: Balance SA -EUR+USD- begining of month | C47: k€ | E47: =E9-E27 -> 0 | F47: =F9-F27 -> -8052057.1 | G47: =G9-G27 -> -8052057.1 | H47: =H9-H27 -> -8052057.1 | I47: =I9-I27 -> -8052057.1 | J47: =J9-J27 -> -8052057.1 | K47: =K9-K27 -> -8052057.1 | L47: =L9-L27 -> -8052057.1 | ... P47: =P9-P27 -> -8052057.1
A48: Comparison | B48: Balance SA -EUR+USD- end of month | C48: k€ | E48: =E10-E28 -> -16565870 | F48: =F10-F28 -> -8052057.1 | G48: =G10-G28 -> -8052057.1 | H48: =H10-H28 -> -8052057.1 | I48: =I10-I28 -> -8052057.1 | J48: =J10-J28 -> -8052057.1 | K48: =K10-K28 -> -8052057.1 | L48: =L10-L28 -> -8052057.1 | ... P48: =P10-P28 -> -8052057.1
A50: Comparison | B50: Montly variance | E50: =E12-E30 -> -16565870 | F50: =F12-F30 -> 1.1920929e-07 | G50: =G12-G30 -> 0 | H50: =H12-H30 -> 0 | I50: =I12-I30 -> 0 | J50: =J12-J30 -> 0 | K50: =K12-K30 -> 0 | L50: =L12-L30 -> -5.9604645e-08 | ... P50: =P12-P30 -> 0
B53: Abivax SA, EUR + USD | E53: 45658 | F53: =EDATE(E53,1) -> 45689 | G53: =EDATE(F53,1) -> 45717 | H53: =EDATE(G53,1) -> 45748 | I53: =EDATE(H53,1) -> 45778 | J53: =EDATE(I53,1) -> 45809 | K53: =EDATE(J53,1) -> 45839 | L53: =EDATE(K53,1) -> 45870 | M53: =EDATE(L53,1) -> 45901 | ... P53: =EDATE(O53,1) -> 45992
A54: Comparison | B54: Balance SA-EUR - begining of month | C54: k€ | E54: =E15-'Consolidated Budget'!E15 -> 0 | F54: =F15-'Consolidated Budget'!F15 -> 107061.47 | G54: =G15-'Consolidated Budget'!G15 -> 107061.47 | H54: =H15-'Consolidated Budget'!H15 -> 107061.47 | I54: =I15-'Consolidated Budget'!I15 -> 107061.47 | J54: =J15-'Consolidated Budget'!J15 -> 107061.47 | K54: =K15-'Consolidated Budget'!K15 -> 107061.47 | L54: =L15-'Consolidated Budget'!L15 -> 107061.47 | ... P54: =P15-'Consolidated Budget'!P15 -> 107061.47
A55: Comparison | B55: Balance SA-EUR - end of month | C55: k€ | E55: =E16-'Consolidated Budget'!E16 -> -4094957.4 | F55: =F16-'Consolidated Budget'!F16 -> 107061.47 | G55: =G16-'Consolidated Budget'!G16 -> 107061.47 | H55: =H16-'Consolidated Budget'!H16 -> 107061.47 | I55: =I16-'Consolidated Budget'!I16 -> 107061.47 | J55: =J16-'Consolidated Budget'!J16 -> 107061.47 | K55: =K16-'Consolidated Budget'!K16 -> 107061.47 | L55: =L16-'Consolidated Budget'!L16 -> 107061.47 | ... P55: =P16-'Consolidated Budget'!P16 -> 107061.47
B57: Abivax LLC, USD expressed in EUR
A58: Comparison | B58: Balance SA-USD - begining of month | C58: k€ | E58: =E19-'Consolidated Budget'!E19 -> 0 | F58: =F19-'Consolidated Budget'!F19 -> -8159118.5 | G58: =G19-'Consolidated Budget'!G19 -> -8159118.5 | H58: =H19-'Consolidated Budget'!H19 -> -8159118.5 | I58: =I19-'Consolidated Budget'!I19 -> -8159118.5 | J58: =J19-'Consolidated Budget'!J19 -> -8159118.5 | K58: =K19-'Consolidated Budget'!K19 -> -8159118.5 | L58: =L19-'Consolidated Budget'!L19 -> -8159118.5 | ... P58: =P19-'Consolidated Budget'!P19 -> -8159118.5
A59: Comparison | B59: Balance SA-USD - end of month | C59: k€ | E59: =E20-'Consolidated Budget'!E20 -> -12470913 | F59: =F20-'Consolidated Budget'!F20 -> -8159118.5 | G59: =G20-'Consolidated Budget'!G20 -> -8159118.5 | H59: =H20-'Consolidated Budget'!H20 -> -8159118.5 | I59: =I20-'Consolidated Budget'!I20 -> -8159118.5 | J59: =J20-'Consolidated Budget'!J20 -> -8159118.5 | K59: =K20-'Consolidated Budget'!K20 -> -8159118.5 | L59: =L20-'Consolidated Budget'!L20 -> -8159118.5 | ... P59: =P20-'Consolidated Budget'!P20 -> -8159118.5
A60: check

Sheet SA Reforecast
B3: Abivax SA | E3: Cash Forecast - V budget | AA3: Comparison Forecast- Budget
B6: Abivax SA EUR | E6: Forecast-Budget | AA6: Forecast-Budget
E7: 46023 | F7: =EDATE(E7,1) -> 46054 | G7: =EDATE(F7,1) -> 46082 | H7: =EDATE(G7,1) -> 46113 | I7: =EDATE(H7,1) -> 46143 | J7: =EDATE(I7,1) -> 46174 | K7: =EDATE(J7,1) -> 46204 | L7: =EDATE(K7,1) -> 46235 | M7: =EDATE(L7,1) -> 46266 | ... P7: =EDATE(O7,1) -> 46357 | R7: 2026 | AA7: 46023 | AB7: =EDATE(AA7,1) -> 46054 | AC7: =EDATE(AB7,1) -> 46082 | AD7: =EDATE(AC7,1) -> 46113 | AE7: =EDATE(AD7,1) -> 46143 | AF7: =EDATE(AE7,1) -> 46174 | AG7: =EDATE(AF7,1) -> 46204 | AH7: =EDATE(AG7,1) -> 46235 | AI7: =EDATE(AH7,1) -> 46266 | ... AL7: =EDATE(AK7,1) -> 46357 | AN7: 2026
B9: Amount are VAT excluded
B10: IQVIA 105 milestone | C10: k€ | E10: ='SA Actual'!E10 -> 0 | F10: ='SA budget'!F10 -> 0 | G10: ='SA budget'!G10 -> 0 | H10: ='SA budget'!H10 -> 0 | I10: ='SA budget'!I10 -> 0 | J10: ='SA budget'!J10 -> 0 | K10: ='SA budget'!K10 -> 2363322 | L10: ='SA budget'!L10 -> 294998.69 | M10: ='SA budget'!M10 -> 0 | ... P10: ='SA budget'!P10 -> 0 | R10: =SUM(E10:P10) -> 2658320.7 | T10: 54 en cash versus 51 au budget : +3 m€ | AA10: =E10-'SA budget'!E10 -> 0 | AB10: =F10-'SA budget'!F10 -> 0 | AC10: =G10-'SA budget'!G10 -> 0 | AD10: =H10-'SA budget'!H10 -> 0 | AE10: =I10-'SA budget'!I10 -> 0 | AF10: =J10-'SA budget'!J10 -> 0 | AG10: =K10-'SA budget'!K10 -> 0 | AH10: =L10-'SA budget'!L10 -> 0 | ... AL10: =P10-'SA budget'!P10 -> 0 | AN10: =SUM(AA10:AL10) -> 0
B11: IQVIA 105 PTC & IF & Q2 | C11: k€ | E11: ='SA Actual'!E11 -> 599166.48 | F11: ='SA budget'!F11 -> 570621.62 | G11: ='SA budget'!G11 -> 612797.98 | H11: ='SA budget'!H11 -> 237810 | I11: ='SA budget'!I11 -> 0 | J11: ='SA budget'!J11 -> 0 | K11: ='SA budget'!K11 -> 0 | L11: ='SA budget'!L11 -> 0 | M11: ='SA budget'!M11 -> 0 | ... P11: ='SA budget'!P11 -> 0 | R11: =SUM(E11:P11) -> 2020396.1 | T11: milestone DBL 105 à ajouter au Reforecast : 2,4 m€ | AA11: =E11-'SA budget'!E11 -> 0 | AB11: =F11-'SA budget'!F11 -> 0 | AC11: =G11-'SA budget'!G11 -> 0 | AD11: =H11-'SA budget'!H11 -> 0 | AE11: =I11-'SA budget'!I11 -> 0 | AF11: =J11-'SA budget'!J11 -> 0 | AG11: =K11-'SA budget'!K11 -> 0 | AH11: =L11-'SA budget'!L11 -> 0 | ... AL11: =P11-'SA budget'!P11 -> 0 | AN11: =SUM(AA11:AL11) -> 0
B12: IQVIA 106 milestone | C12: k€ | E12: ='SA Actual'!E12 -> 0 | F12: ='SA budget'!F12 -> 0 | G12: ='SA budget'!G12 -> 0 | H12: ='SA budget'!H12 -> 0 | I12: ='SA budget'!I12 -> 0 | J12: ='SA budget'!J12 -> 0 | K12: ='SA budget'!K12 -> 756326 | L12: ='SA budget'!L12 -> 109002.94 | M12: ='SA budget'!M12 -> 0 | ... P12: ='SA budget'!P12 -> 0 | R12: =SUM(E12:P12) -> 865328.94 | T12: paiement janvier de facture de décembre 2025 + 10 m€ mais -9 m€ pour 107 (65% monitoring et PTC) | AA12: =E12-'SA budget'!E12 -> 0 | AB12: =F12-'SA budget'!F12 -> 0 | AC12: =G12-'SA budget'!G12 -> 0 | AD12: =H12-'SA budget'!H12 -> 0 | AE12: =I12-'SA budget'!I12 -> 0 | AF12: =J12-'SA budget'!J12 -> 0 | AG12: =K12-'SA budget'!K12 -> 0 | AH12: =L12-'SA budget'!L12 -> 0 | ... AL12: =P12-'SA budget'!P12 -> 0 | AN12: =SUM(AA12:AL12) -> 0
B13: IQVIA 106 PTC & IF & Q2 | C13: k€ | E13: ='SA Actual'!E13 -> 1246050.2 | F13: ='SA budget'!F13 -> 467517.53 | G13: ='SA budget'!G13 -> 619029.58 | H13: ='SA budget'!H13 -> 237306 | I13: ='SA budget'!I13 -> 224267 | J13: ='SA budget'!J13 -> 0 | K13: ='SA budget'!K13 -> 0 | L13: ='SA budget'!L13 -> 0 | M13: ='SA budget'!M13 -> 0 | ... P13: ='SA budget'!P13 -> 0 | R13: =SUM(E13:P13) -> 2794170.4 | AA13: =E13-'SA budget'!E13 -> 0 | AB13: =F13-'SA budget'!F13 -> 0 | AC13: =G13-'SA budget'!G13 -> 0 | AD13: =H13-'SA budget'!H13 -> 0 | AE13: =I13-'SA budget'!I13 -> 0 | AF13: =J13-'SA budget'!J13 -> 0 | AG13: =K13-'SA budget'!K13 -> 0 | AH13: =L13-'SA budget'!L13 -> 0 | ... AL13: =P13-'SA budget'!P13 -> 0 | AN13: =SUM(AA13:AL13) -> 0
B14: IQVIA 107 milestone | C14: k€ | E14: ='SA Actual'!E14 -> 4790962 | F14: ='SA budget'!F14 -> 0 | G14: ='SA budget'!G14 -> 0 | H14: ='SA budget'!H14 -> 0 | I14: ='SA budget'!I14 -> 7186443 | J14: ='SA budget'!J14 -> 0 | K14: ='SA budget'!K14 -> 0 | L14: ='SA budget'!L14 -> 9581924 | M14: ='SA budget'!M14 -> 0 | ... P14: ='SA budget'!P14 -> 0 | R14: =SUM(E14:P14) -> 28745772 | AA14: =E14-'SA budget'!E14 -> 0 | AB14: =F14-'SA budget'!F14 -> 0 | AC14: =G14-'SA budget'!G14 -> 0 | AD14: =H14-'SA budget'!H14 -> 0 | AE14: =I14-'SA budget'!I14 -> 0 | AF14: =J14-'SA budget'!J14 -> 0 | AG14: =K14-'SA budget'!K14 -> 0 | AH14: =L14-'SA budget'!L14 -> 0 | ... AL14: =P14-'SA budget'!P14 -> 0 | AN14: =SUM(AA14:AL14) -> 0
B15: IQVIA 107 PTC & IF & Q2 | C15: k€ | E15: ='SA Actual'!E15 -> 1814129.3 | F15: ='SA budget'!F15 -> 1542238.5 | G15: ='SA budget'!G15 -> 1125311.7 | H15: ='SA budget'!H15 -> 978890 | I15: ='SA budget'!I15 -> 650000 | J15: ='SA budget'!J15 -> 650000 | K15: ='SA budget'!K15 -> 0 | L15: ='SA budget'!L15 -> 0 | M15: ='SA budget'!M15 -> 0 | ... P15: ='SA budget'!P15 -> 0 | R15: =SUM(E15:P15) -> 6760569.5 | AA15: =E15-'SA budget'!E15 -> 0 | AB15: =F15-'SA budget'!F15 -> 0 | AC15: =G15-'SA budget'!G15 -> 0 | AD15: =H15-'SA budget'!H15 -> 0 | AE15: =I15-'SA budget'!I15 -> 0 | AF15: =J15-'SA budget'!J15 -> 0 | AG15: =K15-'SA budget'!K15 -> 0 | AH15: =L15-'SA budget'!L15 -> 0 | ... AL15: =P15-'SA budget'!P15 -> 0 | AN15: =SUM(AA15:AL15) -> 0
B16: IQVIA Ph3 - CO | C16: k€ | E16: ='SA Actual'!E16 -> 0 | F16: ='SA budget'!F16 -> 0 | G16: ='SA budget'!G16 -> 0 | H16: ='SA budget'!H16 -> 5000000 | I16: ='SA budget'!I16 -> 2000000 | J16: ='SA budget'!J16 -> 2000000 | K16: ='SA budget'!K16 -> 1000000 | L16: ='SA budget'!L16 -> 0 | M16: ='SA budget'!M16 -> 0 | ... P16: ='SA budget'!P16 -> 0 | R16: =SUM(E16:P16) -> 10000000 | T16: Budget : 10,5 me CO4 Ph3 sur 2026 | AA16: =E16-'SA budget'!E16 -> 0 | AB16: =F16-'SA budget'!F16 -> 0 | AC16: =G16-'SA budget'!G16 -> 0 | AD16: =H16-'SA budget'!H16 -> 0 | AE16: =I16-'SA budget'!I16 -> 0 | AF16: =J16-'SA budget'!J16 -> 0 | AG16: =K16-'SA budget'!K16 -> 0 | AH16: =L16-'SA budget'!L16 -> 0 | ... AL16: =P16-'SA budget'!P16 -> 0 | AN16: =SUM(AA16:AL16) -> 0
B17: IQVIA CD milestone | C17: k€ | E17: ='SA Actual'!E17 -> 1308382 | F17: ='SA budget'!F17 -> 0 | G17: ='SA budget'!G17 -> 1308382 | H17: ='SA budget'!H17 -> 1308381.9 | I17: ='SA budget'!I17 -> 1831734.7 | J17: ='SA budget'!J17 -> 0 | K17: ='SA budget'!K17 -> 2355087.5 | L17: ='SA budget'!L17 -> 1570058.3 | M17: ='SA budget'!M17 -> 1046705.6 | ... P17: ='SA budget'!P17 -> 0 | R17: =SUM(E17:P17) -> 11775438 | T17: pourquoi 14 m€ versus 10 m€ au budget et 14 m€ sur couts projets | AA17: =E17-'SA budget'!E17 -> 0 | AB17: =F17-'SA budget'!F17 -> 0 | AC17: =G17-'SA budget'!G17 -> 0 | AD17: =H17-'SA budget'!H17 -> 0 | AE17: =I17-'SA budget'!I17 -> 0 | AF17: =J17-'SA budget'!J17 -> 0 | AG17: =K17-'SA budget'!K17 -> 0 | AH17: =L17-'SA budget'!L17 -> 0 | ... AL17: =P17-'SA budget'!P17 -> 0 | AN17: =SUM(AA17:AL17) -> 0
B18: IQVIA CD PTC & IF & Q2 | C18: k€ | E18: ='SA Actual'!E18 -> 214041.3 | F18: ='SA budget'!F18 -> 301393.22 | G18: ='SA budget'!G18 -> 0 | H18: ='SA budget'!H18 -> 220000 | I18: ='SA budget'!I18 -> 220000 | J18: ='SA budget'!J18 -> 220000 | K18: ='SA budget'!K18 -> 220000 | L18: ='SA budget'!L18 -> 220000 | M18: ='SA budget'!M18 -> 220000 | ... P18: ='SA budget'!P18 -> 220000 | R18: =SUM(E18:P18) -> 2495434.5 | T18: réponse : -3m€ de FNP en janvier; +1 m€ de paiement jnvier et -1m€ factures dec 2026 | AA18: =E18-'SA budget'!E18 -> 0 | AB18: =F18-'SA budget'!F18 -> 0 | AC18: =G18-'SA budget'!G18 -> 0 | AD18: =H18-'SA budget'!H18 -> 0 | AE18: =I18-'SA budget'!I18 -> 0 | AF18: =J18-'SA budget'!J18 -> 0 | AG18: =K18-'SA budget'!K18 -> 0 | AH18: =L18-'SA budget'!L18 -> 0 | ... AL18: =P18-'SA budget'!P18 -> 0 | AN18: =SUM(AA18:AL18) -> 0
B19: IQVIA CD -CO | C19: k€ | E19: ='SA Actual'!E19 -> 0 | F19: ='SA budget'!F19 -> 0 | G19: ='SA budget'!G19 -> 0 | H19: ='SA budget'!H19 -> 3000000 | I19: ='SA budget'!I19 -> 375000 | J19: ='SA budget'!J19 -> 375000 | K19: ='SA budget'!K19 -> 375000 | L19: ='SA budget'!L19 -> 375000 | M19: ='SA budget'!M19 -> 375000 | ... P19: ='SA budget'!P19 -> 375000 | R19: =SUM(E19:P19) -> 6000000 | T19: CO2 ! 6 m€ ppour 2026 | AA19: =E19-'SA budget'!E19 -> 0 | AB19: =F19-'SA budget'!F19 -> 0 | AC19: =G19-'SA budget'!G19 -> 0 | AD19: =H19-'SA budget'!H19 -> 0 | AE19: =I19-'SA budget'!I19 -> 0 | AF19: =J19-'SA budget'!J19 -> 0 | AG19: =K19-'SA budget'!K19 -> 0 | AH19: =L19-'SA budget'!L19 -> 0 | ... AL19: =P19-'SA budget'!P19 -> 0 | AN19: =SUM(AA19:AL19) -> 0
B20: Total IQVIA | C20: k€ | E20: =SUM(E10:E19) -> 9972731.3 | F20: =SUM(F10:F19) -> 2881770.9 | G20: =SUM(G10:G19) -> 3665521.2 | H20: =SUM(H10:H19) -> 10982388 | I20: =SUM(I10:I19) -> 12487445 | J20: =SUM(J10:J19) -> 3245000 | K20: =SUM(K10:K19) -> 7069735.5 | L20: =SUM(L10:L19) -> 12150984 | ... P20: =SUM(P10:P19) -> 595000 | R20: =SUM(E20:P20) -> 74115430 | AA20: =SUM(AA10:AA19) -> 0 | AB20: =SUM(AB10:AB19) -> 0 | AC20: =SUM(AC10:AC19) -> 0 | AD20: =SUM(AD10:AD19) -> 0 | AE20: =SUM(AE10:AE19) -> 0 | AF20: =SUM(AF10:AF19) -> 0 | AG20: =SUM(AG10:AG19) -> 0 | AH20: =SUM(AH10:AH19) -> 0 | ... AL20: =SUM(AL10:AL19) -> 0 | AN20: =SUM(AA20:AL20) -> 0
B22: Other Suppliers € (HT) | C22: k€ | E22: ='SA Actual'!E22 -> 5117218.8 | F22: ='SA budget'!F22 -> 4718356.9 | G22: ='SA budget'!G22 -> 4718356.9 | H22: ='SA budget'!H22 -> 4718356.9 | I22: ='SA budget'!I22 -> 4596761.9 | J22: ='SA budget'!J22 -> 4596761.9 | K22: ='SA budget'!K22 -> 4596761.9 | L22: ='SA budget'!L22 -> 4858617.1 | M22: ='SA budget'!M22 -> 4858617.1 | ... P22: ='SA budget'!P22 -> 5128841.5 | R22: =SUM(E22:P22) -> 57896109 | AA22: =E22-'SA budget'!E22 -> 398861.87 | AB22: =F22-'SA budget'!F22 -> 0 | AC22: =G22-'SA budget'!G22 -> 0 | AD22: =H22-'SA budget'!H22 -> 0 | AE22: =I22-'SA budget'!I22 -> 0 | AF22: =J22-'SA budget'!J22 -> 0 | AG22: =K22-'SA budget'!K22 -> 0 | AH22: =L22-'SA budget'!L22 -> 0 | ... AL22: =P22-'SA budget'!P22 -> 0 | AN22: =SUM(AA22:AL22) -> 398861.87
B23: Contractor (HT) | C23: k€ | E23: ='SA Actual'!E23 -> 405647.09 | F23: ='SA budget'!F23 -> 416446.67 | G23: ='SA budget'!G23 -> 416446.67 | H23: ='SA budget'!H23 -> 416446.67 | I23: ='SA budget'!I23 -> 431846.67 | J23: ='SA budget'!J23 -> 431846.67 | K23: ='SA budget'!K23 -> 431846.67 | L23: ='SA budget'!L23 -> 431846.67 | M23: ='SA budget'!M23 -> 431846.67 | ... P23: ='SA budget'!P23 -> 420866.67 | R23: =SUM(E23:P23) -> 5087800.4 | AA23: =E23-'SA budget'!E23 -> -10799.575 | AB23: =F23-'SA budget'!F23 -> 0 | AC23: =G23-'SA budget'!G23 -> 0 | AD23: =H23-'SA budget'!H23 -> 0 | AE23: =I23-'SA budget'!I23 -> 0 | AF23: =J23-'SA budget'!J23 -> 0 | AG23: =K23-'SA budget'!K23 -> 0 | AH23: =L23-'SA budget'!L23 -> 0 | ... AL23: =P23-'SA budget'!P23 -> 0 | AN23: =SUM(AA23:AL23) -> -10799.575
B24: Bank fees | C24: k€ | E24: ='SA Actual'!E24 -> 17774.39 | F24: ='SA budget'!F24 -> 0 | G24: ='SA budget'!G24 -> 0 | H24: ='SA budget'!H24 -> 0 | I24: ='SA budget'!I24 -> 0 | J24: ='SA budget'!J24 -> 0 | K24: ='SA budget'!K24 -> 0 | L24: ='SA budget'!L24 -> 0 | M24: ='SA budget'!M24 -> 0 | ... P24: ='SA budget'!P24 -> 0 | AA24: =E24-'SA budget'!E24 -> 17774.39 | AB24: =F24-'SA budget'!F24 -> 0 | AC24: =G24-'SA budget'!G24 -> 0 | AD24: =H24-'SA budget'!H24 -> 0 | AE24: =I24-'SA budget'!I24 -> 0 | AF24: =J24-'SA budget'!J24 -> 0 | AG24: =K24-'SA budget'!K24 -> 0 | AH24: =L24-'SA budget'!L24 -> 0 | ... AL24: =P24-'SA budget'!P24 -> 0 | AN24: =SUM(AA24:AL24) -> 17774.39
B25: Suppliers + Contractos | C25: k€ | E25: =SUM(E22:E24) -> 5540640.2 | F25: =SUM(F22:F24) -> 5134803.5 | G25: =SUM(G22:G24) -> 5134803.5 | H25: =SUM(H22:H24) -> 5134803.5 | I25: =SUM(I22:I24) -> 5028608.5 | J25: =SUM(J22:J24) -> 5028608.5 | K25: =SUM(K22:K24) -> 5028608.5 | L25: =SUM(L22:L24) -> 5290463.8 | ... P25: =SUM(P22:P24) -> 5549708.2 | R25: =SUM(E25:P25) -> 63001684 | AA25: =SUM(AA22:AA24) -> 405836.68 | AB25: =SUM(AB22:AB24) -> 0 | AC25: =SUM(AC22:AC24) -> 0 | AD25: =SUM(AD22:AD24) -> 0 | AE25: =SUM(AE22:AE24) -> 0 | AF25: =SUM(AF22:AF24) -> 0 | AG25: =SUM(AG22:AG24) -> 0 | AH25: =SUM(AH22:AH24) -> 0 | ... AL25: =SUM(AL22:AL24) -> 0 | AN25: =SUM(AA25:AL25) -> 405836.68
B27: Capex | C27: k€ | E27: ='SA Actual'!E27 -> 0 | F27: ='SA budget'!F27 -> 0 | G27: ='SA budget'!G27 -> 0 | H27: ='SA budget'!H27 -> 200000 | I27: ='SA budget'!I27 -> 200000 | J27: ='SA budget'!J27 -> 200000 | K27: ='SA budget'!K27 -> 200000 | L27: ='SA budget'!L27 -> 200000 | M27: ='SA budget'!M27 -> 200000 | ... P27: ='SA budget'!P27 -> 200000 | R27: =SUM(E27:P27) -> 1800000 | AA27: =E27-'SA budget'!E27 -> 0 | AB27: =F27-'SA budget'!F27 -> 0 | AC27: =G27-'SA budget'!G27 -> 0 | AD27: =H27-'SA budget'!H27 -> 0 | AE27: =I27-'SA budget'!I27 -> 0 | AF27: =J27-'SA budget'!J27 -> 0 | AG27: =K27-'SA budget'!K27 -> 0 | AH27: =L27-'SA budget'!L27 -> 0 | ... AL27: =P27-'SA budget'!P27 -> 0 | AN27: =SUM(AA27:AL27) -> 0
B29: Salaire net aprés PAS | C29: k€ | E29: ='SA Actual'!E29 -> 309076.43 | F29: ='SA budget'!F29 -> 296854.81 | G29: ='SA budget'!G29 -> 296854.81 | H29: ='SA budget'!H29 -> 296854.81 | I29: ='SA budget'!I29 -> 296854.81 | J29: ='SA budget'!J29 -> 296854.81 | K29: ='SA budget'!K29 -> 296854.81 | L29: ='SA budget'!L29 -> 296854.81 | M29: ='SA budget'!M29 -> 296854.81 | ... P29: ='SA budget'!P29 -> 296854.81 | R29: =SUM(E29:P29) -> 3574479.3 | AA29: =E29-'SA budget'!E29 -> 12221.623 | AB29: =F29-'SA budget'!F29 -> 0 | AC29: =G29-'SA budget'!G29 -> 0 | AD29: =H29-'SA budget'!H29 -> 0 | AE29: =I29-'SA budget'!I29 -> 0 | AF29: =J29-'SA budget'!J29 -> 0 | AG29: =K29-'SA budget'!K29 -> 0 | AH29: =L29-'SA budget'!L29 -> 0 | ... AL29: =P29-'SA budget'!P29 -> 0 | AN29: =SUM(AA29:AL29) -> 12221.623
B30: Bonus net sans PAS | C30: k€ | E30: ='SA Actual'!E30 -> 0 | F30: ='SA budget'!F30 -> 662352.23 | G30: ='SA budget'!G30 -> 0 | H30: ='SA budget'!H30 -> 0 | I30: ='SA budget'!I30 -> 0 | J30: ='SA budget'!J30 -> 277342.06 | K30: ='SA budget'!K30 -> 0 | L30: ='SA budget'!L30 -> 0 | M30: ='SA budget'!M30 -> 0 | ... P30: ='SA budget'!P30 -> 0 | R30: =SUM(E30:P30) -> 939694.29 | AA30: =E30-'SA budget'!E30 -> 0 | AB30: =F30-'SA budget'!F30 -> 0 | AC30: =G30-'SA budget'!G30 -> 0 | AD30: =H30-'SA budget'!H30 -> 0 | AE30: =I30-'SA budget'!I30 -> 0 | AF30: =J30-'SA budget'!J30 -> 0 | AG30: =K30-'SA budget'!K30 -> 0 | AH30: =L30-'SA budget'!L30 -> 0 | ... AL30: =P30-'SA budget'!P30 -> 0 | AN30: =SUM(AA30:AL30) -> 0
B31: Urssaf | C31: k€ | E31: ='SA Actual'!E31 -> 175083 | F31: ='SA budget'!F31 -> 213251.39 | G31: ='SA budget'!G31 -> 689064.92 | H31: ='SA budget'!H31 -> 213251.39 | I31: ='SA budget'!I31 -> 213251.39 | J31: ='SA budget'!J31 -> 213251.39 | K31: ='SA budget'!K31 -> 412485.43 | L31: ='SA budget'!L31 -> 213251.39 | M31: ='SA budget'!M31 -> 213251.39 | ... P31: ='SA budget'!P31 -> 213251.39 | R31: =SUM(E31:P31) -> 3195895.9 | AA31: =E31-'SA budget'!E31 -> -38168.39 | AB31: =F31-'SA budget'!F31 -> 0 | AC31: =G31-'SA budget'!G31 -> 0 | AD31: =H31-'SA budget'!H31 -> 0 | AE31: =I31-'SA budget'!I31 -> 0 | AF31: =J31-'SA budget'!J31 -> 0 | AG31: =K31-'SA budget'!K31 -> 0 | AH31: =L31-'SA budget'!L31 -> 0 | ... AL31: =P31-'SA budget'!P31 -> 0 | AN31: =SUM(AA31:AL31) -> -38168.39
B32: Retraite | C32: k€ | E32: ='SA Actual'!E32 -> 70015.02 | F32: ='SA budget'!F32 -> 93053.399 | G32: ='SA budget'!G32 -> 300677.21 | H32: ='SA budget'!H32 -> 93053.399 | I32: ='SA budget'!I32 -> 93053.399 | J32: ='SA budget'!J32 -> 93053.399 | K32: ='SA budget'!K32 -> 179990.25 | L32: ='SA budget'!L32 -> 93053.399 | M32: ='SA budget'!M32 -> 93053.399 | ... P32: ='SA budget'!P32 -> 93053.399 | R32: =SUM(E32:P32) -> 1388163.1 | AA32: =E32-'SA budget'!E32 -> -23038.379 | AB32: =F32-'SA budget'!F32 -> 0 | AC32: =G32-'SA budget'!G32 -> 0 | AD32: =H32-'SA budget'!H32 -> 0 | AE32: =I32-'SA budget'!I32 -> 0 | AF32: =J32-'SA budget'!J32 -> 0 | AG32: =K32-'SA budget'!K32 -> 0 | AH32: =L32-'SA budget'!L32 -> 0 | ... AL32: =P32-'SA budget'!P32 -> 0 | AN32: =SUM(AA32:AL32) -> -23038.379
B33: Prévoyance | C33: k€ | E33: ='SA Actual'!E33 -> 0 | F33: ='SA budget'!F33 -> 0 | G33: ='SA budget'!G33 -> 0 | H33: ='SA budget'!H33 -> 44138.446 | I33: ='SA budget'!I33 -> 0 | J33: ='SA budget'!J33 -> 0 | K33: ='SA budget'!K33 -> 25312.453 | L33: ='SA budget'!L33 -> 0 | M33: ='SA budget'!M33 -> 0 | ... P33: ='SA budget'!P33 -> 0 | R33: =SUM(E33:P33) -> 94763.352 | AA33: =E33-'SA budget'!E33 -> -25312.453 | AB33: =F33-'SA budget'!F33 -> 0 | AC33: =G33-'SA budget'!G33 -> 0 | AD33: =H33-'SA budget'!H33 -> 0 | AE33: =I33-'SA budget'!I33 -> 0 | AF33: =J33-'SA budget'!J33 -> 0 | AG33: =K33-'SA budget'!K33 -> 0 | AH33: =L33-'SA budget'!L33 -> 0 | ... AL33: =P33-'SA budget'!P33 -> 0 | AN33: =SUM(AA33:AL33) -> -25312.453
B34: Mutuelle | C34: k€ | E34: ='SA Actual'!E34 -> 6151.49 | F34: ='SA budget'!F34 -> 0 | G34: ='SA budget'!G34 -> 0 | H34: ='SA budget'!H34 -> 38337.393 | I34: ='SA budget'!I34 -> 0 | J34: ='SA budget'!J34 -> 0 | K34: ='SA budget'!K34 -> 21985.674 | L34: ='SA budget'!L34 -> 0 | M34: ='SA budget'!M34 -> 0 | ... P34: ='SA budget'!P34 -> 0 | R34: =SUM(E34:P34) -> 88460.23 | AA34: =E34-'SA budget'!E34 -> -15834.184 | AB34: =F34-'SA budget'!F34 -> 0 | AC34: =G34-'SA budget'!G34 -> 0 | AD34: =H34-'SA budget'!H34 -> 0 | AE34: =I34-'SA budget'!I34 -> 0 | AF34: =J34-'SA budget'!J34 -> 0 | AG34: =K34-'SA budget'!K34 -> 0 | AH34: =L34-'SA budget'!L34 -> 0 | ... AL34: =P34-'SA budget'!P34 -> 0 | AN34: =SUM(AA34:AL34) -> -15834.184
B35: Dgfip (PAS) | C35: k€ | E35: ='SA Actual'!E35 -> 69813 | F35: ='SA budget'!F35 -> 80276.637 | G35: ='SA budget'!G35 -> 259392.52 | H35: ='SA budget'!H35 -> 80276.637 | I35: ='SA budget'!I35 -> 80276.637 | J35: ='SA budget'!J35 -> 80276.637 | K35: ='SA budget'!K35 -> 155276.56 | L35: ='SA budget'!L35 -> 80276.637 | M35: ='SA budget'!M35 -> 80276.637 | ... P35: ='SA budget'!P35 -> 80276.637 | R35: =SUM(E35:P35) -> 1206971.8 | AA35: =E35-'SA budget'!E35 -> -10463.637 | AB35: =F35-'SA budget'!F35 -> 0 | AC35: =G35-'SA budget'!G35 -> 0 | AD35: =H35-'SA budget'!H35 -> 0 | AE35: =I35-'SA budget'!I35 -> 0 | AF35: =J35-'SA budget'!J35 -> 0 | AG35: =K35-'SA budget'!K35 -> 0 | AH35: =L35-'SA budget'!L35 -> 0 | ... AL35: =P35-'SA budget'!P35 -> 0 | AN35: =SUM(AA35:AL35) -> -10463.637
B36: Total Salary & Social Charges | C36: k€ | E36: =SUM(E29:E35) -> 630138.94 | F36: =SUM(F29:F35) -> 1345788.5 | G36: =SUM(G29:G35) -> 1545989.5 | H36: =SUM(H29:H35) -> 765912.07 | I36: =SUM(I29:I35) -> 683436.23 | J36: =SUM(J29:J35) -> 960778.3 | K36: =SUM(K29:K35) -> 1091905.2 | L36: =SUM(L29:L35) -> 683436.23 | ... P36: =SUM(P29:P35) -> 683436.23 | R36: =SUM(E36:P36) -> 10488428 | AA36: =SUM(AA29:AA35) -> -100595.42 | AB36: =SUM(AB29:AB35) -> 0 | AC36: =SUM(AC29:AC35) -> 0 | AD36: =SUM(AD29:AD35) -> 0 | AE36: =SUM(AE29:AE35) -> 0 | AF36: =SUM(AF29:AF35) -> 0 | AG36: =SUM(AG29:AG35) -> 0 | AH36: =SUM(AH29:AH35) -> 0 | ... AL36: =SUM(AL29:AL35) -> 0 | AN36: =SUM(AA36:AL36) -> -100595.42
B38: Jetons de présence | C38: k€ | E38: ='SA Actual'!E38 -> 75500 | F38: ='SA budget'!F38 -> 0 | G38: ='SA budget'!G38 -> 0 | H38: ='SA budget'!H38 -> 0 | I38: ='SA budget'!I38 -> 0 | J38: ='SA budget'!J38 -> 385000 | K38: ='SA budget'!K38 -> 0 | L38: ='SA budget'!L38 -> 0 | M38: ='SA budget'!M38 -> 0 | ... P38: ='SA budget'!P38 -> 385000 | R38: =SUM(E38:P38) -> 845500 | AA38: =E38-'SA budget'!E38 -> 75500 | AB38: =F38-'SA budget'!F38 -> 0 | AC38: =G38-'SA budget'!G38 -> 0 | AD38: =H38-'SA budget'!H38 -> 0 | AE38: =I38-'SA budget'!I38 -> 0 | AF38: =J38-'SA budget'!J38 -> 0 | AG38: =K38-'SA budget'!K38 -> 0 | AH38: =L38-'SA budget'!L38 -> 0 | ... AL38: =P38-'SA budget'!P38 -> 0 | AN38: =SUM(AA38:AL38) -> 75500
B39: Forfait social jetons de présence (urssaf) | C39: k€ | E39: ='SA Actual'!E39 -> 0 | F39: ='SA budget'!F39 -> 0 | G39: ='SA budget'!G39 -> 0 | H39: ='SA budget'!H39 -> 0 | I39: ='SA budget'!I39 -> 0 | J39: ='SA budget'!J39 -> 0 | K39: ='SA budget'!K39 -> 90500 | L39: ='SA budget'!L39 -> 0 | M39: ='SA budget'!M39 -> 0 | ... P39: ='SA budget'!P39 -> 0 | R39: =SUM(E39:P39) -> 90500 | AA39: =E39-'SA budget'!E39 -> -77000 | AB39: =F39-'SA budget'!F39 -> 0 | AC39: =G39-'SA budget'!G39 -> 0 | AD39: =H39-'SA budget'!H39 -> 0 | AE39: =I39-'SA budget'!I39 -> 0 | AF39: =J39-'SA budget'!J39 -> 0 | AG39: =K39-'SA budget'!K39 -> 0 | AH39: =L39-'SA budget'!L39 -> 0 | ... AL39: =P39-'SA budget'!P39 -> 0 | AN39: =SUM(AA39:AL39) -> -77000
B40: Total jetons | C40: k€ | E40: =SUM(E38:E39) -> 75500 | F40: =SUM(F38:F39) -> 0 | G40: =SUM(G38:G39) -> 0 | H40: =SUM(H38:H39) -> 0 | I40: =SUM(I38:I39) -> 0 | J40: =SUM(J38:J39) -> 385000 | K40: =SUM(K38:K39) -> 90500 | L40: =SUM(L38:L39) -> 0 | ... P40: =SUM(P38:P39) -> 385000 | R40: =SUM(E40:P40) -> 936000 | AA40: =SUM(AA38:AA39) -> -1500 | AB40: =SUM(AB38:AB39) -> 0 | AC40: =SUM(AC38:AC39) -> 0 | AD40: =SUM(AD38:AD39) -> 0 | AE40: =SUM(AE38:AE39) -> 0 | AF40: =SUM(AF38:AF39) -> 0 | AG40: =SUM(AG38:AG39) -> 0 | AH40: =SUM(AH38:AH39) -> 0 | ... AL40: =SUM(AL38:AL39) -> 0 | AN40: =SUM(AA40:AL40) -> -1500
B42: AGA MdG - Part patronales | C42: k€ | E42: ='SA Actual'!E42 -> 0 | F42: ='SA budget'!F42 -> 274324.77 | G42: ='SA budget'!G42 -> 0 | H42: ='SA budget'!H42 -> 787709.15 | I42: ='SA budget'!I42 -> 0 | J42: ='SA budget'!J42 -> 0 | K42: ='SA budget'!K42 -> 787709.15 | L42: ='SA budget'!L42 -> 0 | M42: ='SA budget'!M42 -> 0 | ... P42: ='SA budget'!P42 -> 787709.15 | R42: =SUM(E42:P42) -> 3425161.4 | AA42: =E42-'SA budget'!E42 -> 0 | AB42: =F42-'SA budget'!F42 -> 0 | AC42: =G42-'SA budget'!G42 -> 0 | AD42: =H42-'SA budget'!H42 -> 0 | AE42: =I42-'SA budget'!I42 -> 0 | AF42: =J42-'SA budget'!J42 -> 0 | AG42: =K42-'SA budget'!K42 -> 0 | AH42: =L42-'SA budget'!L42 -> 0 | ... AL42: =P42-'SA budget'!P42 -> 0 | AN42: =SUM(AA42:AL42) -> 0
B43: AGA MdG - Part salariales | C43: k€ | E43: ='SA Actual'!E43 -> 0 | F43: ='SA budget'!F43 -> 274324.77 | G43: ='SA budget'!G43 -> 0 | H43: ='SA budget'!H43 -> 787709.15 | I43: ='SA budget'!I43 -> 0 | J43: ='SA budget'!J43 -> 0 | K43: ='SA budget'!K43 -> 787709.15 | L43: ='SA budget'!L43 -> 0 | M43: ='SA budget'!M43 -> 0 | ... P43: ='SA budget'!P43 -> 787709.15 | R43: =SUM(E43:P43) -> 3425161.4 | AA43: =E43-'SA budget'!E43 -> 0 | AB43: =F43-'SA budget'!F43 -> 0 | AC43: =G43-'SA budget'!G43 -> 0 | AD43: =H43-'SA budget'!H43 -> 0 | AE43: =I43-'SA budget'!I43 -> 0 | AF43: =J43-'SA budget'!J43 -> 0 | AG43: =K43-'SA budget'!K43 -> 0 | AH43: =L43-'SA budget'!L43 -> 0 | ... AL43: =P43-'SA budget'!P43 -> 0 | AN43: =SUM(AA43:AL43) -> 0
B44: AGA MdG -Remboursement MdG - Part salariales | C44: k€ | E44: ='SA Actual'!E44 -> -400704.4 | F44: ='SA budget'!F44 -> 0 | G44: ='SA budget'!G44 -> 0 | H44: ='SA budget'!H44 -> 0 | I44: ='SA budget'!I44 -> 0 | J44: ='SA budget'!J44 -> 0 | K44: ='SA budget'!K44 -> 0 | L44: ='SA budget'!L44 -> 0 | M44: ='SA budget'!M44 -> 0 | ... P44: ='SA budget'!P44 -> -3425161.4 | R44: =SUM(E44:P44) -> -3825865.8 | AA44: =E44-'SA budget'!E44 -> 0 | AB44: =F44-'SA budget'!F44 -> 0 | AC44: =G44-'SA budget'!G44 -> 0 | AD44: =H44-'SA budget'!H44 -> 0 | AE44: =I44-'SA budget'!I44 -> 0 | AF44: =J44-'SA budget'!J44 -> 0 | AG44: =K44-'SA budget'!K44 -> 0 | AH44: =L44-'SA budget'!L44 -> 0 | ... AL44: =P44-'SA budget'!P44 -> 0 | AN44: =SUM(AA44:AL44) -> 0
B45: AGA Abivax SA (French employee) | C45: k€ | E45: ='SA Actual'!E45 -> 353002 | F45: ='SA budget'!F45 -> 352350 | G45: ='SA budget'!G45 -> 0 | H45: ='SA budget'!H45 -> 8715600 | I45: ='SA budget'!I45 -> 210600 | J45: ='SA budget'!J45 -> 0 | K45: ='SA budget'!K45 -> 502200 | L45: ='SA budget'!L45 -> 0 | M45: ='SA budget'!M45 -> 252720 | ... P45: ='SA budget'!P45 -> 0 | R45: =SUM(E45:P45) -> 14383822 | AA45: =E45-'SA budget'!E45 -> 353002 | AB45: =F45-'SA budget'!F45 -> 0 | AC45: =G45-'SA budget'!G45 -> 0 | AD45: =H45-'SA budget'!H45 -> 0 | AE45: =I45-'SA budget'!I45 -> 0 | AF45: =J45-'SA budget'!J45 -> 0 | AG45: =K45-'SA budget'!K45 -> 0 | AH45: =L45-'SA budget'!L45 -> 0 | ... AL45: =P45-'SA budget'!P45 -> 0 | AN45: =SUM(AA45:AL45) -> 353002
B46: Total AGA | C46: k€ | E46: =SUM(E42:E45) -> -47702.4 | F46: =SUM(F42:F45) -> 900999.53 | G46: =SUM(G42:G45) -> 0 | H46: =SUM(H42:H45) -> 10291018 | I46: =SUM(I42:I45) -> 210600 | J46: =SUM(J42:J45) -> 0 | K46: =SUM(K42:K45) -> 2077618.3 | L46: =SUM(L42:L45) -> 0 | ... P46: =SUM(P42:P45) -> -1849743.1 | R46: =SUM(E46:P46) -> 17408279 | AA46: =SUM(AA42:AA45) -> 353002 | AB46: =SUM(AB42:AB45) -> 0 | AC46: =SUM(AC42:AC45) -> 0 | AD46: =SUM(AD42:AD45) -> 0 | AE46: =SUM(AE42:AE45) -> 0 | AF46: =SUM(AF42:AF45) -> 0 | AG46: =SUM(AG42:AG45) -> 0 | AH46: =SUM(AH42:AH45) -> 0 | ... AL46: =SUM(AL42:AL45) -> 0 | AN46: =SUM(AA46:AL46) -> 353002
B48: Total HR related | C48: k€ | E48: =E46+E40+E36 -> 657936.54 | F48: =F46+F40+F36 -> 2246788 | G48: =G46+G40+G36 -> 1545989.5 | H48: =H46+H40+H36 -> 11056930 | I48: =I46+I40+I36 -> 894036.23 | J48: =J46+J40+J36 -> 1345778.3 | K48: =K46+K40+K36 -> 3260023.5 | L48: =L46+L40+L36 -> 683436.23 | ... P48: =P46+P40+P36 -> -781306.84 | R48: =SUM(E48:P48) -> 28832707 | AA48: =AA46+AA40+AA36 -> 250906.58 | AB48: =AB46+AB40+AB36 -> 0 | AC48: =AC46+AC40+AC36 -> 0 | AD48: =AD46+AD40+AD36 -> 0 | AE48: =AE46+AE40+AE36 -> 0 | AF48: =AF46+AF40+AF36 -> 0 | AG48: =AG46+AG40+AG36 -> 0 | AH48: =AH46+AH40+AH36 -> 0 | ... AL48: =AL46+AL40+AL36 -> 0 | AN48: =SUM(AA48:AL48) -> 250906.58
B50: RTC | C50: k€ | E50: ='SA Actual'!E50 -> 0 | F50: ='SA budget'!F50 -> 0 | G50: ='SA budget'!G50 -> 0 | H50: ='SA budget'!H50 -> 0 | I50: ='SA budget'!I50 -> 0 | J50: ='SA budget'!J50 -> 0 | K50: ='SA budget'!K50 -> 0 | L50: ='SA budget'!L50 -> 0 | M50: ='SA budget'!M50 -> -5000000 | ... P50: ='SA budget'!P50 -> 0 | R50: =SUM(E50:P50) -> -5000000 | AA50: =E50-'SA budget'!E50 -> 0 | AB50: =F50-'SA budget'!F50 -> 0 | AC50: =G50-'SA budget'!G50 -> 0 | AD50: =H50-'SA budget'!H50 -> 0 | AE50: =I50-'SA budget'!I50 -> 0 | AF50: =J50-'SA budget'!J50 -> 0 | AG50: =K50-'SA budget'!K50 -> 0 | AH50: =L50-'SA budget'!L50 -> 0 | ... AL50: =P50-'SA budget'!P50 -> 0 | AN50: =SUM(AA50:AL50) -> 0
B51: IQVIA advances | C51: k€ | E51: ='SA Actual'!E51 -> 0 | F51: ='SA budget'!F51 -> 0 | G51: ='SA budget'!G51 -> 0 | H51: ='SA budget'!H51 -> 0 | I51: ='SA budget'!I51 -> 0 | J51: ='SA budget'!J51 -> 0 | K51: ='SA budget'!K51 -> 0 | L51: ='SA budget'!L51 -> 0 | M51: ='SA budget'!M51 -> 0 | ... P51: ='SA budget'!P51 -> -7739045.2 | AA51: =E51-'SA budget'!E51 -> 0 | AB51: =F51-'SA budget'!F51 -> 0 | AC51: =G51-'SA budget'!G51 -> 0 | AD51: =H51-'SA budget'!H51 -> 0 | AE51: =I51-'SA budget'!I51 -> 0 | AF51: =J51-'SA budget'!J51 -> 0 | AG51: =K51-'SA budget'!K51 -> 0 | AH51: =L51-'SA budget'!L51 -> 0 | ... AL51: =P51-'SA budget'!P51 -> 0 | AN51: =SUM(AA51:AL51) -> 0
B52: BSA/BCE cash in | C52: k€ | E52: ='SA Actual'!E52 -> -22758.4 | F52: ='SA budget'!F52 -> 0 | G52: ='SA budget'!G52 -> 0 | H52: ='SA budget'!H52 -> 0 | I52: ='SA budget'!I52 -> 0 | J52: ='SA budget'!J52 -> 0 | K52: ='SA budget'!K52 -> 0 | L52: ='SA budget'!L52 -> 0 | M52: ='SA budget'!M52 -> 0 | ... P52: ='SA budget'!P52 -> 0 | AA52: =E52-'SA budget'!E52 -> -22758.4 | AB52: =F52-'SA budget'!F52 -> 0 | AC52: =G52-'SA budget'!G52 -> 0 | AD52: =H52-'SA budget'!H52 -> 0 | AE52: =I52-'SA budget'!I52 -> 0 | AF52: =J52-'SA budget'!J52 -> 0 | AG52: =K52-'SA budget'!K52 -> 0 | AH52: =L52-'SA budget'!L52 -> 0 | ... AL52: =P52-'SA budget'!P52 -> 0 | AN52: =SUM(AA52:AL52) -> -22758.4
...

Sheet LLC Reforecast
E3: Cash Forecast - V budget | AA3: Cash Forecast - V budget
B6: Abivax LLC USD
E7: 46023 | F7: =EDATE(E7,1) -> 46054 | G7: =EDATE(F7,1) -> 46082 | H7: =EDATE(G7,1) -> 46113 | I7: =EDATE(H7,1) -> 46143 | J7: =EDATE(I7,1) -> 46174 | K7: =EDATE(J7,1) -> 46204 | L7: =EDATE(K7,1) -> 46235 | M7: =EDATE(L7,1) -> 46266 | ... P7: =EDATE(O7,1) -> 46357 | R7: 2026 | AA7: 46023 | AB7: =EDATE(AA7,1) -> 46054 | AC7: =EDATE(AB7,1) -> 46082 | AD7: =EDATE(AC7,1) -> 46113 | AE7: =EDATE(AD7,1) -> 46143 | AF7: =EDATE(AE7,1) -> 46174 | AG7: =EDATE(AF7,1) -> 46204 | AH7: =EDATE(AG7,1) -> 46235 | AI7: =EDATE(AH7,1) -> 46266 | ... AL7: =EDATE(AK7,1) -> 46357 | AN7: 2026
B9: Amount are VAT excluded
B10: Other Suppliers € (HT) | C10: k$ | E10: ='LLC actual'!E10 -> 615407.3 | F10: ='LLC Budget'!F10 -> 945918.42 | G10: ='LLC Budget'!G10 -> 945918.42 | H10: ='LLC Budget'!H10 -> 945918.42 | I10: ='LLC Budget'!I10 -> 870303.42 | J10: ='LLC Budget'!J10 -> 870303.42 | K10: ='LLC Budget'!K10 -> 870303.42 | L10: ='LLC Budget'!L10 -> 2552403.4 | M10: ='LLC Budget'!M10 -> 2552403.4 | ... P10: ='LLC Budget'!P10 -> 2666531.4 | R10: =SUM(E10:P10) -> 19054346 | AA10: =E10-'LLC Budget'!E10 -> -330511.12 | AB10: =F10-'LLC Budget'!F10 -> 0 | AC10: =G10-'LLC Budget'!G10 -> 0 | AD10: =H10-'LLC Budget'!H10 -> 0 | AE10: =I10-'LLC Budget'!I10 -> 0 | AF10: =J10-'LLC Budget'!J10 -> 0 | AG10: =K10-'LLC Budget'!K10 -> 0 | AH10: =L10-'LLC Budget'!L10 -> 0 | ... AL10: =P10-'LLC Budget'!P10 -> 0 | AN10: =SUM(AA10:AL10) -> -330511.12
B11: Contractor (HT) | C11: k$ | E11: ='LLC actual'!E11 -> 0 | F11: ='LLC Budget'!F11 -> 112000 | G11: ='LLC Budget'!G11 -> 112000 | H11: ='LLC Budget'!H11 -> 112000 | I11: ='LLC Budget'!I11 -> 112000 | J11: ='LLC Budget'!J11 -> 112000 | K11: ='LLC Budget'!K11 -> 112000 | L11: ='LLC Budget'!L11 -> 112000 | M11: ='LLC Budget'!M11 -> 112000 | ... P11: ='LLC Budget'!P11 -> 112000 | R11: =SUM(E11:P11) -> 1232000 | AA11: =E11-'LLC Budget'!E11 -> -112000 | AB11: =F11-'LLC Budget'!F11 -> 0 | AC11: =G11-'LLC Budget'!G11 -> 0 | AD11: =H11-'LLC Budget'!H11 -> 0 | AE11: =I11-'LLC Budget'!I11 -> 0 | AF11: =J11-'LLC Budget'!J11 -> 0 | AG11: =K11-'LLC Budget'!K11 -> 0 | AH11: =L11-'LLC Budget'!L11 -> 0 | ... AL11: =P11-'LLC Budget'!P11 -> 0 | AN11: =SUM(AA11:AL11) -> -112000
B12: Bank fees | C12: k$ | E12: ='LLC actual'!E12 -> 1825.81 | F12: ='LLC Budget'!F12 -> 0 | G12: ='LLC Budget'!G12 -> 0 | H12: ='LLC Budget'!H12 -> 0 | I12: ='LLC Budget'!I12 -> 0 | J12: ='LLC Budget'!J12 -> 0 | K12: ='LLC Budget'!K12 -> 0 | L12: ='LLC Budget'!L12 -> 0 | M12: ='LLC Budget'!M12 -> 0 | ... P12: ='LLC Budget'!P12 -> 0 | AA12: =E12-'LLC Budget'!E12 -> 1825.81 | AB12: =F12-'LLC Budget'!F12 -> 0 | AC12: =G12-'LLC Budget'!G12 -> 0 | AD12: =H12-'LLC Budget'!H12 -> 0 | AE12: =I12-'LLC Budget'!I12 -> 0 | AF12: =J12-'LLC Budget'!J12 -> 0 | AG12: =K12-'LLC Budget'!K12 -> 0 | AH12: =L12-'LLC Budget'!L12 -> 0 | ... AL12: =P12-'LLC Budget'!P12 -> 0
B13: Suppliers + Contractos | C13: k$ | E13: =E11+E10 -> 615407.3 | F13: =F11+F10 -> 1057918.4 | G13: =G11+G10 -> 1057918.4 | H13: =H11+H10 -> 1057918.4 | I13: =I11+I10 -> 982303.42 | J13: =J11+J10 -> 982303.42 | K13: =K11+K10 -> 982303.42 | L13: =L11+L10 -> 2664403.4 | ... P13: =P11+P10 -> 2778531.4 | R13: =SUM(E13:P13) -> 20286346 | AA13: =AA11+AA10 -> -442511.12 | AB13: =AB11+AB10 -> 0 | AC13: =AC11+AC10 -> 0 | AD13: =AD11+AD10 -> 0 | AE13: =AE11+AE10 -> 0 | AF13: =AF11+AF10 -> 0 | AG13: =AG11+AG10 -> 0 | AH13: =AH11+AH10 -> 0 | ... AL13: =AL11+AL10 -> 0 | AN13: =SUM(AA13:AL13) -> -442511.12
B15: Payroll LLC (Salary) | C15: k$ | E15: ='LLC actual'!E15 -> 853284.16 | F15: ='LLC Budget'!F15 -> 893415.14 | G15: ='LLC Budget'!G15 -> 893415.14 | H15: ='LLC Budget'!H15 -> 1106748.5 | I15: ='LLC Budget'!I15 -> 1106748.5 | J15: ='LLC Budget'!J15 -> 1106748.5 | K15: ='LLC Budget'!K15 -> 1184650.9 | L15: ='LLC Budget'!L15 -> 1184650.9 | M15: ='LLC Budget'!M15 -> 1184650.9 | ... P15: ='LLC Budget'!P15 -> 1495900.9 | R15: =SUM(E15:P15) -> 14002015 | AA15: =E15-'LLC Budget'!E15 -> -40130.979 | AB15: =F15-'LLC Budget'!F15 -> 0 | AC15: =G15-'LLC Budget'!G15 -> 0 | AD15: =H15-'LLC Budget'!H15 -> 0 | AE15: =I15-'LLC Budget'!I15 -> 0 | AF15: =J15-'LLC Budget'!J15 -> 0 | AG15: =K15-'LLC Budget'!K15 -> 0 | AH15: =L15-'LLC Budget'!L15 -> 0 | ... AL15: =P15-'LLC Budget'!P15 -> 0 | AN15: =SUM(AA15:AL15) -> -40130.979
B16: Payroll LLC (Charges) | C16: k$ | E16: ='LLC actual'!E16 -> 0 | F16: ='LLC Budget'!F16 -> 138479.35 | G16: ='LLC Budget'!G16 -> 138479.35 | H16: ='LLC Budget'!H16 -> 171546.01 | I16: ='LLC Budget'!I16 -> 171546.01 | J16: ='LLC Budget'!J16 -> 171546.01 | K16: ='LLC Budget'!K16 -> 183620.89 | L16: ='LLC Budget'!L16 -> 183620.89 | M16: ='LLC Budget'!M16 -> 183620.89 | ... P16: ='LLC Budget'!P16 -> 231864.64 | R16: =SUM(E16:P16) -> 2038053.3 | AA16: =E16-'LLC Budget'!E16 -> -138479.35 | AB16: =F16-'LLC Budget'!F16 -> 0 | AC16: =G16-'LLC Budget'!G16 -> 0 | AD16: =H16-'LLC Budget'!H16 -> 0 | AE16: =I16-'LLC Budget'!I16 -> 0 | AF16: =J16-'LLC Budget'!J16 -> 0 | AG16: =K16-'LLC Budget'!K16 -> 0 | AH16: =L16-'LLC Budget'!L16 -> 0 | ... AL16: =P16-'LLC Budget'!P16 -> 0 | AN16: =SUM(AA16:AL16) -> -138479.35
B17: Bonus LLC (Gross) | C17: k$ | E17: ='LLC actual'!E17 -> 0 | F17: ='LLC Budget'!F17 -> 3740926.2 | G17: ='LLC Budget'!G17 -> 0 | H17: ='LLC Budget'!H17 -> 0 | I17: ='LLC Budget'!I17 -> 0 | J17: ='LLC Budget'!J17 -> 0 | K17: ='LLC Budget'!K17 -> 0 | L17: ='LLC Budget'!L17 -> 0 | M17: ='LLC Budget'!M17 -> 0 | ... P17: ='LLC Budget'!P17 -> 0 | R17: =SUM(E17:P17) -> 3740926.2 | AA17: =E17-'LLC Budget'!E17 -> 0 | AB17: =F17-'LLC Budget'!F17 -> 0 | AC17: =G17-'LLC Budget'!G17 -> 0 | AD17: =H17-'LLC Budget'!H17 -> 0 | AE17: =I17-'LLC Budget'!I17 -> 0 | AF17: =J17-'LLC Budget'!J17 -> 0 | AG17: =K17-'LLC Budget'!K17 -> 0 | AH17: =L17-'LLC Budget'!L17 -> 0 | ... AL17: =P17-'LLC Budget'!P17 -> 0 | AN17: =SUM(AA17:AL17) -> 0
B18: Bonus LLC (Charges) | C18: k$ | E18: ='LLC actual'!E18 -> 0 | F18: ='LLC Budget'!F18 -> 579843.56 | G18: ='LLC Budget'!G18 -> 0 | H18: ='LLC Budget'!H18 -> 0 | I18: ='LLC Budget'!I18 -> 0 | J18: ='LLC Budget'!J18 -> 0 | K18: ='LLC Budget'!K18 -> 0 | L18: ='LLC Budget'!L18 -> 0 | M18: ='LLC Budget'!M18 -> 0 | ... P18: ='LLC Budget'!P18 -> 0 | R18: =SUM(E18:P18) -> 579843.56 | AA18: =E18-'LLC Budget'!E18 -> 0 | AB18: =F18-'LLC Budget'!F18 -> 0 | AC18: =G18-'LLC Budget'!G18 -> 0 | AD18: =H18-'LLC Budget'!H18 -> 0 | AE18: =I18-'LLC Budget'!I18 -> 0 | AF18: =J18-'LLC Budget'!J18 -> 0 | AG18: =K18-'LLC Budget'!K18 -> 0 | AH18: =L18-'LLC Budget'!L18 -> 0 | ... AL18: =P18-'LLC Budget'!P18 -> 0 | AN18: =SUM(AA18:AL18) -> 0
B19: Total Salary & Social Charges | C19: k$ | E19: =SUM(E15:E18) -> 853284.16 | F19: =SUM(F15:F18) -> 5352664.2 | G19: =SUM(G15:G18) -> 1031894.5 | H19: =SUM(H15:H18) -> 1278294.5 | I19: =SUM(I15:I18) -> 1278294.5 | J19: =SUM(J15:J18) -> 1278294.5 | K19: =SUM(K15:K18) -> 1368271.8 | L19: =SUM(L15:L18) -> 1368271.8 | ... P19: =SUM(P15:P18) -> 1727765.5 | R19: =SUM(E19:P19) -> 20360838 | AA19: =SUM(AA15:AA18) -> -178610.33 | AB19: =SUM(AB15:AB18) -> 0 | AC19: =SUM(AC15:AC18) -> 0 | AD19: =SUM(AD15:AD18) -> 0 | AE19: =SUM(AE15:AE18) -> 0 | AF19: =SUM(AF15:AF18) -> 0 | AG19: =SUM(AG15:AG18) -> 0 | AH19: =SUM(AH15:AH18) -> 0 | ... AL19: =SUM(AL15:AL18) -> 0 | AN19: =SUM(AA19:AL19) -> -178610.33
B22: AGA charges LLC | C22: k$ | E22: ='LLC actual'!E22 -> 10193888 | F22: ='LLC Budget'!F22 -> 2222235 | G22: ='LLC Budget'!G22 -> 54480.6 | H22: ='LLC Budget'!H22 -> 0 | I22: ='LLC Budget'!I22 -> 0 | J22: ='LLC Budget'!J22 -> 0 | K22: ='LLC Budget'!K22 -> 602154 | L22: ='LLC Budget'!L22 -> 0 | M22: ='LLC Budget'!M22 -> 2168614.6 | ... P22: ='LLC Budget'!P22 -> 138323.38 | R22: =SUM(E22:P22) -> 15379696 | AA22: =E22-'LLC Budget'!E22 -> 10193888 | AB22: =F22-'LLC Budget'!F22 -> 0 | AC22: =G22-'LLC Budget'!G22 -> 0 | AD22: =H22-'LLC Budget'!H22 -> 0 | AE22: =I22-'LLC Budget'!I22 -> 0 | AF22: =J22-'LLC Budget'!J22 -> 0 | AG22: =K22-'LLC Budget'!K22 -> 0 | AH22: =L22-'LLC Budget'!L22 -> 0 | ... AL22: =P22-'LLC Budget'!P22 -> 0 | AN22: =SUM(AA22:AL22) -> 10193888
B23: AGA Uptevia STC | E23: ='LLC actual'!E23 -> 0 | F23: ='LLC Budget'!F23 -> 0 | G23: ='LLC Budget'!G23 -> 0 | H23: ='LLC Budget'!H23 -> 0 | I23: ='LLC Budget'!I23 -> 0 | J23: ='LLC Budget'!J23 -> 0 | K23: ='LLC Budget'!K23 -> 0 | L23: ='LLC Budget'!L23 -> 0 | M23: ='LLC Budget'!M23 -> 0 | ... P23: ='LLC Budget'!P23 -> 0 | AA23: =E23-'LLC Budget'!E23 -> 0 | AB23: =F23-'LLC Budget'!F23 -> 0 | AC23: =G23-'LLC Budget'!G23 -> 0 | AD23: =H23-'LLC Budget'!H23 -> 0 | AE23: =I23-'LLC Budget'!I23 -> 0 | AF23: =J23-'LLC Budget'!J23 -> 0 | AG23: =K23-'LLC Budget'!K23 -> 0 | AH23: =L23-'LLC Budget'!L23 -> 0 | ... AL23: =P23-'LLC Budget'!P23 -> 0
B24: Total AGA | C24: k$ | E24: =SUM(E22:E22) -> 10193888 | F24: =SUM(F22:F22) -> 2222235 | G24: =SUM(G22:G22) -> 54480.6 | H24: =SUM(H22:H22) -> 0 | I24: =SUM(I22:I22) -> 0 | J24: =SUM(J22:J22) -> 0 | K24: =SUM(K22:K22) -> 602154 | L24: =SUM(L22:L22) -> 0 | ... P24: =SUM(P22:P22) -> 138323.38 | R24: =SUM(E24:P24) -> 15379696 | AA24: =SUM(AA22:AA22) -> 10193888 | AB24: =SUM(AB22:AB22) -> 0 | AC24: =SUM(AC22:AC22) -> 0 | AD24: =SUM(AD22:AD22) -> 0 | AE24: =SUM(AE22:AE22) -> 0 | AF24: =SUM(AF22:AF22) -> 0 | AG24: =SUM(AG22:AG22) -> 0 | AH24: =SUM(AH22:AH22) -> 0 | ... AL24: =SUM(AL22:AL22) -> 0 | AN24: =SUM(AA24:AL24) -> 10193888
B26: Total HR related | C26: k$ | E26: =E24+E19 -> 11047172 | F26: =F24+F19 -> 7574899.2 | G26: =G24+G19 -> 1086375.1 | H26: =H24+H19 -> 1278294.5 | I26: =I24+I19 -> 1278294.5 | J26: =J24+J19 -> 1278294.5 | K26: =K24+K19 -> 1970425.8 | L26: =L24+L19 -> 1368271.8 | ... P26: =P24+P19 -> 1866088.9 | R26: =SUM(E26:P26) -> 35740534 | AA26: =AA24+AA19 -> 10015278 | AB26: =AB24+AB19 -> 0 | AC26: =AC24+AC19 -> 0 | AD26: =AD24+AD19 -> 0 | AE26: =AE24+AE19 -> 0 | AF26: =AF24+AF19 -> 0 | AG26: =AG24+AG19 -> 0 | AH26: =AH24+AH19 -> 0 | ... AL26: =AL24+AL19 -> 0 | AN26: =SUM(AA26:AL26) -> 10015278
B28: Interets in | C28: k$ | E28: ='LLC actual'!E28 -> -600434.79 | F28: ='LLC Budget'!F28 -> -480072.95 | G28: ='LLC Budget'!G28 -> -467801.74 | H28: ='LLC Budget'!H28 -> -463370.62 | I28: ='LLC Budget'!I28 -> -458783.03 | J28: ='LLC Budget'!J28 -> -454278.49 | K28: ='LLC Budget'!K28 -> -448897.53 | L28: ='LLC Budget'!L28 -> -441288.02 | M28: ='LLC Budget'!M28 -> -429598.78 | ... P28: ='LLC Budget'!P28 -> -396931.18 | R28: =SUM(E28:P28) -> -5466239.5 | AA28: =E28-'LLC Budget'!E28 -> -108189.17 | AB28: =F28-'LLC Budget'!F28 -> 0 | AC28: =G28-'LLC Budget'!G28 -> 0 | AD28: =H28-'LLC Budget'!H28 -> 0 | AE28: =I28-'LLC Budget'!I28 -> 0 | AF28: =J28-'LLC Budget'!J28 -> 0 | AG28: =K28-'LLC Budget'!K28 -> 0 | AH28: =L28-'LLC Budget'!L28 -> 0 | ... AL28: =P28-'LLC Budget'!P28 -> 0 | AN28: =SUM(AA28:AL28) -> -108189.17
B29: Internal wire | C29: k$ | E29: ='LLC actual'!E29 -> 0 | F29: ='LLC Budget'!F29 -> 0 | G29: ='LLC Budget'!G29 -> 0 | H29: ='LLC Budget'!H29 -> 0 | I29: ='LLC Budget'!I29 -> 0 | J29: ='LLC Budget'!J29 -> 0 | K29: ='LLC Budget'!K29 -> 0 | L29: ='LLC Budget'!L29 -> 0 | M29: ='LLC Budget'!M29 -> 0 | ... P29: ='LLC Budget'!P29 -> 0 | R29: =SUM(E29:P29) -> 0 | AA29: =E29-'LLC Budget'!E29 -> 0 | AB29: =F29-'LLC Budget'!F29 -> 0 | AC29: =G29-'LLC Budget'!G29 -> 0 | AD29: =H29-'LLC Budget'!H29 -> 0 | AE29: =I29-'LLC Budget'!I29 -> 0 | AF29: =J29-'LLC Budget'!J29 -> 0 | AG29: =K29-'LLC Budget'!K29 -> 0 | AH29: =L29-'LLC Budget'!L29 -> 0 | ... AL29: =P29-'LLC Budget'!P29 -> 0 | AN29: =SUM(AA29:AL29) -> 0
B30: Deposit | C30: k$
B32: Total | C32: k$ | E32: =SUM(E28:E29,E24,E19,E13) -> 11062145 | F32: =SUM(F28:F29,F24,F19,F13) -> 8152744.7 | G32: =SUM(G28:G29,G24,G19,G13) -> 1676491.8 | H32: =SUM(H28:H29,H24,H19,H13) -> 1872842.3 | I32: =SUM(I28:I29,I24,I19,I13) -> 1801814.9 | J32: =SUM(J28:J29,J24,J19,J13) -> 1806319.4 | K32: =SUM(K28:K29,K24,K19,K13) -> 2503831.7 | L32: =SUM(L28:L29,L24,L19,L13) -> 3591387.2 | ... P32: =SUM(P28:P29,P24,P19,P13) -> 4247689.1 | R32: =SUM(E32:P32) -> 50560640 | AA32: =SUM(AA28:AA29,AA24,AA19,AA13) -> 9464577.5 | AB32: =SUM(AB28:AB29,AB24,AB19,AB13) -> 0 | AC32: =SUM(AC28:AC29,AC24,AC19,AC13) -> 0 | AD32: =SUM(AD28:AD29,AD24,AD19,AD13) -> 0 | AE32: =SUM(AE28:AE29,AE24,AE19,AE13) -> 0 | AF32: =SUM(AF28:AF29,AF24,AF19,AF13) -> 0 | AG32: =SUM(AG28:AG29,AG24,AG19,AG13) -> 0 | AH32: =SUM(AH28:AH29,AH24,AH19,AH13) -> 0 | ... AL32: =SUM(AL28:AL29,AL24,AL19,AL13) -> 0 | AN32: =SUM(AA32:AL32) -> 9464577.5
R33: =R32/12 -> 4213386.7 | AN33: =AN32/12 -> 788714.79
B35: Cash Balance - Abivax LLC
B37: Balance LLC - USD - begining of month | C37: k$ | E37: ='LLC actual'!E37 -> 1.9794316e+08 | F37: =E38 -> 1.8688101e+08 | G37: =F38 -> 1.7872827e+08 | H37: =G38 -> 1.7705178e+08 | I37: =H38 -> 1.7517893e+08 | J37: =I38 -> 1.7337712e+08 | K37: =J38 -> 1.715708e+08 | L37: =K38 -> 1.6906697e+08 | M37: =L38 -> 1.6547558e+08 | ... P37: =O38 -> 1.5163021e+08 | AA37: =E37-'LLC Budget'!E37 -> 0 | AB37: =F37-'LLC Budget'!F37 -> -9464577.5 | AC37: =G37-'LLC Budget'!G37 -> -9464577.5 | AD37: =H37-'LLC Budget'!H37 -> -9464577.5 | AE37: =I37-'LLC Budget'!I37 -> -9464577.5 | AF37: =J37-'LLC Budget'!J37 -> -9464577.5 | AG37: =K37-'LLC Budget'!K37 -> -9464577.5 | AH37: =L37-'LLC Budget'!L37 -> -9464577.5 | ... AL37: =P37-'LLC Budget'!P37 -> -9464577.5
B38: Balance LLC - USD - end of month | C38: k$ | E38: =E37-E32 -> 1.8688101e+08 | F38: =F37-F32 -> 1.7872827e+08 | G38: =G37-G32 -> 1.7705178e+08 | H38: =H37-H32 -> 1.7517893e+08 | I38: =I37-I32 -> 1.7337712e+08 | J38: =J37-J32 -> 1.715708e+08 | K38: =K37-K32 -> 1.6906697e+08 | L38: =L37-L32 -> 1.6547558e+08 | ... P38: =P37-P32 -> 1.4738252e+08 | AA38: =E38-'LLC Budget'!E38 -> -9464577.5 | AB38: =F38-'LLC Budget'!F38 -> -9464577.5 | AC38: =G38-'LLC Budget'!G38 -> -9464577.5 | AD38: =H38-'LLC Budget'!H38 -> -9464577.5 | AE38: =I38-'LLC Budget'!I38 -> -9464577.5 | AF38: =J38-'LLC Budget'!J38 -> -9464577.5 | AG38: =K38-'LLC Budget'!K38 -> -9464577.5 | AH38: =L38-'LLC Budget'!L38 -> -9464577.5 | ... AL38: =P38-'LLC Budget'!P38 -> -9464577.5
B40: EUR-USD m-1 | C40: $ | E40: ='SA Reforecast'!E88 -> 1.175 | F40: ='SA Reforecast'!F88 -> 1.16 | G40: ='SA Reforecast'!G88 -> 1.16 | H40: ='SA Reforecast'!H88 -> 1.16 | I40: ='SA Reforecast'!I88 -> 1.16 | J40: ='SA Reforecast'!J88 -> 1.16 | K40: ='SA Reforecast'!K88 -> 1.16 | L40: ='SA Reforecast'!L88 -> 1.16 | ... P40: ='SA Reforecast'!P88 -> 1.16 | AA40: =E40-'LLC Budget'!E40 -> 0 | AB40: =F40-'LLC Budget'!F40 -> 0 | AC40: =G40-'LLC Budget'!G40 -> 0 | AD40: =H40-'LLC Budget'!H40 -> 0 | AE40: =I40-'LLC Budget'!I40 -> 0 | AF40: =J40-'LLC Budget'!J40 -> 0 | AG40: =K40-'LLC Budget'!K40 -> 0 | AH40: =L40-'LLC Budget'!L40 -> 0 | ... AL40: =P40-'LLC Budget'!P40 -> 0
B41: EUR-USD m | C41: $ | E41: ='SA Reforecast'!E89 -> 1.1919 | F41: ='SA Reforecast'!F89 -> 1.16 | G41: ='SA Reforecast'!G89 -> 1.16 | H41: ='SA Reforecast'!H89 -> 1.16 | I41: ='SA Reforecast'!I89 -> 1.16 | J41: ='SA Reforecast'!J89 -> 1.16 | K41: ='SA Reforecast'!K89 -> 1.16 | L41: ='SA Reforecast'!L89 -> 1.16 | ... P41: ='SA Reforecast'!P89 -> 1.16 | AA41: =E41-'LLC Budget'!E41 -> 0.0319 | AB41: =F41-'LLC Budget'!F41 -> 0 | AC41: =G41-'LLC Budget'!G41 -> 0 | AD41: =H41-'LLC Budget'!H41 -> 0 | AE41: =I41-'LLC Budget'!I41 -> 0 | AF41: =J41-'LLC Budget'!J41 -> 0 | AG41: =K41-'LLC Budget'!K41 -> 0 | AH41: =L41-'LLC Budget'!L41 -> 0 | ... AL41: =P41-'LLC Budget'!P41 -> 0
B43: Cash Balance - Abivax LLC expressed in EUR
B45: Balance SA-USD - begining of month | C45: k€ | E45: =E37/E40 -> 1.6846226e+08 | F45: =F37/F40 -> 1.6110432e+08 | G45: =G37/G40 -> 1.5407609e+08 | H45: =H37/H40 -> 1.5263084e+08 | I45: =I37/I40 -> 1.5101632e+08 | J45: =J37/J40 -> 1.4946303e+08 | K45: =K37/K40 -> 1.4790586e+08 | L45: =L37/L40 -> 1.4574739e+08 | ... P45: =P37/P40 -> 1.3071569e+08 | AA45: =E45-'LLC Budget'!E45 -> 0 | AB45: =F45-'LLC Budget'!F45 -> -8159118.5 | AC45: =G45-'LLC Budget'!G45 -> -8159118.5 | AD45: =H45-'LLC Budget'!H45 -> -8159118.5 | AE45: =I45-'LLC Budget'!I45 -> -8159118.5 | AF45: =J45-'LLC Budget'!J45 -> -8159118.5 | AG45: =K45-'LLC Budget'!K45 -> -8159118.5 | AH45: =L45-'LLC Budget'!L45 -> -8159118.5 | ... AL45: =P45-'LLC Budget'!P45 -> -8159118.5
B46: Balance SA-USD - end of month | C46: k€ | E46: =E38/E41 -> 1.5679253e+08 | F46: =F38/F41 -> 1.5407609e+08 | G46: =G38/G41 -> 1.5263084e+08 | H46: =H38/H41 -> 1.5101632e+08 | I46: =I38/I41 -> 1.4946303e+08 | J46: =J38/J41 -> 1.4790586e+08 | K46: =K38/K41 -> 1.4574739e+08 | L46: =L38/L41 -> 1.4265136e+08 | ... P46: =P38/P41 -> 1.2705389e+08 | AA46: =E46-'LLC Budget'!E46 -> -12470913 | AB46: =F46-'LLC Budget'!F46 -> -8159118.5 | AC46: =G46-'LLC Budget'!G46 -> -8159118.5 | AD46: =H46-'LLC Budget'!H46 -> -8159118.5 | AE46: =I46-'LLC Budget'!I46 -> -8159118.5 | AF46: =J46-'LLC Budget'!J46 -> -8159118.5 | AG46: =K46-'LLC Budget'!K46 -> -8159118.5 | AH46: =L46-'LLC Budget'!L46 -> -8159118.5 | ... AL46: =P46-'LLC Budget'!P46 -> -8159118.5

Sheet Data Reforecast
C1: EURUSD - Budget | D1: =1/1.16 -> 0.86206897
B3: Verification
F4: Budget
C5: Contractors | D5: French + LLC | E5: EUR | F5: =SUM(M39:M41) -> 15068882
C6: ALL Suppliers without IQVIA/Contractors/Jetons | D6: French-EUR | E6: EUR | F6: =J56 -> 57907732 | I6: Explications
C7: IQVIA | D7: French | E7: EUR | F7: 67563871 | G7: ='SA Reforecast'!R20 -> 74115430 | H7: =G7-F7 -> 6551559 | I7: 3m€ extourne FNP, 1 m€ dépenses janvier/dece, +2,4 milestone 105
C8: ALL Suppliers without contractors | D8: French-USD | E8: EUR | F8: =J65*D1 -> 36304410
C9: ALL Suppliers without contractors | D9: LLC | E9: EUR | F9: =J74*D1 -> 18194371
C10: Jetons | D10: French | E10: EUR | F10: 770000 | G10: ='SA Reforecast'!R40 -> 936000 | H10: 905 k€ versus 770 k€, et charges sociales | L10: charges sociales forfait social intégré au budget ?
C11: Non cash | D11: French | E11: N/A | F11: 286677.12
C12: Non cash | D12: LLC | E12: N/A | F12: 34482.759
C14: Total Suppliers | D14: French + LLC | E14: EUR | F14: =SUM(F5:F12) -> 1.9613043e+08
F15: 1.9613043e+08
F16: =F14-F15 -> 0
C17: Budget 2026 FTE - SA | E17: EUR | F17: 10529171 | G17: ='SA Reforecast'!R36 -> 10488428
C18: Budget 2026 FTE - LLC | E18: EUR | F18: 17706421 | G18: ='LLC Reforecast'!R19 -> 20360838
C19: Budget 2026 AGA LLC | D19: EUR | E19: EUR | F19: 9373187.6 | G19: ='LLC Reforecast'!R24 -> 15379696
C20: Budget 2026 AGA SA | E20: EUR | F20: 30886028 | G20: ='SA Reforecast'!R46 -> 17408279
C22: Total budget 2026 (avec ce fichier) | F22: =F14+SUM(F17:F20) -> 2.6462523e+08 | H22: 265 m€
B25: Abivax SA
C26: IQVIA
C27: Source :
C28: IQVIA Vision Summary Reforecast 20260223
C29: Done with Clinical Trial follow-up and budget for CO impact
C30: CO impact :
C31: RD - Clinical_budget 2026-NBE 10.11update
B33: Source : Suppliers SA EUR-USD et LLC-USD - vBudget
B34: Abivax SA & LLC
C36: Contractors
C37: Budget by quarter
B38: Entity | C38: P&L | D38: Devise | E38: Q1 2026 | F38: Q2 2026 | G38: Q3 2026 | H38: Q4 2026 | J38: 2026 | K38: Monthly | M38: en EUR | P38: Source :
B39: LLC | C39: Contractors USD | D39: USD | E39: 336000 | F39: 336000 | G39: 336000 | H39: 336000 | J39: =SUM(E39:H39) -> 1344000 | K39: =J39/12 -> 112000 | M39: =J39*D1 -> 1158620.7 | P39: Suppliers SA EUR-USD et LLC-USD -vBudget 2026
B40: French | C40: Contractors USD | D40: USD | E40: 2523760 | F40: 2584560 | G40: 2558160 | H40: 2549920 | J40: =SUM(E40:H40) -> 10216400 | K40: =J40/12 -> 851366.67 | M40: =J40*D1 -> 8807241.4
B41: French | C41: Contractors EUR | D41: EUR | E41: 1249340 | F41: 1295540 | G41: 1295540 | H41: 1262600 | J41: =SUM(E41:H41) -> 5103020 | K41: =J41/12 -> 425251.67 | M41: =J41 -> 5103020 | N41: =SUM(M39:M41) -> 15068882
C45: monthly | E45: 46023 | F45: =EDATE(E45,1) -> 46054 | G45: =EDATE(F45,1) -> 46082 | H45: =EDATE(G45,1) -> 46113 | I45: =EDATE(H45,1) -> 46143 | J45: =EDATE(I45,1) -> 46174 | K45: =EDATE(J45,1) -> 46204 | L45: =EDATE(K45,1) -> 46235 | M45: =EDATE(L45,1) -> 46266 | ... P45: =EDATE(O45,1) -> 46357 | R45: Total | S45: check (negligeable)
B46: LLC | C46: Contractors USD-LLC | D46: USD | E46: =E39/3 -> 112000 | F46: =E46 -> 112000 | G46: =F46 -> 112000 | H46: =G46 -> 112000 | I46: =F39/3 -> 112000 | J46: =I46 -> 112000 | K46: =J46 -> 112000 | L46: =G39/3 -> 112000 | M46: =L46 -> 112000 | N46: =M46 -> 112000 | O46: =H39/3 -> 112000 | P46: =O46 -> 112000 | R46: =SUM(E46:P46) -> 1344000 | S46: =R46-J39 -> 0
