Workbook

Sheet Cover page
D2: Abivax financial grids
D6: Support in choosing and implementing an ERP solution

Sheet Cash forecast analysis
A1: Hypothesis used for final comparison (%)
A2: Contingency | B2: 0.15
A3: Inflation rate for licenses costs and TMA - from Y4 | B3: 0.06
A4: External support % | B4: 0.35
H7: Additional costs in analysis (comparison cash conso forecast VS cash forecast analysis
C8: Netsuite - Oracle | D8: SAP - KPMG | F8: Netsuite - Oracle | G8: SAP - KPMG | H8: Comment | N8: Differences
A9: Overall cost over 3 years | C9: =SUM(C24:E24) -> 1238305.8 | D9: =SUM(C28:E28) -> 2172715 | F9: =C9-'Financial analysis conso'!C10 -> 333734.8 | G9: =D9-'Financial analysis conso'!D10 -> 588772.65 | H9: Contingency + external support
A10: Overall cost over 5 years | C10: =SUM(C24:G24) -> 1646657.8 | D10: =SUM(C28:G28) -> 2649482.2 | F10: =C10-'Financial analysis conso'!C11 -> 440052.78 | G10: =D10-'Financial analysis conso'!D11 -> 720373.87 | H10: Contingency + external support + inflation rate
A11: Overall cost over 10 years | C11: =SUM(C24:L24) -> 2902208.8 | D11: =SUM(C28:L28) -> 4115388.1 | F11: =C11-'Financial analysis conso'!C12 -> 940518.82 | G11: =D11-'Financial analysis conso'!D12 -> 1323364.8 | H11: Contingency + external support + inflation rate
A13: Sub-total “Run” Saas (3 years) | C13: =SUM(C23:E23) -> 561025.8 | D13: =SUM(C27:E27) -> 573425 | F13: =C13-'Financial analysis conso'!C38*3 -> 107974.8 | G13: =D13-'Financial analysis conso'!D38*3 -> 55676 | H13: No inflation rate
A14: Sub-total “Run” Saas (5 years) | C14: =SUM(C23:G23) -> 969377.78 | D14: =SUM(C27:G27) -> 1050192.2 | F14: =C14-'Financial analysis conso'!C39 -> 214292.78 | G14: =D14-'Financial analysis conso'!D39 -> 187277.22 | H14: Inflation rate - because of transitional year for the MS program and reduction of costs environment
A15: Sub-total “Run” Saas (10 years) | C15: =SUM(C23:L23) -> 2224928.8 | D15: =SUM(C27:L27) -> 2516098.1 | F15: =C15-'Financial analysis conso'!C39*2 -> 714758.82 | G15: =D15-'Financial analysis conso'!D39*2 -> 790268.14 | H15: Inflation rate
B17: After first negociations
A19: Cash-out forecast for Abivax
A20: Editor/Implementer | C20: Year 1 | D20: Year 2 | E20: Year 3 | F20: Year 4 | G20: Year 5 | H20: Year 6 | I20: Year 7 | J20: Year 8 | K20: Year 9 | L20: Year 10 | M20: TOTAL | S20: CTRL
A21: Netsuite - Oracle | B21: Build + T&E + Contingency | C21: ='Cash forecast consolidation'!E3*(1+$B$2) -> 519248 | D21: ='Cash forecast consolidation'!F3*(1+$B$2) -> 0 | E21: ='Cash forecast consolidation'!G3*(1+$B$2) -> 0 | F21: ='Cash forecast consolidation'!H3*(1+$B$2) -> 0 | G21: ='Cash forecast consolidation'!I3*(1+$B$2) -> 0 | H21: ='Cash forecast consolidation'!J3*(1+$B$2) -> 0 | I21: ='Cash forecast consolidation'!K3*(1+$B$2) -> 0 | J21: ='Cash forecast consolidation'!L3*(1+$B$2) -> 0 | ... L21: ='Cash forecast consolidation'!N3*(1+$B$2) -> 0 | M21: =SUM(C21:L21) -> 519248 | S21: =(SUM(C21:L21))-('Financial analysis conso'!$C$26)*(1+$B$2) -> 0
B22: External support | C22: ='Cash forecast consolidation'!E3*$B$4 -> 158032 | D22: ='Cash forecast consolidation'!F3*$B$4 -> 0 | E22: ='Cash forecast consolidation'!G3*$B$4 -> 0 | F22: ='Cash forecast consolidation'!H3*$B$4 -> 0 | G22: ='Cash forecast consolidation'!I3*$B$4 -> 0 | H22: ='Cash forecast consolidation'!J3*$B$4 -> 0 | I22: ='Cash forecast consolidation'!K3*$B$4 -> 0 | J22: ='Cash forecast consolidation'!L3*$B$4 -> 0 | ... L22: ='Cash forecast consolidation'!N3*$B$4 -> 0 | M22: =SUM(C22:L22) -> 158032 | S22: =(SUM(C22:L22))-($B$4*('Financial analysis conso'!$C$26)) -> 0
B23: Run (license cost and TMA) | C23: ='Cash forecast consolidation'!E4 -> 187008.6 | D23: ='Cash forecast consolidation'!F4 -> 187008.6 | E23: ='Cash forecast consolidation'!G4 -> 187008.6 | F23: ='Cash forecast consolidation'!H4*(1+$B$3) -> 198229.12 | G23: =F23*(1+$B$3) -> 210122.86 | H23: =G23*(1+$B$3) -> 222730.23 | I23: =H23*(1+$B$3) -> 236094.05 | J23: =I23*(1+$B$3) -> 250259.69 | K23: =J23*(1+$B$3) -> 265275.27 | L23: =K23*(1+$B$3) -> 281191.79 | M23: =SUM(C23:L23) -> 2224928.8
B24: TOTAL | C24: =SUM(C21:C23) -> 864288.6 | D24: =SUM(D21:D23) -> 187008.6 | E24: =SUM(E21:E23) -> 187008.6 | F24: =SUM(F21:F23) -> 198229.12 | G24: =SUM(G21:G23) -> 210122.86 | H24: =SUM(H21:H23) -> 222730.23 | I24: =SUM(I21:I23) -> 236094.05 | J24: =SUM(J21:J23) -> 250259.69 | ... L24: =SUM(L21:L23) -> 281191.79 | M24: =SUM(C24:L24) -> 2902208.8
A25: SAP - KPMG | B25: Build + T&E + Contingency | C25: ='Cash forecast consolidation'!E6*(1+$B$2) -> 904128.05 | D25: ='Cash forecast consolidation'!F6*(1+$B$2) -> 321994.25 | E25: ='Cash forecast consolidation'!G6*(1+$B$2) -> 0 | F25: ='Cash forecast consolidation'!H6*(1+$B$2) -> 0 | G25: ='Cash forecast consolidation'!I6*(1+$B$2) -> 0 | H25: ='Cash forecast consolidation'!J6*(1+$B$2) -> 0 | I25: ='Cash forecast consolidation'!K6*(1+$B$2) -> 0 | J25: ='Cash forecast consolidation'!L6*(1+$B$2) -> 0 | ... L25: ='Cash forecast consolidation'!N6*(1+$B$2) -> 0 | M25: =SUM(C25:L25) -> 1226122.3 | S25: =(SUM(C25:L25))-('Financial analysis conso'!$D$26)*(1+$B$2) -> 0
B26: External support | C26: ='Cash forecast consolidation'!E6*$B$4 -> 275169.41 | D26: ='Cash forecast consolidation'!F6*$B$4 -> 97998.25 | E26: ='Cash forecast consolidation'!G6*$B$4 -> 0 | F26: ='Cash forecast consolidation'!H6*$B$4 -> 0 | G26: ='Cash forecast consolidation'!I6*$B$4 -> 0 | H26: ='Cash forecast consolidation'!J6*$B$4 -> 0 | I26: ='Cash forecast consolidation'!K6*$B$4 -> 0 | J26: ='Cash forecast consolidation'!L6*$B$4 -> 0 | ... L26: ='Cash forecast consolidation'!N6*$B$4 -> 0 | M26: =SUM(C26:L26) -> 373167.66 | S26: =(SUM(C26:L26))-($B$4*('Financial analysis conso'!$D$26)) -> 0
B27: Run (license cost and TMA) | C27: ='Cash forecast consolidation'!E7 -> 136745 | D27: ='Cash forecast consolidation'!F7 -> 218340 | E27: ='Cash forecast consolidation'!G7 -> 218340 | F27: ='Cash forecast consolidation'!H7*(1+$B$3) -> 231440.4 | G27: =F27*(1+$B$3) -> 245326.82 | H27: =G27*(1+$B$3) -> 260046.43 | I27: =H27*(1+$B$3) -> 275649.22 | J27: =I27*(1+$B$3) -> 292188.17 | K27: =J27*(1+$B$3) -> 309719.46 | L27: =K27*(1+$B$3) -> 328302.63 | M27: =SUM(C27:L27) -> 2516098.1
B28: TOTAL | C28: =SUM(C25:C27) -> 1316042.5 | D28: =SUM(D25:D27) -> 638332.5 | E28: =SUM(E25:E27) -> 218340 | F28: =SUM(F25:F27) -> 231440.4 | G28: =SUM(G25:G27) -> 245326.82 | H28: =SUM(H25:H27) -> 260046.43 | I28: =SUM(I25:I27) -> 275649.22 | J28: =SUM(J25:J27) -> 292188.17 | ... L28: =SUM(L25:L27) -> 328302.63 | M28: =SUM(C28:L28) -> 4115388.1

Sheet Cash forecast consolidation
C1: Cash-out forecast for Abivax
C2: Editor/Implementer | E2: Year 1 | F2: Year 2 | G2: Year 3 | H2: Year 4 | I2: Year 5 | J2: Year 6 | K2: Year 7 | L2: Year 8 | M2: Year 9 | N2: Year 10 | P2: CTRL | Q2: CTRL
C3: Netsuite - Oracle | D3: BUILD | E3: ='Netsuite Cash forecast'!C12 -> 451520 | F3: ='Netsuite Cash forecast'!D12 -> 0 | G3: ='Netsuite Cash forecast'!E12 -> 0 | H3: ='Netsuite Cash forecast'!F12 -> 0 | I3: ='Netsuite Cash forecast'!G12 -> 0 | J3: ='Netsuite Cash forecast'!H12 -> 0 | K3: ='Netsuite Cash forecast'!I12 -> 0 | L3: ='Netsuite Cash forecast'!J12 -> 0 | ... N3: ='Netsuite Cash forecast'!L12 -> 0 | P3: =SUM(E3:N3)-'Netsuite Cash forecast'!M12 -> 0 | Q3: =SUM(E3:N3)-'Financial analysis conso'!C26 -> 0
D4: Run & TMA | E4: ='Netsuite Cash forecast'!C13 -> 187008.6 | F4: ='Netsuite Cash forecast'!D13 -> 187008.6 | G4: ='Netsuite Cash forecast'!E13 -> 187008.6 | H4: ='Netsuite Cash forecast'!F13 -> 187008.6 | I4: ='Netsuite Cash forecast'!G13 -> 187008.6 | J4: ='Netsuite Cash forecast'!H13 -> 187008.6 | K4: ='Netsuite Cash forecast'!I13 -> 187008.6 | L4: ='Netsuite Cash forecast'!J13 -> 187008.6 | ... N4: ='Netsuite Cash forecast'!L13 -> 187008.6 | P4: =SUM(E4:N4)-'Netsuite Cash forecast'!M13 -> 0 | Q4: =SUM(E4:N4)-('Financial analysis With BoB'!C39*2) -> 0
D5: TOTAL | E5: =E3+E4 -> 638528.6 | F5: =F3+F4 -> 187008.6 | G5: =G3+G4 -> 187008.6 | H5: =H3+H4 -> 187008.6 | I5: =I3+I4 -> 187008.6 | J5: =J3+J4 -> 187008.6 | K5: =K3+K4 -> 187008.6 | L5: =L3+L4 -> 187008.6 | ... N5: =N3+N4 -> 187008.6
C6: SAP - KPMG | D6: BUILD | E6: ='SAP Cash forecast'!C12 -> 786198.3 | F6: ='SAP Cash forecast'!D12 -> 279995 | G6: ='SAP Cash forecast'!E12 -> 0 | H6: ='SAP Cash forecast'!F12 -> 0 | I6: ='SAP Cash forecast'!G12 -> 0 | J6: ='SAP Cash forecast'!H12 -> 0 | K6: ='SAP Cash forecast'!I12 -> 0 | L6: ='SAP Cash forecast'!J12 -> 0 | ... N6: ='SAP Cash forecast'!L12 -> 0 | P6: =SUM(E6:N6)-'SAP Cash forecast'!M12 -> 0 | Q6: =SUM(E6:N6)-'Financial analysis conso'!D26 -> 0
D7: Run & TMA | E7: ='SAP Cash forecast'!C13 -> 136745 | F7: ='SAP Cash forecast'!D13 -> 218340 | G7: ='SAP Cash forecast'!E13 -> 218340 | H7: ='SAP Cash forecast'!F13 -> 218340 | I7: ='SAP Cash forecast'!G13 -> 218340 | J7: ='SAP Cash forecast'!H13 -> 218340 | K7: ='SAP Cash forecast'!I13 -> 218340 | L7: ='SAP Cash forecast'!J13 -> 218340 | ... N7: ='SAP Cash forecast'!L13 -> 218340 | P7: =SUM(E7:N7)-'SAP Cash forecast'!M13 -> 0 | Q7: =SUM(E7:N7)-'Financial analysis With BoB'!D39*2 -> -81595 | R7: -81K OK reated to Y1 ramp up
D8: TOTAL | E8: =E6+E7 -> 922943.3 | F8: =F6+F7 -> 498335 | G8: =G6+G7 -> 218340 | H8: =H6+H7 -> 218340 | I8: =I6+I7 -> 218340 | J8: =J6+J7 -> 218340 | K8: =K6+K7 -> 218340 | L8: =L6+L7 -> 218340 | ... N8: =N6+N7 -> 218340

Sheet Financial analysis conso
A5: DETAIL OF FINANCIAL ANALYSIS
C8: Netsuite - Oracle | D8: SAP - KPMG
A9: Saas
A10: Overall cost over 3 years | C10: =C26+C38*3 -> 904571 | D10: =D26+D38*3 -> 1583942.3
A11: Overall cost over 5 years | C11: =C26+C39 -> 1206605 | D11: =D26+D39 -> 1929108.3
A12: Overall cost over 10 years | C12: =C26+C39*2 -> 1961690 | D12: =D26+D39*2 -> 2792023.3
A14: Build | B14: Project management | C14: ='Netsuite Financial analysis'!C16 -> 20960 | D14: ='SAP Financial analysis'!C16 -> 146700
B15: Initialization | C15: ='Netsuite Financial analysis'!C17 -> 50640 | D15: ='SAP Financial analysis'!C17 -> 5800
B16: Solution design | C16: ='Netsuite Financial analysis'!C18 -> 16440 | D16: ='SAP Financial analysis'!C18 -> 114410
B17: Solution implementation | C17: ='Netsuite Financial analysis'!C19 -> 269240 | D17: ='SAP Financial analysis'!C19 -> 246408.3
B18: Data recovery | C18: ='Netsuite Financial analysis'!C20 -> 17120 | D18: ='SAP Financial analysis'!C20 -> 0
B19: Acceptance | C19: ='Netsuite Financial analysis'!C21 -> 11360 | D19: ='SAP Financial analysis'!C21 -> 84100
B20: Training | C20: ='Netsuite Financial analysis'!C22 -> 13920 | D20: ='SAP Financial analysis'!C22 -> 0
B21: Production start-up and assistance | C21: ='Netsuite Financial analysis'!C23 -> 15760 | D21: ='SAP Financial analysis'!C23 -> 109680
B22: Maintenance and user support during the warranty phase | C22: ='Netsuite Financial analysis'!C24 -> 0 | D22: ='SAP Financial analysis'!C24 -> 0
B23: Reversibility management | C23: ='Netsuite Financial analysis'!C25 -> 6640 | D23: ='SAP Financial analysis'!C25 -> 0
B24: Best-of-breed implementation (options) | C24: ='Netsuite Financial analysis'!C26 -> 11440 | D24: ='SAP Financial analysis'!C26 -> 341095
B25: Travel expenses | C25: ='BUILD (3)'!C56 -> 18000 | D25: ='BUILD (4)'!C56 -> 18000
B26: Sub-total “Build” (One-Off) | C26: =SUM(C14:C25) -> 451520 | D26: =SUM(D14:D25) -> 1066193.3
A27: Run | B27: SAAS rent (annual) | C27: =C30+C32 -> 109908 | D27: =D30+D32 -> 115333
B28: SaaS rent (annual unit basis) | C28: ='Netsuite Financial analysis'!C30 -> 779.48936 | D28: ='SAP Financial analysis'!C30 -> 348.43807
B29: SaaS rent (monthly basis) | C29: ='Netsuite Financial analysis'!C31 -> 9159 | D29: ='SAP Financial analysis'!C31 -> 13424.167
B30: SaaS rent (annual basis) | C30: ='Netsuite Financial analysis'!C32 -> 109908 | D30: ='SAP Financial analysis'!C32 -> 115333
B31: Best of Breed SaaS rent (annual basis) | C31: ='Netsuite Financial analysis'!C33 -> 23935.8 | D31: ='SAP Financial analysis'!C33 -> 45757
B32: Hosting subscription (annual) | C32: ='Netsuite Financial analysis'!C34 -> 0 | D32: ='SAP Financial analysis'!C34 -> 0
B33: Other costs | C33: ='Netsuite Financial analysis'!C35 -> 12055.8 | D33: ='SAP Financial analysis'!C35 -> 0
B34: TMA (annual) | C34: =SUM(C35:C37) -> 41109 | D34: =SUM(D35:D37) -> 57250
B35: Support (annual basis) | C35: ='Netsuite Financial analysis'!C37 -> 21257.4 | D35: ='SAP Financial analysis'!C37 -> 14400
B36: TMA rent (annual basis) | C36: ='Netsuite Financial analysis'!C38 -> 19851.6 | D36: ='SAP Financial analysis'!C38 -> 42850
B37: Other support / maintenance services | C37: ='Netsuite Financial analysis'!C39 -> 0 | D37: ='SAP Financial analysis'!C39 -> 0
B38: Sub-total “Run” Saas (annual) | C38: =C34+C27 -> 151017 | D38: =D34+D27 -> 172583
B39: Sub-total “Run” Saas (5 years) | C39: =C38*5 -> 755085 | D39: =D38*5 -> 862915
A41: Total (man days) | C41: =Graph!C50 -> 372 | D41: =Graph!D50 -> 747.5
A42: Integrator's average daily rate | C42: =(C26-C25)/C41 -> 1165.3763 | D42: =(D26-D25)/D41 -> 1402.2653
A44: Abivax Workload | C44: ='Netsuite Financial analysis'!C46 -> 134 | D44: ='SAP Financial analysis'!C46 -> 480
A46: Ratio Abivax load VS implementer | C46: =C44/C41 -> 0.36021505 | D46: =D44/D41 -> 0.64214047

Sheet Financial analysis With BoB
A5: DETAIL OF FINANCIAL ANALYSIS
C8: Netsuite - Oracle | D8: SAP - KPMG
A9: Saas
A10: Overall cost over 3 years | C10: =C26+C38*3 -> 1012545.8 | D10: =D26+D38*3 -> 1721213.3
A11: Overall cost over 5 years | C11: =C26+C39 -> 1386563 | D11: =D26+D39 -> 2157893.3
A12: Overall cost over 10 years | C12: =C26+C39*2 -> 2321606 | D12: =D26+D39*2 -> 3249593.3
A14: Build | B14: Project management | C14: ='Netsuite Financial analysis'!C16 -> 20960 | D14: ='SAP Financial analysis'!C16 -> 146700
B15: Initialization | C15: ='Netsuite Financial analysis'!C17 -> 50640 | D15: ='SAP Financial analysis'!C17 -> 5800
B16: Solution design | C16: ='Netsuite Financial analysis'!C18 -> 16440 | D16: ='SAP Financial analysis'!C18 -> 114410
B17: Solution implementation | C17: ='Netsuite Financial analysis'!C19 -> 269240 | D17: ='SAP Financial analysis'!C19 -> 246408.3
B18: Data recovery | C18: ='Netsuite Financial analysis'!C20 -> 17120 | D18: ='SAP Financial analysis'!C20 -> 0
B19: Acceptance | C19: ='Netsuite Financial analysis'!C21 -> 11360 | D19: ='SAP Financial analysis'!C21 -> 84100
B20: Training | C20: ='Netsuite Financial analysis'!C22 -> 13920 | D20: ='SAP Financial analysis'!C22 -> 0
B21: Production start-up and assistance | C21: ='Netsuite Financial analysis'!C23 -> 15760 | D21: ='SAP Financial analysis'!C23 -> 109680 | E21: 2 hypercare months for SAP
B22: Maintenance and user support during the warranty phase | C22: ='Netsuite Financial analysis'!C24 -> 0 | D22: ='SAP Financial analysis'!C24 -> 0
B23: Reversibility management | C23: ='Netsuite Financial analysis'!C25 -> 6640 | D23: ='SAP Financial analysis'!C25 -> 0
B24: Best-of-breed implementation (options) | C24: ='Netsuite Financial analysis'!C26 -> 11440 | D24: ='SAP Financial analysis'!C26 -> 341095
B25: Travel expenses | C25: ='BUILD (3)'!C56 -> 18000 | D25: ='BUILD (4)'!C56 -> 18000
B26: Sub-total “Build” (One-Off) | C26: =SUM(C14:C25) -> 451520 | D26: =SUM(D14:D25) -> 1066193.3
A27: Run | B27: SAAS rent (annual) | C27: ='Netsuite Financial analysis'!C29 -> 145899.6 | D27: ='SAP Financial analysis'!C29 -> 161090
B28: SaaS rent (annual unit basis) | C28: ='Netsuite Financial analysis'!C30 -> 779.48936 | D28: ='SAP Financial analysis'!C30 -> 348.43807
B29: SaaS rent (monthly basis) | C29: ='Netsuite Financial analysis'!C31 -> 9159 | D29: ='SAP Financial analysis'!C31 -> 13424.167
B30: SaaS rent (annual basis) | C30: ='Netsuite Financial analysis'!C32 -> 109908 | D30: ='SAP Financial analysis'!C32 -> 115333
B31: Best of Breed SaaS rent (annual basis) | C31: ='Netsuite Financial analysis'!C33 -> 23935.8 | D31: ='SAP Financial analysis'!C33 -> 45757
B32: Hosting subscription (annual) | C32: ='Netsuite Financial analysis'!C34 -> 0 | D32: ='SAP Financial analysis'!C34 -> 0
B33: Other costs | C33: ='Netsuite Financial analysis'!C35 -> 12055.8 | D33: ='SAP Financial analysis'!C35 -> 0
B34: TMA (annual) | C34: =SUM(C35:C37) -> 41109 | D34: =SUM(D35:D37) -> 57250
B35: Support (annual basis) | C35: ='Netsuite Financial analysis'!C37 -> 21257.4 | D35: ='SAP Financial analysis'!C37 -> 14400
B36: TMA rent (annual basis) | C36: ='Netsuite Financial analysis'!C38 -> 19851.6 | D36: ='SAP Financial analysis'!C38 -> 42850
B37: Other support / maintenance services | C37: ='Netsuite Financial analysis'!C39 -> 0 | D37: ='SAP Financial analysis'!C39 -> 0
B38: Sub-total “Run” Saas (annual) | C38: =C34+C27 -> 187008.6 | D38: =D34+D27 -> 218340
B39: Sub-total “Run” Saas (5 years) | C39: =C38*5 -> 935043 | D39: =D38*5 -> 1091700
A41: Total (man days) without best of breed | C41: ='Netsuite Financial analysis'!C43 -> 382 | D41: ='SAP Financial analysis'!C43 -> 1075.875
A42: Integrator's average daily rate | C42: =(C26-C25)/C41 -> 1134.8691 | D42: =(D26-D25)/D41 -> 974.27053
A44: Abivax Workload | C44: ='Netsuite Financial analysis'!C46 -> 134 | D44: ='SAP Financial analysis'!C46 -> 480
A46: Ratio Abivax load VS inmplementer | C46: =C44/C41 -> 0.35078534 | D46: =D44/D41 -> 0.44614848

Sheet Graph
C37: BUILD (3) | D37: BUILD (4)
C38: Netsuite - Oracle | D38: SAP - KPMG
B39: Project management | C39: {=INDIRECT("'"&C$37&"'!$K15")} -> 18 | D39: {=INDIRECT("'"&D$37&"'!$K15")} -> 144
B40: Initialization | C40: {=INDIRECT("'"&C$37&"'!$K17")} -> 46 | D40: {=INDIRECT("'"&D$37&"'!$K17")} -> 4
B41: Solution design | C41: {=INDIRECT("'"&C$37&"'!$K23")} -> 15 | D41: {=INDIRECT("'"&D$37&"'!$K23")} -> 109.5
B42: Total design | C42: =C40+C41 -> 61 | D42: =D40+D41 -> 113.5
B43: Solution implementation | C43: {=INDIRECT("'"&C$37&"'!$K27")} -> 235 | D43: {=INDIRECT("'"&D$37&"'!$K27")} -> 296
B44: Data recovery | C44: {=INDIRECT("'"&C$37&"'!$K34")} -> 16 | D44: {=INDIRECT("'"&D$37&"'!$K34")} -> 0
B45: Acceptance | C45: {=INDIRECT("'"&C$37&"'!$K38")} -> 10 | D45: {=INDIRECT("'"&D$37&"'!$K38")} -> 94
B46: Training | C46: {=INDIRECT("'"&C$37&"'!$K40")} -> 12 | D46: {=INDIRECT("'"&D$37&"'!$K40")} -> 0
B47: Production start-up and assistance | C47: {=INDIRECT("'"&C$37&"'!$K43")} -> 14 | D47: {=INDIRECT("'"&D$37&"'!$K43")} -> 100
B48: Maintenance and user support during the warranty phase | C48: {=INDIRECT("'"&C$37&"'!$K46")} -> 0 | D48: {=INDIRECT("'"&D$37&"'!$K46")} -> 0
B49: Reversibility management | C49: {=INDIRECT("'"&C$37&"'!$K48")} -> 6 | D49: {=INDIRECT("'"&D$37&"'!$K48")} -> 0
C50: =SUM(C39:C49)-C42 -> 372 | D50: =SUM(D39:D49)-D42 -> 747.5

Sheet License price analysis
C4: Netsuite - Oracle | D4: SAP - KPMG
B5: Unit public price per user per year for Core solution for a full user | C5: ='RUN (3)'!E20/'RUN (3)'!C20 -> 1097.8723 | D5: ='RUN (4)'!E20/'RUN (4)'!C20 -> 812.20423
B6: Discount proposed on public price | C6: 0.29 | D6: Not communicated
B7: Unit price per user per year for Core solution for a full user | C7: ='RUN (3)'!G20/'RUN (3)'!C20 -> 779.48936 | D7: ='RUN (4)'!G20/'RUN (4)'!C20 -> 812.20423
B8: License mix | C8: NetSuite SuiteSuccess Financials Premium Cloud Service: 1 for 43K each NetSuite General Access Cloud Service User (full user): 42 for 1K3 each NetSuite Employee Self-Serve Cloud Service Users: 85 for 216 each NetSuite Specialized View and Approve Cloud Service Users: 10 for 336 each NetSuite OneWorld Cloud Service: 1 for 21,6K each NetSuite Procurement Mid-Market Cloud Service: 1 for 6K480 each NetSuite Inventory Management Mid-Market Cloud Service: 1 for 6k480 each | D8: SAP Finance and Supply Chain developer: 2 for 2K9 each SAP Finance Base: 15 for 3K each SAP Finance and Supply Chain operations: 35 for 700 each SAP Finance and Supply Chain self-service: 90 for 146 each SAP Ariba Central Invoice Management: 20 for 618 each SAP AI Units: 10 for 320 each SAP BTPEA - Build Automation: 1 for 11K each
B9: Total amount of licenses for Core solution / per year | C9: ='RUN (3)'!C20 -> 141 | D9: ='RUN (4)'!C20 -> 142
B10: Total amounts of licenses per year discounts included / with best of breed solution | C10: ='RUN (3)'!G20+'RUN (3)'!G28 -> 133843.8 | D10: =+'RUN (4)'!G20+'RUN (4)'!G30 -> 161090
B11: Total amount / by number of real Abivax users (142 in RFP) | C11: =C10/142 -> 942.56197 | D11: =D10/142 -> 1134.4366
G25: =#REF!/#REF! -> #REF! | H25: =#REF!/#REF! -> #REF! | I25: ='RUN (3)'!K39/'RUN (3)'!I39 -> #DIV/0! | J25: ='RUN (4)'!K39/'RUN (4)'!I39 -> #DIV/0!

Sheet Best of breed
D3: Netsuite - Oracle | E3: SAP - KPMG
C4: Best-of-breed implementation nb of days | D4: {=INDIRECT("'"&Graph!C$37&"'!$K50")} -> 10 | E4: {=INDIRECT("'"&Graph!D$37&"'!$K50")} -> 328.375

Sheet Data >>

Sheet Oracle >>

Sheet RUN (3)
D3: Company name | E3: Oracle Corporation UK Limited
D4: Solution name | E4: Netsuite
B6: DETAIL OF RUN
B9: Fields to be completed by applicant
E10: License cost
B11: Criteria | C11: Quantity | D11: Unit price by year by user | E11: Acquisition cost Public price | F11: Applicable rebate | G11: Final offer V1 | H11: Comments
B12: Licences Core Model | C12: Nb of users | D12: Unit price € Excluding tax | E12: € Excluding tax (by year) | F12: % | G12: € Excluding tax
B13: NetSuite SuiteSuccess Financials Premium Cloud Service | C13: 1 | D13: 43080 | E13: =C13*D13 -> 43080 | F13: 0.29 | G13: =E13*(1-F13) -> 30586.8 | H13: This refers to the core ERP, which includes all standard functionalities, excluding optional modules.
B14: NetSuite General Access Cloud Service User (full user) | C14: 42 | D14: 1320 | E14: =C14*D14 -> 55440 | F14: 0.29 | G14: =E14*(1-F14) -> 39362.4 | H14: This represents the upper-bound assumption for the number of Full users. This number can be reduced in favor of “Self-Serve” or “View and Approve” user profiles, following our discussions to define the appropriate user volume based on business needs.
B15: NetSuite Employee Self-Serve Cloud Service Users | C15: 85 | D15: 216 | E15: =C15*D15 -> 18360 | F15: 0.29 | G15: =E15*(1-F15) -> 13035.6 | H15: The NetSuite Employee Self-Serve user is a limited-access internal user designed for employees to perform basic self-service activities. This user profile allows employees to: Enter and submit their worked time Submit personal expense reports Submit purchase requests Create and submit support tickets Approve time and expense transactions Create events, contacts, and tasks in the NetSuite calendar This role does not provide any access to accounting, financial, sales, administrative, or marketing functions, nor to financial reports, budgets, or transactions (including view-only access). - One pack of 5 NetSuite Employee Self-Service Cloud Service Users is already included in the NetSuite SuiteSuccess Financials Premier core ERP.
B16: NetSuite Specialized View and Approve Cloud Service Users | C16: 10 | D16: 336 | E16: =C16*D16 -> 3360 | F16: 0.29 | G16: =E16*(1-F16) -> 2385.6 | H16: NetSuite Specialized View and Approve Cloud Service 5-Pk Users allows a User to have read-only access and approve specific records, as listed below, within the NetSuite Cloud Service. • Invoices; • Journal Entries; • Return Authorizations; • Sales Orders; • Transfer Orders; • Vendor Bills; • Vendor Payments; • Vendor In-Transit Payments; and • Vendor Return Authorizations. If Customer has Procurement Management Cloud Service (any edition), then NetSuite Specialized View and Approve Cloud Service 5-Pk Users allows a User to have read-only access and approve specific records, as listed below: • Blanket Purchase Orders; • Purchase Contract Approvals; and • Requisitions Approvals. NetSuite Specialized View and Approve Cloud Service 5-Pk Users cannot: • Transact within the NetSuite Service; • Set up or configure any NetSuite Service; • Modify pre-established permissions already restricted to “Approve” or “View-Only” access; • View payroll information; or • View employee records. Usage Limits: NetSuite Specialized View and Approve Cloud Service 5-Pk Users is subject to the following usage limits: • Customer is entitled to the quantity of NetSuite Specialized View and Approve Cloud Service 5-Pk Users specified in Customer’s Estimate Order Form. • NetSuite Specialized View and Approve Cloud Service 5-Pk Users is limited to only the features and functionalities and Customer records listed above that the Customer makes available to the specific NetSuite Specialized View and Approve Cloud Service 5-Pk Users. If customizations result in modifications to the access and use rights granted to the NetSuite Specialized View and Approve Cloud
B17: NetSuite OneWorld Cloud Service | C17: 1 | D17: 21600 | E17: =C17*D17 -> 21600 | F17: 0.29 | G17: =E17*(1-F18) -> 15336 | H17: NetSuite OneWorld allows a company to manage multiple subsidiaries, business units, and locations across different countries, including localized operations like US subsidiaries.
B18: NetSuite Procurement Mid-Market Cloud Service | C18: 1 | D18: 6480 | E18: =C18*D18 -> 6480 | F18: 0.29 | G18: =E18*(1-F19) -> 4600.8
B19: NetSuite Inventory Management Mid-Market Cloud Service | C19: 1 | D19: 6480 | E19: =C19*D19 -> 6480 | F19: 0.29 | G19: =E19*(1-F19) -> 4600.8
B20: Sub-total for licences cost (core model exc. Best of breed) | C20: =SUM(C13:C19) -> 141 | D20: =SUM(D13:D19) -> 79512 | E20: =SUM(E13:E19) -> 154800 | G20: =SUM(G13:G19) -> 109908
B21: Add-ons, best-of-breed and other licenses by domain | C21: Nb of users | D21: Unit price € Excluding tax | E21: € Excluding tax (by year) | F21: % | G21: € Excluding tax
B22: NetSuite Analytics Warehouse Standard Cloud Service (NSAW) | C22: 1 | D22: 8160 | E22: =C22*D22 -> 8160 | F22: 0.29 | G22: =E22*(1-F22) -> 5793.6 | H22: NetSuite Analytics Warehouse (NSAW) is NetSuite’s BI tool for reporting, analytics, and dashboards. 10 users included
B23: Oracle Integration Cloud Service for Oracle SaaS - Standard (NSIP) | C23: 1 | D23: 6720 | E23: =C23*D23 -> 6720 | F23: 0.29 | G23: =E23*(1-F23) -> 4771.2 | H23: NSIP is NetSuite’s ETL tool for integrating, transforming, and syncing data
B24: ZoneCapture | C24: 1 | D24: 6555 | E24: =C24*D24 -> 6555 | G24: =E24*(1-F24) -> 6555 | H24: Partner solution (SDN) built for NetSuite for OCR. Pricing is based on the number of vendor invoices. The indicated price corresponds to a maximum volume of 500 invoices per month.
A25: Moved from "Other cost items | B25: NetSuite Electronic Invoices Mid-Market Cloud Service | C25: 1 | D25: 8640 | E25: =C25*D25 -> 8640 | F25: 0.29 | G25: =E25*(1-F25) -> 6134.4 | H25: This service supports e-invoicing by enabling the creation, transmission, and management of electronic invoices directly within NetSuite.
A26: Moved from "Other cost items | B26: NetSuite Electronic Business Extension | C26: 1 | D26: 240 | E26: =C26*D26 -> 240 | F26: 0.29 | G26: =E26*(1-F26) -> 170.4 | H26: NetSuite Electronic Business Extension provides the secure integration layer required to enable electronic business communications, including e-invoicing, between NetSuite and external partners or networks.
A27: Moved from "Other cost items | B27: NetSuite Electronic Document Processing Cloud Service | C27: 1 | D27: 720 | E27: =C27*D27 -> 720 | F27: 0.29 | G27: =E27*(1-F27) -> 511.2 | H27: NetSuite Electronic Document Processing Cloud Service enables the electronic processing of various business documents (such as invoices, bills, credit memos, cash sales, purchase orders, and more) through Avalara networks, with each license including a cap of 1000 Documents Processed per 12-month period.
B28: Sub-total for licences cost (Best of breed) | C28: =SUM(C22:C27) -> 6 | D28: =SUM(D22:D27) -> 31035 | E28: =SUM(E22:E27) -> 31035 | G28: =SUM(G22:G27) -> 23935.8
B29: Support & Maintenance | C29: Quantity | D29: Unit price € Excluding tax | E29: € Excluding tax (by year) | F29: % | G29: € Excluding tax
B30: Support (helpdesk) = 20 days per year NetSuite Premium Support | C30: 1 | D30: 16980 | E30: =C30*D30 -> 16980 | F30: 0.29 | G30: =E30*(1-F30) -> 12055.8
B31: Maintenance : • Corrective maintenance = 30 days per year • Major release assistance = 10 days per year • Evolution assistance = 15 days a year • Project management related to the follow-up of services provided = 2 hours by quarter | C31: 1 | D31: 27960 | E31: =C31*D31 -> 27960 | F31: 0.29 | G31: =E31*(1-F31) -> 19851.6 | H31: refer to appendix ABIVAX - Appendix Delivery team NetSuite CS.zip document in 008 Maintenance team - ACS presentation
B32: Customer Learning Cloud Support Company Pass - Premium | C32: 1 | D32: 12960 | E32: =C32*D32 -> 12960 | F32: 0.29 | G32: =E32*(1-F32) -> 9201.6
B33: Total other services offered | C33: =SUM(C30:C32) -> 3 | D33: =SUM(D30:D32) -> 57900 | E33: =SUM(E30:E32) -> 57900 | G33: =SUM(G30:G32) -> 41109
B34: Other cost items (infrastructure, etc.) | C34: Quantity | D34: Unit price € Excluding tax | E34: € Excluding tax | F34: % | G34: € Excluding tax
B35: Hosting subscription (annual) | E35: =C35*D35 -> 0 | G35: =E35*(1-F35) -> 0
B36: NetSuite Standard Tier Infrastructure Cloud Service (included) | C36: 1 | E36: =C36*D36 -> 0 | F36: 0.29 | G36: =E36*(1-F36) -> 0 | H36: Standard Tier – Infrastructure sized according to transaction volume and user count; to be confirmed based on discussions. This is the Standard version, which can be upgraded to premium based on our discussions.
B37: NetSuite Sandbox Environment Cloud Service | C37: 1 | D37: 16980 | E37: =C37*D37 -> 16980 | F37: 0.29 | G37: =E37*(1-F37) -> 12055.8
B41: Sub-total for other items | C41: =SUM(C35:C40) -> 2 | D41: =SUM(D35:D40) -> 16980 | E41: =SUM(E35:E40) -> 16980 | G41: =SUM(G35:G40) -> 12055.8
C43: TOTAL | G43: =G20+G28+G33+G41 -> 187008.6
B47: It is understood that further discussions and dialogue will take place between us and that these may lead us to agree changes to the solution which is currently envisaged. If that happens we will issue an updated estimate reflecting such changes.

Sheet BUILD (3)
D3: Company name | E3: Oracle Corporation UK Limited
D4: Solution name | E4: Netsuite
B6: DETAIL OF BUILD
B9: Is the project costed on a fixed-price basis?
B10: Fields to be completed by applicant
B11: Phases | C11: Workloads Provider / profile / phase | M11: GC workloads / profile / phase | U11: Assumptions / Comments
C12: Project Director Profile | D12: Project Manager Profile | E12: Technical Consultant Profile | F12: Functional Consultant Profile | G12: Trainer Profile | H12: IT Architect Profile | I12: Profile xxxxxx | J12: Profile xxxxxx | K12: Total (Days) | L12: Total € by phase | M12: Project Manager | N12: BPO | O12: Key User | P12: Users | Q12: IT team member (technical responsible) | R12: Profile xxxxxx | S12: Profile xxxxxx | T12: Total (D) | U12: Total € by phase
B13: Average daily rate by profile (in € excl. tax) | C13: 1240 | D13: 1160 | E13: 1000 | F13: 1160 | G13: 1160 | H13: 1160
C14: Estimated workload (in days) | M14: Estimated workload (in days)
B15: Project management | C15: =SUM(C16) -> 3 | D15: =SUM(D16) -> 14 | E15: =SUM(E16) -> 1 | F15: =SUM(F16) -> 0 | G15: =SUM(G16) -> 0 | H15: =SUM(H16) -> 0 | I15: =SUM(I16) -> 0 | J15: =SUM(J16) -> 0 | K15: =SUM(C15:J15) -> 18 | L15: =SUMPRODUCT(C15:J15,$C$13:$J$13) -> 20960 | M15: =M16 -> 5 | N15: =N16 -> 2 | O15: =O16 -> 1 | P15: =P16 -> 0 | Q15: =Q16 -> 1 | R15: =R16 -> 0 | S15: =S16 -> 0 | T15: =SUM(M15:S15) -> 9
B16: Project follow-up | C16: 3 | D16: 14 | E16: 1 | F16: 0 | G16: 0 | H16: 0 | I16: 0 | J16: 0 | K16: =SUM(C16:J16) -> 18 | L16: =SUMPRODUCT(C16:J16,$C$13:$J$13) -> 20960 | M16: 5 | N16: 2 | O16: 1 | P16: 0 | Q16: 1 | T16: =SUM(M16:S16) -> 9
B17: Initialization | C17: =SUM(C18:C22) -> 2 | D17: =SUM(D18:D22) -> 6 | E17: =SUM(E18:E22) -> 18 | F17: =SUM(F18:F22) -> 16 | G17: =SUM(G18:G22) -> 0 | H17: =SUM(H18:H22) -> 4 | I17: =SUM(I18:I22) -> 0 | J17: =SUM(J18:J22) -> 0 | K17: =SUM(C17:J17) -> 46 | L17: =SUMPRODUCT(C17:J17,$C$13:$J$13) -> 50640 | M17: =SUM(M18:M22) -> 8 | N17: =SUM(N18:N22) -> 9 | O17: =SUM(O18:O22) -> 7 | P17: =SUM(P18:P22) -> 0 | Q17: =SUM(Q18:Q22) -> 6 | R17: =SUM(R18:R22) -> 0 | S17: =SUM(S18:S22) -> 0 | T17: =SUM(M17:S17) -> 30
B18: Project scoping and launch | C18: 2 | D18: 6 | E18: 2 | F18: 0 | G18: 0 | H18: 1 | I18: 0 | K18: =SUM(C18:J18) -> 11 | L18: =SUMPRODUCT(C18:J18,$C$13:$J$13) -> 12600 | M18: 4 | N18: 2 | O18: 1 | P18: 0 | Q18: 1 | T18: =SUM(M18:S18) -> 8
B19: Technical analysis | C19: 0 | D19: 0 | E19: 1 | F19: 7 | G19: 0 | H19: 2 | I19: 0 | K19: =SUM(C19:J19) -> 10 | L19: =SUMPRODUCT(C19:J19,$C$13:$J$13) -> 11440 | M19: 1 | N19: 1 | O19: 1 | P19: 0 | Q19: 2 | T19: =SUM(M19:S19) -> 5
B20: Functional analysis | C20: 0 | D20: 0 | E20: 11 | F20: 4 | G20: 0 | H20: 1 | I20: 0 | K20: =SUM(C20:J20) -> 16 | L20: =SUMPRODUCT(C20:J20,$C$13:$J$13) -> 16800 | M20: 2 | N20: 4 | O20: 3 | P20: 0 | Q20: 1 | T20: =SUM(M20:S20) -> 10
B21: Data analysis | C21: 0 | D21: 0 | E21: 2 | F21: 3 | G21: 0 | H21: 0 | I21: 0 | K21: =SUM(C21:J21) -> 5 | L21: =SUMPRODUCT(C21:J21,$C$13:$J$13) -> 5480 | M21: 1 | N21: 2 | O21: 1 | P21: 0 | Q21: 1 | T21: =SUM(M21:S21) -> 5
B22: Preparation of environments | C22: 0 | D22: 0 | E22: 2 | F22: 2 | G22: 0 | H22: 0 | I22: 0 | K22: =SUM(C22:J22) -> 4 | L22: =SUMPRODUCT(C22:J22,$C$13:$J$13) -> 4320 | M22: 0 | N22: 0 | O22: 1 | P22: 0 | Q22: 1 | T22: =SUM(M22:S22) -> 2
B23: Solution design | C23: =SUM(C24:C25) -> 0 | D23: =SUM(D24:D25) -> 0 | E23: =SUM(E24:E25) -> 6 | F23: =SUM(F24:F25) -> 9 | G23: =SUM(G24:G25) -> 0 | H23: =SUM(H24:H25) -> 0 | I23: =SUM(I24:I25) -> 0 | J23: =SUM(J24:J25) -> 0 | K23: =SUM(C23:J23) -> 15 | L23: =SUMPRODUCT(C23:J23,$C$13:$J$13) -> 16440 | M23: =SUM(M24:M25) -> 2 | N23: =SUM(N24:N25) -> 3 | O23: =SUM(O24:O25) -> 1 | P23: =SUM(P24:P25) -> 0 | Q23: =SUM(Q24:Q25) -> 0 | R23: =SUM(R24:R25) -> 0 | S23: =SUM(S24:S25) -> 0 | T23: =SUM(M23:S23) -> 6
B24: Drafting of solution design file | C24: 0 | D24: 0 | E24: 3 | F24: 6 | G24: 0 | H24: 0 | I24: 0 | K24: =SUM(C24:J24) -> 9 | L24: =SUMPRODUCT(C24:J24,$C$13:$J$13) -> 9960 | M24: 1 | N24: 2 | O24: 1 | P24: 0 | Q24: 0 | T24: =SUM(M24:S24) -> 4
B25: Definition of development plan | C25: 0 | D25: 0 | E25: 3 | F25: 3 | G25: 0 | H25: 0 | I25: 0 | K25: =SUM(C25:J25) -> 6 | L25: =SUMPRODUCT(C25:J25,$C$13:$J$13) -> 6480 | M25: 1 | N25: 1 | O25: 0 | P25: 0 | Q25: 0 | T25: =SUM(M25:S25) -> 2
B26: Initialization and design | C26: =C23+C17 -> 2 | D26: =D23+D17 -> 6 | E26: =E23+E17 -> 24 | F26: =F23+F17 -> 25 | G26: =G23+G17 -> 0 | H26: =H23+H17 -> 4 | I26: =I23+I17 -> 0 | J26: =J23+J17 -> 0 | K26: =K23+K17 -> 61 | L26: =SUMPRODUCT(C26:J26,$C$13:$J$13) -> 67080 | M26: =M23+M17 -> 10 | N26: =N23+N17 -> 12 | O26: =O23+O17 -> 8 | P26: =P23+P17 -> 0 | Q26: =Q23+Q17 -> 6 | R26: =R23+R17 -> 0 | S26: =S23+S17 -> 0 | T26: =SUM(M26:S26) -> 36
B27: Solution implementation | C27: =SUM(C28:C33) -> 0 | D27: =SUM(D28:D33) -> 0 | E27: =SUM(E28:E33) -> 21 | F27: =SUM(F28:F33) -> 208 | G27: =SUM(G28:G33) -> 0 | H27: =SUM(H28:H33) -> 6 | I27: =SUM(I28:I33) -> 0 | J27: =SUM(J28:J33) -> 0 | K27: =SUM(C27:J27) -> 235 | L27: =SUMPRODUCT(C27:J27,$C$13:$J$13) -> 269240 | M27: =SUM(M28:M33) -> 0 | N27: =SUM(N28:N33) -> 7 | O27: =SUM(O28:O33) -> 10 | P27: =SUM(P28:P33) -> 1 | Q27: =SUM(Q28:Q33) -> 9 | R27: =SUM(R28:R33) -> 0 | S27: =SUM(S28:S33) -> 0 | T27: =SUM(M27:S27) -> 27
B28: Specific development and parameterization | C28: 0 | D28: 0 | E28: 9 | F28: 139 | G28: 0 | H28: 2 | I28: 0 | K28: =SUM(C28:J28) -> 150 | L28: =SUMPRODUCT(C28:J28,$C$13:$J$13) -> 172560 | M28: 0 | N28: 2 | O28: 2 | P28: 0 | Q28: 2 | T28: =SUM(M28:S28) -> 6
B29: Realization of interfaces (please provide with the details in the Interfaces detail tab) | C29: 0 | D29: 0 | E29: 5 | F29: 49 | G29: 0 | H29: 1 | I29: 0 | K29: =SUM(C29:J29) -> 55 | L29: =SUMPRODUCT(C29:J29,$C$13:$J$13) -> 63000 | M29: 0 | N29: 0 | O29: 0 | P29: 0 | Q29: 3 | T29: =SUM(M29:S29) -> 3
B30: Production of editions | C30: 0 | D30: 0 | E30: 1 | F30: 7 | G30: 0 | H30: 0 | K30: =SUM(C30:J30) -> 8 | L30: =SUMPRODUCT(C30:J30,$C$13:$J$13) -> 9120 | M30: 0 | N30: 1 | O30: 1 | P30: 0 | Q30: 1 | T30: =SUM(M30:S30) -> 3
B31: Production of indicators and dashboards | C31: 0 | D31: 0 | E31: 2 | F31: 5 | G31: 0 | H31: 1 | K31: =SUM(C31:J31) -> 8 | L31: =SUMPRODUCT(C31:J31,$C$13:$J$13) -> 8960 | M31: 0 | N31: 1 | O31: 2 | P31: 0 | Q31: 1 | T31: =SUM(M31:S31) -> 4
B32: Unit testing | C32: 0 | D32: 0 | E32: 2 | F32: 5 | G32: 0 | H32: 1 | K32: =SUM(C32:J32) -> 8 | L32: =SUMPRODUCT(C32:J32,$C$13:$J$13) -> 8960 | M32: 0 | N32: 1 | O32: 2 | P32: 0 | Q32: 1 | T32: =SUM(M32:S32) -> 4
B33: End-to-end testing support | C33: 0 | D33: 0 | E33: 2 | F33: 3 | G33: 0 | H33: 1 | K33: =SUM(C33:J33) -> 6 | L33: =SUMPRODUCT(C33:J33,$C$13:$J$13) -> 6640 | M33: 0 | N33: 2 | O33: 3 | P33: 1 | Q33: 1 | T33: =SUM(M33:S33) -> 7
B34: Data migration | C34: =SUM(C35:C37) -> 0 | D34: =SUM(D35:D37) -> 0 | E34: =SUM(E35:E37) -> 9 | F34: =SUM(F35:F37) -> 6 | G34: =SUM(G35:G37) -> 0 | H34: =SUM(H35:H37) -> 1 | I34: =SUM(I35:I37) -> 0 | J34: =SUM(J35:J37) -> 0 | K34: =SUM(C34:J34) -> 16 | L34: =SUMPRODUCT(C34:J34,$C$13:$J$13) -> 17120 | M34: =SUM(M35:M37) -> 2 | N34: =SUM(N35:N37) -> 6 | O34: =SUM(O35:O37) -> 1 | P34: =SUM(P35:P37) -> 0 | Q34: =SUM(Q35:Q37) -> 5 | R34: =SUM(R35:R37) -> 0 | S34: =SUM(S35:S37) -> 0 | T34: =SUM(M34:S34) -> 14
B35: Cleaning and standardization of repositories | C35: 0 | D35: 0 | E35: 3 | F35: 0 | G35: 0 | H35: 0 | K35: =SUM(C35:J35) -> 3 | L35: =SUMPRODUCT(C35:J35,$C$13:$J$13) -> 3000 | M35: 0 | N35: 2 | O35: 0 | P35: 0 | Q35: 2 | T35: =SUM(M35:S35) -> 4
B36: Formalization of target data architecture | C36: 0 | D36: 0 | E36: 2 | F36: 3 | G36: 0 | H36: 1 | K36: =SUM(C36:J36) -> 6 | L36: =SUMPRODUCT(C36:J36,$C$13:$J$13) -> 6640 | M36: 1 | N36: 2 | O36: 0 | P36: 0 | Q36: 1 | T36: =SUM(M36:S36) -> 4
B37: Data migration | C37: 0 | D37: 0 | E37: 4 | F37: 3 | G37: 0 | H37: 0 | K37: =SUM(C37:J37) -> 7 | L37: =SUMPRODUCT(C37:J37,$C$13:$J$13) -> 7480 | M37: 1 | N37: 2 | O37: 1 | P37: 0 | Q37: 2 | T37: =SUM(M37:S37) -> 6
B38: Acceptance | C38: =C39 -> 1 | D38: =D39 -> 4 | E38: =E39 -> 2 | F38: =F39 -> 2 | G38: =G39 -> 0 | H38: =H39 -> 1 | I38: =I39 -> 0 | J38: =J39 -> 0 | K38: =SUM(C38:J38) -> 10 | L38: =SUMPRODUCT(C38:J38,$C$13:$J$13) -> 11360 | M38: =M39 -> 0 | N38: =N39 -> 1 | O38: =O39 -> 2 | P38: =P39 -> 2 | Q38: =Q39 -> 0 | R38: =R39 -> 0 | S38: =S39 -> 0 | T38: =SUM(M38:S38) -> 5
B39: Support during acceptance phase | C39: 1 | D39: 4 | E39: 2 | F39: 2 | G39: 0 | H39: 1 | K39: =SUM(C39:J39) -> 10 | L39: =SUMPRODUCT(C39:J39,$C$13:$J$13) -> 11360 | M39: 0 | N39: 1 | O39: 2 | P39: 2 | Q39: 0 | T39: =SUM(M39:S39) -> 5
B40: Training | C40: =SUM(C41:C42) -> 0 | D40: =SUM(D41:D42) -> 0 | E40: =SUM(E41:E42) -> 0 | F40: =SUM(F41:F42) -> 0 | G40: =SUM(G41:G42) -> 12 | H40: =SUM(H41:H42) -> 0 | I40: =SUM(I41:I42) -> 0 | J40: =SUM(J41:J42) -> 0 | K40: =SUM(C40:J40) -> 12 | L40: =SUMPRODUCT(C40:J40,$C$13:$J$13) -> 13920 | M40: =SUM(M41:M42) -> 1 | N40: =SUM(N41:N42) -> 8 | O40: =SUM(O41:O42) -> 7 | P40: =SUM(P41:P42) -> 6 | Q40: =SUM(Q41:Q42) -> 2 | R40: =SUM(R41:R42) -> 0 | S40: =SUM(S41:S42) -> 0 | T40: =SUM(M40:S40) -> 24
B41: Formalization of training plan and training materials (for users, tool admins and managers) | C41: 0 | D41: 0 | E41: 0 | F41: 0 | G41: 6 | K41: =SUM(C41:J41) -> 6 | L41: =SUMPRODUCT(C41:J41,$C$13:$J$13) -> 6960 | M41: 1 | N41: 2 | O41: 1 | T41: =SUM(M41:S41) -> 4
B42: Conduct training sessions (for users, tool admins and managers) | C42: 0 | D42: 0 | E42: 0 | F42: 0 | G42: 6 | K42: =SUM(C42:J42) -> 6 | L42: =SUMPRODUCT(C42:J42,$C$13:$J$13) -> 6960 | N42: 6 | O42: 6 | P42: 6 | Q42: 2 | T42: =SUM(M42:S42) -> 20
B43: Production start-up and assistance | C43: =SUM(C44:C45) -> 0 | D43: =SUM(D44:D45) -> 4 | E43: =SUM(E44:E45) -> 3 | F43: =SUM(F44:F45) -> 5 | G43: =SUM(G44:G45) -> 0 | H43: =SUM(H44:H45) -> 2 | I43: =SUM(I44:I45) -> 0 | J43: =SUM(J44:J45) -> 0 | K43: =SUM(C43:J43) -> 14 | L43: =SUMPRODUCT(C43:J43,$C$13:$J$13) -> 15760 | M43: =SUM(M44:M45) -> 3 | N43: =SUM(N44:N45) -> 2 | O43: =SUM(O44:O45) -> 2 | P43: =SUM(P44:P45) -> 1 | Q43: =SUM(Q44:Q45) -> 2 | R43: =SUM(R44:R45) -> 0 | S43: =SUM(S44:S45) -> 0 | T43: =SUM(M43:S43) -> 10
B44: Decommissioning and changeover | C44: 0 | D44: 2 | E44: 1 | F44: 2 | G44: 0 | H44: 1 | K44: =SUM(C44:J44) -> 6 | L44: =SUMPRODUCT(C44:J44,$C$13:$J$13) -> 6800 | M44: 1 | N44: 1 | O44: 0 | P44: 0 | Q44: 1 | T44: =SUM(M44:S44) -> 3
B45: Production start-up and assistance | C45: 0 | D45: 2 | E45: 2 | F45: 3 | G45: 0 | H45: 1 | K45: =SUM(C45:J45) -> 8 | L45: =SUMPRODUCT(C45:J45,$C$13:$J$13) -> 8960 | M45: 2 | N45: 1 | O45: 2 | P45: 1 | Q45: 1 | T45: =SUM(M45:S45) -> 7
...

Sheet Netsuite Interface details
D3: Company name | E3: Oracle Corporation UK Limited
D4: Solution name | E4: Netsuite
B6: INTERFACES DETAILS
B9: Fields to be completed by applicant
B10: ID | C10: No. | D10: Application name (t obe interfaced with the future ERP system | E10: Business objects exchanged | F10: Estimation in number of days
D12: Interfaces with existing solutions
B13: =IF(LEN(C13)=1,$B$11&"00"&C13,IF(LEN(C13)=2,$B$11&"0"&C13,$B$11&C13)) -> 001 | C13: 1 | D13: Trust Pair | E13: Supplier database verification (vendor master data, risk scoring, validation status) | F13: 5
B14: =IF(LEN(C14)=1,$B$11&"00"&C14,IF(LEN(C14)=2,$B$11&"0"&C14,$B$11&C14)) -> 002 | C14: 2 | D14: Agicap | E14: Treasury & cash management (cash positions, bank transactions, forecasts) | F14: 3
B15: =IF(LEN(C15)=1,$B$11&"00"&C15,IF(LEN(C15)=2,$B$11&"0"&C15,$B$11&C15)) -> 003 | C15: 3 | D15: E-invoicing platform (TBD) | E15: E-invoicing management (customer & supplier invoices, statuses, legal archiving references) | F15: 3
B16: =IF(LEN(C16)=1,$B$11&"00"&C16,IF(LEN(C16)=2,$B$11&"0"&C16,$B$11&C16)) -> 004 | C16: 4 | D16: ADP | E16: Payroll data, HR master data | F16: 4
B17: =IF(LEN(C17)=1,$B$11&"00"&C17,IF(LEN(C17)=2,$B$11&"0"&C17,$B$11&C17)) -> 005 | C17: 5 | D17: Lucca | E17: People management | F17: 3
B18: =IF(LEN(C18)=1,$B$11&"00"&C18,IF(LEN(C18)=2,$B$11&"0"&C18,$B$11&C18)) -> 006 | C18: =C17+1 -> 6 | D18: Workday Adaptive Planning | E18: Budget data, forecasts, analytical structures | F18: 8
B19: =IF(LEN(C19)=1,$B$11&"00"&C19,IF(LEN(C19)=2,$B$11&"0"&C19,$B$11&C19)) -> 007 | C19: =C18 + 1 -> 7 | D19: Workiva | E19: Financial reporting data (journals, adjustments, disclosure items) | F19: 6
B20: =IF(LEN(C20)=1,$B$11&"00"&C20,IF(LEN(C20)=2,$B$11&"0"&C20,$B$11&C20)) -> 008 | C20: =C19 + 1 -> 8 | D20: SAP Concur | E20: Expense report | F20: 2
D21: Interfaces with possible future solutions
B22: =IF(LEN(C22)=1,$B$11&"00"&C22,IF(LEN(C22)=2,$B$11&"0"&C22,$B$11&C22)) -> 009 | C22: =C20+1 -> 9 | D22: 3PL | E22: Inventory, shipment, and logistics data | F22: 12
B23: =IF(LEN(C23)=1,$B$11&"00"&C23,IF(LEN(C23)=2,$B$11&"0"&C23,$B$11&C23)) -> 010 | C23: =C22+1 -> 10 | D23: Order to cash partner | E23: Order-to-cash information, including orders, billing, and customer transactions | F23: 8
B24: =IF(LEN(C24)=1,$B$11&"00"&C24,IF(LEN(C24)=2,$B$11&"0"&C24,$B$11&C24)) -> 011 | C24: =C23+1 -> 11 | D24: Production partner | E24: Production data such as manufacturing orders, consumption, and outputs with the production system. | F24: 8

Sheet Netsuite Cash forecast
D3: Company name | E3: Oracle Corporation UK Limited
D4: Solution name | E4: Netsuite
B6: DETAIL OF CASH FORECAST
B10: Cash-out forecast for Abivax
B11: Cash-out forecast for Abivax | C11: Year 1 | D11: Year 2 | E11: Year 3 | F11: Year 4 | G11: Year 5 | H11: Year 6 | I11: Year 7 | J11: Year 8 | K11: Year 9 | L11: Year 10 | M11: Total
B12: Build | C12: ='BUILD (3)'!C60 -> 451520 | D12: 0 | E12: 0 | F12: 0 | G12: 0 | H12: 0 | I12: 0 | J12: 0 | K12: 0 | L12: 0 | M12: =SUM(C12:L12) -> 451520
B13: Run (license cost and TMA) | C13: ='RUN (3)'!$G$43 -> 187008.6 | D13: ='RUN (3)'!$G$43 -> 187008.6 | E13: ='RUN (3)'!$G$43 -> 187008.6 | F13: =E13 -> 187008.6 | G13: =F13 -> 187008.6 | H13: =G13 -> 187008.6 | I13: =H13 -> 187008.6 | J13: =I13 -> 187008.6 | K13: =J13 -> 187008.6 | L13: =K13 -> 187008.6 | M13: =SUM(C13:L13) -> 1870086
B20: It is understood that further discussions and dialogue will take place between us and that these may lead us to agree changes to the solution which is currently envisaged. If that happens we will issue an updated estimate reflecting such changes.
B23: NB : KPMG a retiré le taux d'inflation de 7% car il est déjà comptabilisé dans l'analyse générale

Sheet Netsuite Planning

Sheet Netsuite Financial analysis
C1: L
B4: Company name | C4: Oracle Corporation UK Limited
B5: Solution name | C5: Netsuite
A7: DETAIL OF FINANCIAL ANALYSIS
C10: ERP solution - Integrator
A11: Saas
A12: Overall cost over 3 years | C12: =C28+C40*3 -> 1012545.8
A13: Overall cost over 5 years | C13: =C28+C41 -> 1386563
A14: Overall cost over 10 years | C14: =C28+C41*2 -> 2321606
A16: Build | B16: Project management | C16: ='BUILD (3)'!L15 -> 20960
B17: Initialization | C17: ='BUILD (3)'!L17 -> 50640
B18: Solution design | C18: ='BUILD (3)'!L23 -> 16440
B19: Solution implementation | C19: ='BUILD (3)'!L27 -> 269240
B20: Data recovery | C20: ='BUILD (3)'!L34 -> 17120
B21: Acceptance | C21: ='BUILD (3)'!L38 -> 11360
B22: Training | C22: ='BUILD (3)'!L40 -> 13920
B23: Production start-up and assistance | C23: ='BUILD (3)'!L43 -> 15760
B24: Maintenance and user support during the warranty phase | C24: ='BUILD (3)'!L46 -> 0
B25: Reversibility management | C25: ='BUILD (3)'!L48 -> 6640
B26: Best-of-breed implementation | C26: ='BUILD (3)'!L50 -> 11440
B27: Travel expenses | C27: ='BUILD (3)'!C56 -> 18000
B28: Sub-total “Build” (One-Off) | C28: =SUM(C16:C27) -> 451520
A29: Run | B29: SAAS rent (annual) | C29: =SUM(C32:C35) -> 145899.6
B30: SaaS rent (annual unit basis) | C30: =IFERROR(C32/'RUN (3)'!C20,0) -> 779.48936
B31: SaaS rent (monthly basis) | C31: =C32/12 -> 9159
B32: SaaS rent (annual basis) | C32: ='RUN (3)'!G20 -> 109908
B33: Best of Breed SaaS rent (annual basis) | C33: ='RUN (3)'!G28 -> 23935.8
B34: Hosting subscription (annual) | C34: ='RUN (3)'!G35 -> 0
B35: Other costs | C35: ='RUN (3)'!G41 -> 12055.8
B36: TMA (annual) | C36: =SUM(C37:C39) -> 41109
B37: Support (annual basis) | C37: ='RUN (3)'!G30+'RUN (3)'!G32 -> 21257.4
B38: TMA rent (annual basis) | C38: ='RUN (3)'!G31 -> 19851.6
B39: Other support / maintenance services
B40: Sub-total “Run” Saas (annual) | C40: =C36+C29 -> 187008.6
B41: Sub-total “Run” Saas (5 years) | C41: =C40*5 -> 935043
A43: Total (man days) | C43: ='BUILD (3)'!K54 -> 382
A44: Integrator's average daily rate | C44: =IFERROR('BUILD (3)'!C62,0) -> 1134.8691
A46: Abivax Workload | C46: ='BUILD (3)'!T54 -> 134
A48: It is understood that further discussions and dialogue will take place between us and that these may lead us to agree changes to the solution which is currently envisaged. If that happens we will issue an updated estimate reflecting such changes.

Sheet KPMG >>

Sheet RUN (4)
D3: Company name | E3: KPMG
D4: Solution name | E4: SAP S/4HANA Public Cloud
B6: DETAIL OF RUN
B9: Fields to be completed by applicant
E10: License cost
B11: Criteria | C11: Quantity | D11: Unit price by year by user | E11: Acquisition cost Public price | F11: Applicable rebate | G11: Final offer V1 | H11: Comments
B12: Licences Core Model | C12: Nb of users | D12: Unit price € Excluding tax | E12: € Excluding tax (by year) | F12: % | G12: € Excluding tax
B13: SAP Finance and Supply Chain developer | C13: 2 | D13: 2928 | E13: =C13*D13 -> 5856 | G13: =E13*(1-F13) -> 5856
B14: SAP Finance Base | C14: 15 | D14: 3045.1333 | E14: =C14*D14 -> 45677 | G14: =E14*(1-F14) -> 45677
B15: SAP Finance and Supply Chain operations | C15: 35 | D15: 688.08571 | E15: =C15*D15 -> 24083 | G15: =E15*(1-F15) -> 24083
B16: SAP Finance and Supply Chain self-service | C16: 90 | D16: 146.4 | E16: =C16*D16 -> 13176 | G16: =E16*(1-F16) -> 13176
B17: SAP Ariba Central Invoice Management | C17: 20.008091 | D17: 618 | E17: =C17*D17 -> 12365 | G17: =E17*(1-F17) -> 12365
B18: SAP AI Units | C18: 9.9875 | D18: 320 | E18: =C18*D18 -> 3196 | G18: =E18*(1-F18) -> 3196
B19: SAP BTPEA - Build Automation | C19: 1 | D19: 10980 | E19: =C19*D19 -> 10980 | G19: =E19*(1-F19) -> 10980
B20: Sub-total for licences cost (core model exc. Best of breed) | C20: =SUM(C13:C16) -> 142 | D20: =SUM(D13:D19) -> 18725.619 | E20: =SUM(E13:E19) -> 115333 | G20: =SUM(G13:G19) -> 115333
B21: Add-ons, best-of-breed and other licenses by domain | C21: 1 | D21: Unit price € Excluding tax | E21: € Excluding tax (by year) | F21: % | G21: € Excluding tax
B22: SAP Document and Reporting Compliance (Recommended) | C22: 1 | D22: 4488 | E22: =C22*D22 -> 4488 | G22: =E22*(1-F22) -> 4488 | H22: Optional? To be checked in SAP doc
B23: Cloud Edition (Recommended) | C23: 1 | D23: 4411 | E23: =C23*D23 -> 4411 | G23: =E23*(1-F23) -> 4411 | H23: Optional? To be checked in SAP doc
B24: SAP intergration Suite, basic edition (Recommended) | C24: 1 | D24: 17185 | E24: =C24*D24 -> 17185 | G24: =E24*(1-F24) -> 17185 | H24: Optional? To be checked in SAP doc
B25: Customer-Managed Data Products | C25: 1 | D25: 11814 | E25: =C25*D25 -> 11814 | G25: =E25*(1-F25) -> 11814 | H25: Optional? To be checked in SAP doc
B26: SAP Business Data Cloud, core capacity | C26: 1 | D26: 5060 | E26: =C26*D26 -> 5060 | G26: =E26*(1-F26) -> 5060 | H26: Optional? To be checked in SAP doc
B27: WalkMe LearningArc | C27: 140 | D27: 19.992857 | E27: =C27*D27 -> 2799 | G27: =E27*(1-F27) -> 2799 | H27: Optional? To be checked in SAP doc
E28: =C28*D28 -> 0 | G28: =E28*(1-F28) -> 0
E29: =C29*D29 -> 0 | G29: =E29*(1-F29) -> 0
B30: Sub-total for licences cost (Best of breed) | C30: =SUM(C27) -> 140 | D30: =SUM(D22:D29) -> 42977.993 | E30: =SUM(E22:E29) -> 45757 | G30: =SUM(G22:G29) -> 45757
B31: Support & Maintenance | C31: Day | D31: Unit price € Excluding tax | E31: € Excluding tax (by year) | F31: % | G31: € Excluding tax
B32: Support (helpdesk) = 20 days per year | C32: 20 | D32: 720 | E32: =C32*D32 -> 14400 | G32: =E32*(1-F32) -> 14400
B33: Maintenance : • Corrective maintenance = 30 days per year • Major release assistance = 10 days per year • Evolution assistance = 15 days a year • Project management related to the follow-up of services provided = 2 hours by quarter | C33: 55 | D33: 779.09091 | E33: =C33*D33 -> 42850 | G33: =E33*(1-F33) -> 42850
B34: List other services offered | E34: =C34*D34 -> 0 | G34: =E34*(1-F34) -> 0
B35: List other services offered | E35: =C35*D35 -> 0 | G35: =E35*(1-F35) -> 0
B36: Total other services offered | C36: =SUM(C32:C35) -> 75 | D36: =SUM(D32:D35) -> 1499.0909 | E36: =SUM(E32:E35) -> 57250 | G36: =SUM(G32:G35) -> 57250
B37: Other cost items (infrastructure, etc.) | C37: Quantity | D37: Unit price € Excluding tax | E37: € Excluding tax | F37: % | G37: € Excluding tax
B38: Hosting subscription (annual) | E38: =C38*D38 -> 0 | G38: =E38*(1-F38) -> 0
B39: List the other cost items (hardware, servers, etc.) from an infrastructure point of view | E39: =C39*D39 -> 0 | G39: =E39*(1-F39) -> 0
B40: List the other cost items (hardware, servers, etc.) from an infrastructure point of view | E40: =C40*D40 -> 0 | G40: =E40*(1-F40) -> 0
B41: List the other cost items (hardware, servers, etc.) from an infrastructure point of view | E41: =C41*D41 -> 0 | G41: =E41*(1-F41) -> 0
B42: Sub-total for other items | C42: =SUM(C38:C41) -> 0 | D42: =SUM(D38:D41) -> 0 | E42: =SUM(E38:E41) -> 0 | G42: =SUM(G38:G41) -> 0
C44: TOTAL | G44: =G20+G30+G36+G42 -> 218340

Sheet BUILD (4)
D3: Company name | E3: KPMG
D4: Solution name | E4: SAP S/4HANA Public Cloud
B6: DETAIL OF BUILD
B9: Is the project costed on a fixed-price basis?
B10: Fields to be completed by applicant
B11: Phases | C11: Workloads Provider / profile / phase | M11: GC workloads / profile / phase | U11: Assumptions / Comments
C12: Project Director Profile | D12: Project Manager Profile | E12: Technical Consultant Profile | F12: Functional Consultant Profile | G12: Trainer Profile | H12: IT Architect Profile | I12: Profile xxxxxx | J12: Profile xxxxxx | K12: Total (Days) | L12: Total € by phase | M12: Project Manager | N12: BPO | O12: Key User | P12: Users | Q12: IT team member (technical responsible) | R12: Profile xxxxxx | S12: Profile xxxxxx | T12: Total (D) | U12: Total € by phase
B13: Average daily rate by profile (in € excl. tax) | C13: 1800 | D13: 1100 | E13: 850 | F13: 1500 | G13: 780 | H13: 1300 | I13: 520 | J13: 520
C14: Estimated workload (in days) | M14: Estimated workload (in days)
B15: Project management | C15: =SUM(C16) -> 9 | D15: =SUM(D16) -> 63 | E15: =SUM(E16) -> 72 | F15: =SUM(F16) -> 0 | G15: =SUM(G16) -> 0 | H15: =SUM(H16) -> 0 | I15: =SUM(I16) -> 0 | J15: =SUM(J16) -> 0 | K15: =SUM(C15:J15) -> 144 | L15: =SUMPRODUCT(C15:J15,$C$13:$J$13) -> 146700 | M15: =M16 -> 60 | N15: =N16 -> 0 | O15: =O16 -> 0 | P15: =P16 -> 0 | Q15: =Q16 -> 0 | R15: =R16 -> 0 | S15: =S16 -> 0 | T15: =SUM(M15:S15) -> 60
B16: Project follow-up | C16: 9 | D16: 63 | E16: 72 | K16: =SUM(C16:J16) -> 144 | L16: =SUMPRODUCT(C16:J16,$C$13:$J$13) -> 146700 | M16: 60 | T16: =SUM(M16:S16) -> 60
B17: Initialization | C17: =SUM(C18:C22) -> 0 | D17: =SUM(D18:D22) -> 0 | E17: =SUM(E18:E22) -> 0 | F17: =SUM(F18:F22) -> 3 | G17: =SUM(G18:G22) -> 0 | H17: =SUM(H18:H22) -> 1 | I17: =SUM(I18:I22) -> 0 | J17: =SUM(J18:J22) -> 0 | K17: =SUM(C17:J17) -> 4 | L17: =SUMPRODUCT(C17:J17,$C$13:$J$13) -> 5800 | M17: =SUM(M18:M22) -> 0 | N17: =SUM(N18:N22) -> 0 | O17: =SUM(O18:O22) -> 0 | P17: =SUM(P18:P22) -> 0 | Q17: =SUM(Q18:Q22) -> 0 | R17: =SUM(R18:R22) -> 0 | S17: =SUM(S18:S22) -> 0 | T17: =SUM(M17:S17) -> 0
B18: Project scoping and launch | F18: 3 | H18: 0.5 | K18: =SUM(C18:J18) -> 3.5 | L18: =SUMPRODUCT(C18:J18,$C$13:$J$13) -> 5150 | T18: =SUM(M18:S18) -> 0
B19: Technical analysis | K19: =SUM(C19:J19) -> 0 | L19: =SUMPRODUCT(C19:J19,$C$13:$J$13) -> 0 | T19: =SUM(M19:S19) -> 0
B20: Functional analysis | K20: =SUM(C20:J20) -> 0 | L20: =SUMPRODUCT(C20:J20,$C$13:$J$13) -> 0 | T20: =SUM(M20:S20) -> 0
B21: Data analysis | K21: =SUM(C21:J21) -> 0 | L21: =SUMPRODUCT(C21:J21,$C$13:$J$13) -> 0 | T21: =SUM(M21:S21) -> 0
B22: Preparation of environments | H22: 0.5 | K22: =SUM(C22:J22) -> 0.5 | L22: =SUMPRODUCT(C22:J22,$C$13:$J$13) -> 650 | T22: =SUM(M22:S22) -> 0
B23: Solution design | C23: =SUM(C24:C25) -> 0 | D23: =SUM(D24:D25) -> 0 | E23: =SUM(E24:E25) -> 0 | F23: =SUM(F24:F25) -> 34.5 | G23: =SUM(G24:G25) -> 59.5 | H23: =SUM(H24:H25) -> 10.5 | I23: =SUM(I24:I25) -> 5 | J23: =SUM(J24:J25) -> 0 | K23: =SUM(C23:J23) -> 109.5 | L23: =SUMPRODUCT(C23:J23,$C$13:$J$13) -> 114410 | M23: =SUM(M24:M25) -> 0 | N23: =SUM(N24:N25) -> 0 | O23: =SUM(O24:O25) -> 0 | P23: =SUM(P24:P25) -> 0 | Q23: =SUM(Q24:Q25) -> 0 | R23: =SUM(R24:R25) -> 0 | S23: =SUM(S24:S25) -> 0 | T23: =SUM(M23:S23) -> 0
B24: Drafting of solution design file | F24: 34.5 | G24: 59.5 | H24: 10.5 | I24: 5 | K24: =SUM(C24:J24) -> 109.5 | L24: =SUMPRODUCT(C24:J24,$C$13:$J$13) -> 114410 | T24: =SUM(M24:S24) -> 0
B25: Definition of development plan | K25: =SUM(C25:J25) -> 0 | L25: =SUMPRODUCT(C25:J25,$C$13:$J$13) -> 0 | T25: =SUM(M25:S25) -> 0
B26: Initialization and design | C26: =C23+C17 -> 0 | D26: =D23+D17 -> 0 | E26: =E23+E17 -> 0 | F26: =F23+F17 -> 37.5 | G26: =G23+G17 -> 59.5 | H26: =H23+H17 -> 11.5 | I26: =I23+I17 -> 5 | J26: =J23+J17 -> 0 | K26: =K23+K17 -> 113.5 | L26: =SUMPRODUCT(C26:J26,$C$13:$J$13) -> 120210 | M26: =M23+M17 -> 0 | N26: =N23+N17 -> 0 | O26: =O23+O17 -> 0 | P26: =P23+P17 -> 0 | Q26: =Q23+Q17 -> 0 | R26: =R23+R17 -> 0 | S26: =S23+S17 -> 0 | T26: =SUM(M26:S26) -> 0
B27: Solution implementation | C27: =SUM(C28:C33) -> 0 | D27: =SUM(D28:D33) -> 0 | E27: =SUM(E28:E33) -> 0 | F27: =SUM(F28:F33) -> 59.490566 | G27: =SUM(G28:G33) -> 119.49057 | H27: =SUM(H28:H33) -> 4 | I27: =SUM(I28:I33) -> 83.018868 | J27: =SUM(J28:J33) -> 30 | K27: =SUM(C27:J27) -> 296 | L27: =SUMPRODUCT(C27:J27,$C$13:$J$13) -> 246408.3 | M27: =SUM(M28:M33) -> 0 | N27: =SUM(N28:N33) -> 0 | O27: =SUM(O28:O33) -> 0 | P27: =SUM(P28:P33) -> 0 | Q27: =SUM(Q28:Q33) -> 0 | R27: =SUM(R28:R33) -> 0 | S27: =SUM(S28:S33) -> 0 | T27: =SUM(M27:S27) -> 0
B28: Specific development and parameterization | F28: 35 | G28: 95 | H28: 4 | I28: 14 | J28: 30 | K28: =SUM(C28:J28) -> 178 | L28: =SUMPRODUCT(C28:J28,$C$13:$J$13) -> 154680 | T28: =SUM(M28:S28) -> 0
B29: Realization of interfaces (please provide with the details in the Interfaces detail tab) | F29: =11+'SAP Interface details'!I15 -> 24.490566 | G29: =11+'SAP Interface details'!J15 -> 24.490566 | I29: =31+'SAP Interface details'!K15 -> 69.018868 | K29: =SUM(C29:J29) -> 118 | L29: =SUMPRODUCT(C29:J29,$C$13:$J$13) -> 91728.302 | T29: =SUM(M29:S29) -> 0
B30: Production of editions | K30: =SUM(C30:J30) -> 0 | L30: =SUMPRODUCT(C30:J30,$C$13:$J$13) -> 0 | T30: =SUM(M30:S30) -> 0
B31: Production of indicators and dashboards | K31: =SUM(C31:J31) -> 0 | L31: =SUMPRODUCT(C31:J31,$C$13:$J$13) -> 0 | T31: =SUM(M31:S31) -> 0
B32: Unit testing | K32: =SUM(C32:J32) -> 0 | L32: =SUMPRODUCT(C32:J32,$C$13:$J$13) -> 0 | T32: =SUM(M32:S32) -> 0
B33: End-to-end testing support | K33: =SUM(C33:J33) -> 0 | L33: =SUMPRODUCT(C33:J33,$C$13:$J$13) -> 0 | T33: =SUM(M33:S33) -> 0
B34: Data migration | C34: =SUM(C35:C37) -> 0 | D34: =SUM(D35:D37) -> 0 | E34: =SUM(E35:E37) -> 0 | F34: =SUM(F35:F37) -> 0 | G34: =SUM(G35:G37) -> 0 | H34: =SUM(H35:H37) -> 0 | I34: =SUM(I35:I37) -> 0 | J34: =SUM(J35:J37) -> 0 | K34: =SUM(C34:J34) -> 0 | L34: =SUMPRODUCT(C34:J34,$C$13:$J$13) -> 0 | M34: =SUM(M35:M37) -> 0 | N34: =SUM(N35:N37) -> 0 | O34: =SUM(O35:O37) -> 0 | P34: =SUM(P35:P37) -> 0 | Q34: =SUM(Q35:Q37) -> 0 | R34: =SUM(R35:R37) -> 0 | S34: =SUM(S35:S37) -> 0 | T34: =SUM(M34:S34) -> 0
B35: Cleaning and standardization of repositories | K35: =SUM(C35:J35) -> 0 | L35: =SUMPRODUCT(C35:J35,$C$13:$J$13) -> 0 | T35: =SUM(M35:S35) -> 0
B36: Formalization of target data architecture | K36: =SUM(C36:J36) -> 0 | L36: =SUMPRODUCT(C36:J36,$C$13:$J$13) -> 0 | T36: =SUM(M36:S36) -> 0
B37: Data migration | K37: =SUM(C37:J37) -> 0 | L37: =SUMPRODUCT(C37:J37,$C$13:$J$13) -> 0 | T37: =SUM(M37:S37) -> 0
B38: Acceptance | C38: =C39 -> 0 | D38: =D39 -> 0 | E38: =E39 -> 0 | F38: =F39 -> 24 | G38: =G39 -> 45 | H38: =H39 -> 0 | I38: =I39 -> 5 | J38: =J39 -> 20 | K38: =SUM(C38:J38) -> 94 | L38: =SUMPRODUCT(C38:J38,$C$13:$J$13) -> 84100 | M38: =M39 -> 0 | N38: =N39 -> 0 | O38: =O39 -> 0 | P38: =P39 -> 0 | Q38: =Q39 -> 0 | R38: =R39 -> 0 | S38: =S39 -> 0 | T38: =SUM(M38:S38) -> 0
B39: Support during acceptance phase | F39: 24 | G39: 45 | I39: 5 | J39: 20 | K39: =SUM(C39:J39) -> 94 | L39: =SUMPRODUCT(C39:J39,$C$13:$J$13) -> 84100 | T39: =SUM(M39:S39) -> 0
B40: Training | C40: =SUM(C41:C42) -> 0 | D40: =SUM(D41:D42) -> 0 | E40: =SUM(E41:E42) -> 0 | F40: =SUM(F41:F42) -> 0 | G40: =SUM(G41:G42) -> 0 | H40: =SUM(H41:H42) -> 0 | I40: =SUM(I41:I42) -> 0 | J40: =SUM(J41:J42) -> 0 | K40: =SUM(C40:J40) -> 0 | L40: =SUMPRODUCT(C40:J40,$C$13:$J$13) -> 0 | M40: =SUM(M41:M42) -> 0 | N40: =SUM(N41:N42) -> 0 | O40: =SUM(O41:O42) -> 0 | P40: =SUM(P41:P42) -> 0 | Q40: =SUM(Q41:Q42) -> 0 | R40: =SUM(R41:R42) -> 0 | S40: =SUM(S41:S42) -> 0 | T40: =SUM(M40:S40) -> 0
B41: Formalization of training plan and training materials (for users, tool admins and managers) | K41: =SUM(C41:J41) -> 0 | L41: =SUMPRODUCT(C41:J41,$C$13:$J$13) -> 0 | T41: =SUM(M41:S41) -> 0
B42: Conduct training sessions (for users, tool admins and managers) | K42: =SUM(C42:J42) -> 0 | L42: =SUMPRODUCT(C42:J42,$C$13:$J$13) -> 0 | T42: =SUM(M42:S42) -> 0
B43: Production start-up and assistance | C43: =SUM(C44:C45) -> 0 | D43: =SUM(D44:D45) -> 0 | E43: =SUM(E44:E45) -> 0 | F43: =SUM(F44:F45) -> 44 | G43: =SUM(G44:G45) -> 56 | H43: =SUM(H44:H45) -> 0 | I43: =SUM(I44:I45) -> 0 | J43: =SUM(J44:J45) -> 0 | K43: =SUM(C43:J43) -> 100 | L43: =SUMPRODUCT(C43:J43,$C$13:$J$13) -> 109680 | M43: =SUM(M44:M45) -> 0 | N43: =SUM(N44:N45) -> 0 | O43: =SUM(O44:O45) -> 0 | P43: =SUM(P44:P45) -> 0 | Q43: =SUM(Q44:Q45) -> 0 | R43: =SUM(R44:R45) -> 0 | S43: =SUM(S44:S45) -> 0 | T43: =SUM(M43:S43) -> 0
